2017-07-13 23:11:25,344 INFO: tutor startup [in C:\Users\jackm\Desktop\tutor\app\__init__.py:25]
2017-07-13 23:12:21,059 INFO: tutor startup [in C:\Users\jackm\Desktop\tutor\app\__init__.py:25]
2017-07-13 23:13:46,292 INFO: tutor startup [in C:\Users\jackm\Desktop\tutor\app\__init__.py:25]
2017-07-13 23:21:35,775 INFO: tutor startup [in C:\Users\jackm\Desktop\tutor\app\__init__.py:25]
2017-07-13 23:23:51,929 INFO: tutor startup [in C:\Users\jackm\Desktop\tutor\app\__init__.py:25]
2017-07-13 23:24:13,530 INFO: tutor startup [in C:\Users\jackm\Desktop\tutor\app\__init__.py:25]
2017-07-13 23:24:16,553 INFO: tutor startup [in C:\Users\jackm\Desktop\tutor\app\__init__.py:25]
2017-07-14 12:41:53,052 INFO: tutor startup [in C:\Users\jackm\Desktop\tutor\app\__init__.py:25]
2017-07-14 13:21:46,234 INFO: tutor startup [in C:\Users\jackm\Desktop\tutor\app\__init__.py:25]
2017-07-14 13:28:57,723 INFO: tutor startup [in C:\Users\jackm\Desktop\tutor\app\__init__.py:25]
2017-07-14 13:29:46,343 INFO: tutor startup [in C:\Users\jackm\Desktop\tutor\app\__init__.py:25]
2017-07-14 13:34:50,632 INFO: tutor startup [in C:\Users\jackm\Desktop\tutor\app\__init__.py:25]
2017-07-14 13:35:30,809 INFO: tutor startup [in C:\Users\jackm\Desktop\tutor\app\__init__.py:25]
2017-07-14 13:37:06,651 INFO: tutor startup [in C:\Users\jackm\Desktop\tutor\app\__init__.py:25]
2017-07-14 13:37:34,887 INFO: tutor startup [in C:\Users\jackm\Desktop\tutor\app\__init__.py:25]
2017-07-14 17:13:37,704 INFO: tutor startup [in C:\Users\jackm\Desktop\tutor\app\__init__.py:25]
2017-07-14 17:26:23,348 INFO: tutor startup [in C:\Users\jackm\Desktop\tutor\app\__init__.py:25]
2017-07-14 17:26:27,650 ERROR: Exception on /chat [GET] [in C:\Users\jackm\Desktop\tutor\flask\lib\site-packages\flask\app.py:1560]
Traceback (most recent call last):
  File "C:\Users\jackm\Desktop\tutor\flask\lib\site-packages\flask\app.py", line 1982, in wsgi_app
    response = self.full_dispatch_request()
  File "C:\Users\jackm\Desktop\tutor\flask\lib\site-packages\flask\app.py", line 1614, in full_dispatch_request
    rv = self.handle_user_exception(e)
  File "C:\Users\jackm\Desktop\tutor\flask\lib\site-packages\flask\app.py", line 1517, in handle_user_exception
    reraise(exc_type, exc_value, tb)
  File "C:\Users\jackm\Desktop\tutor\flask\lib\site-packages\flask\_compat.py", line 33, in reraise
    raise value
  File "C:\Users\jackm\Desktop\tutor\flask\lib\site-packages\flask\app.py", line 1612, in full_dispatch_request
    rv = self.dispatch_request()
  File "C:\Users\jackm\Desktop\tutor\flask\lib\site-packages\flask\app.py", line 1598, in dispatch_request
    return self.view_functions[rule.endpoint](**req.view_args)
  File "C:\Users\jackm\Desktop\tutor\app\views.py", line 50, in chat
    title='Chat')
  File "C:\Users\jackm\Desktop\tutor\flask\lib\site-packages\flask\templating.py", line 134, in render_template
    context, ctx.app)
  File "C:\Users\jackm\Desktop\tutor\flask\lib\site-packages\flask\templating.py", line 116, in _render
    rv = template.render(context)
  File "C:\Users\jackm\Desktop\tutor\flask\lib\site-packages\jinja2\asyncsupport.py", line 76, in render
    return original_render(self, *args, **kwargs)
  File "C:\Users\jackm\Desktop\tutor\flask\lib\site-packages\jinja2\environment.py", line 1008, in render
    return self.environment.handle_exception(exc_info, True)
  File "C:\Users\jackm\Desktop\tutor\flask\lib\site-packages\jinja2\environment.py", line 780, in handle_exception
    reraise(exc_type, exc_value, tb)
  File "C:\Users\jackm\Desktop\tutor\flask\lib\site-packages\jinja2\_compat.py", line 37, in reraise
    raise value.with_traceback(tb)
  File "C:\Users\jackm\Desktop\tutor\app\templates\chat.html", line 1, in top-level template code
    {% extends "base.html" %}
  File "C:\Users\jackm\Desktop\tutor\app\templates\base.html", line 20, in top-level template code
    {% block content %}{% endblock %}
  File "C:\Users\jackm\Desktop\tutor\app\templates\chat.html", line 10, in block "content"
    {{ form.hidden_tag() }}
  File "C:\Users\jackm\Desktop\tutor\flask\lib\site-packages\jinja2\environment.py", line 430, in getattr
    return getattr(obj, attribute)
jinja2.exceptions.UndefinedError: 'form' is undefined
2017-07-14 17:28:52,344 INFO: tutor startup [in C:\Users\jackm\Desktop\tutor\app\__init__.py:25]
2017-07-14 17:34:46,023 INFO: tutor startup [in C:\Users\jackm\Desktop\tutor\app\__init__.py:25]
2017-07-14 17:34:56,980 ERROR: Exception on /chat [POST] [in C:\Users\jackm\Desktop\tutor\flask\lib\site-packages\flask\app.py:1560]
Traceback (most recent call last):
  File "C:\Users\jackm\Desktop\tutor\flask\lib\site-packages\flask\app.py", line 1982, in wsgi_app
    response = self.full_dispatch_request()
  File "C:\Users\jackm\Desktop\tutor\flask\lib\site-packages\flask\app.py", line 1614, in full_dispatch_request
    rv = self.handle_user_exception(e)
  File "C:\Users\jackm\Desktop\tutor\flask\lib\site-packages\flask\app.py", line 1517, in handle_user_exception
    reraise(exc_type, exc_value, tb)
  File "C:\Users\jackm\Desktop\tutor\flask\lib\site-packages\flask\_compat.py", line 33, in reraise
    raise value
  File "C:\Users\jackm\Desktop\tutor\flask\lib\site-packages\flask\app.py", line 1612, in full_dispatch_request
    rv = self.dispatch_request()
  File "C:\Users\jackm\Desktop\tutor\flask\lib\site-packages\flask\app.py", line 1598, in dispatch_request
    return self.view_functions[rule.endpoint](**req.view_args)
  File "C:\Users\jackm\Desktop\tutor\app\views.py", line 53, in chat
    return redirect(url_for('/room/<roomname>'))
  File "C:\Users\jackm\Desktop\tutor\flask\lib\site-packages\flask\helpers.py", line 333, in url_for
    return appctx.app.handle_url_build_error(error, endpoint, values)
  File "C:\Users\jackm\Desktop\tutor\flask\lib\site-packages\flask\app.py", line 1805, in handle_url_build_error
    reraise(exc_type, exc_value, tb)
  File "C:\Users\jackm\Desktop\tutor\flask\lib\site-packages\flask\_compat.py", line 33, in reraise
    raise value
  File "C:\Users\jackm\Desktop\tutor\flask\lib\site-packages\flask\helpers.py", line 323, in url_for
    force_external=external)
  File "C:\Users\jackm\Desktop\tutor\flask\lib\site-packages\werkzeug\routing.py", line 1768, in build
    raise BuildError(endpoint, values, method, self)
werkzeug.routing.BuildError: Could not build url for endpoint '/room/<roomname>'. Did you mean 'room' instead?
2017-07-14 17:35:16,209 INFO: tutor startup [in C:\Users\jackm\Desktop\tutor\app\__init__.py:25]
2017-07-14 17:35:26,312 ERROR: Exception on /chat [POST] [in C:\Users\jackm\Desktop\tutor\flask\lib\site-packages\flask\app.py:1560]
Traceback (most recent call last):
  File "C:\Users\jackm\Desktop\tutor\flask\lib\site-packages\flask\app.py", line 1982, in wsgi_app
    response = self.full_dispatch_request()
  File "C:\Users\jackm\Desktop\tutor\flask\lib\site-packages\flask\app.py", line 1614, in full_dispatch_request
    rv = self.handle_user_exception(e)
  File "C:\Users\jackm\Desktop\tutor\flask\lib\site-packages\flask\app.py", line 1517, in handle_user_exception
    reraise(exc_type, exc_value, tb)
  File "C:\Users\jackm\Desktop\tutor\flask\lib\site-packages\flask\_compat.py", line 33, in reraise
    raise value
  File "C:\Users\jackm\Desktop\tutor\flask\lib\site-packages\flask\app.py", line 1612, in full_dispatch_request
    rv = self.dispatch_request()
  File "C:\Users\jackm\Desktop\tutor\flask\lib\site-packages\flask\app.py", line 1598, in dispatch_request
    return self.view_functions[rule.endpoint](**req.view_args)
  File "C:\Users\jackm\Desktop\tutor\app\views.py", line 53, in chat
    return redirect(url_for('/room/roomname'))
  File "C:\Users\jackm\Desktop\tutor\flask\lib\site-packages\flask\helpers.py", line 333, in url_for
    return appctx.app.handle_url_build_error(error, endpoint, values)
  File "C:\Users\jackm\Desktop\tutor\flask\lib\site-packages\flask\app.py", line 1805, in handle_url_build_error
    reraise(exc_type, exc_value, tb)
  File "C:\Users\jackm\Desktop\tutor\flask\lib\site-packages\flask\_compat.py", line 33, in reraise
    raise value
  File "C:\Users\jackm\Desktop\tutor\flask\lib\site-packages\flask\helpers.py", line 323, in url_for
    force_external=external)
  File "C:\Users\jackm\Desktop\tutor\flask\lib\site-packages\werkzeug\routing.py", line 1768, in build
    raise BuildError(endpoint, values, method, self)
werkzeug.routing.BuildError: Could not build url for endpoint '/room/roomname'. Did you mean 'room' instead?
2017-07-14 17:36:04,303 INFO: tutor startup [in C:\Users\jackm\Desktop\tutor\app\__init__.py:25]
2017-07-14 17:36:15,881 ERROR: Exception on /chat [POST] [in C:\Users\jackm\Desktop\tutor\flask\lib\site-packages\flask\app.py:1560]
Traceback (most recent call last):
  File "C:\Users\jackm\Desktop\tutor\flask\lib\site-packages\flask\app.py", line 1982, in wsgi_app
    response = self.full_dispatch_request()
  File "C:\Users\jackm\Desktop\tutor\flask\lib\site-packages\flask\app.py", line 1614, in full_dispatch_request
    rv = self.handle_user_exception(e)
  File "C:\Users\jackm\Desktop\tutor\flask\lib\site-packages\flask\app.py", line 1517, in handle_user_exception
    reraise(exc_type, exc_value, tb)
  File "C:\Users\jackm\Desktop\tutor\flask\lib\site-packages\flask\_compat.py", line 33, in reraise
    raise value
  File "C:\Users\jackm\Desktop\tutor\flask\lib\site-packages\flask\app.py", line 1612, in full_dispatch_request
    rv = self.dispatch_request()
  File "C:\Users\jackm\Desktop\tutor\flask\lib\site-packages\flask\app.py", line 1598, in dispatch_request
    return self.view_functions[rule.endpoint](**req.view_args)
  File "C:\Users\jackm\Desktop\tutor\app\views.py", line 53, in chat
    return redirect(url_for('/room/%s' % form.roomname.data))
  File "C:\Users\jackm\Desktop\tutor\flask\lib\site-packages\flask\helpers.py", line 333, in url_for
    return appctx.app.handle_url_build_error(error, endpoint, values)
  File "C:\Users\jackm\Desktop\tutor\flask\lib\site-packages\flask\app.py", line 1805, in handle_url_build_error
    reraise(exc_type, exc_value, tb)
  File "C:\Users\jackm\Desktop\tutor\flask\lib\site-packages\flask\_compat.py", line 33, in reraise
    raise value
  File "C:\Users\jackm\Desktop\tutor\flask\lib\site-packages\flask\helpers.py", line 323, in url_for
    force_external=external)
  File "C:\Users\jackm\Desktop\tutor\flask\lib\site-packages\werkzeug\routing.py", line 1768, in build
    raise BuildError(endpoint, values, method, self)
werkzeug.routing.BuildError: Could not build url for endpoint '/room/flop'. Did you mean 'room' instead?
2017-07-14 17:36:58,664 INFO: tutor startup [in C:\Users\jackm\Desktop\tutor\app\__init__.py:25]
2017-07-14 17:37:05,531 ERROR: Exception on /chat [POST] [in C:\Users\jackm\Desktop\tutor\flask\lib\site-packages\flask\app.py:1560]
Traceback (most recent call last):
  File "C:\Users\jackm\Desktop\tutor\flask\lib\site-packages\flask\app.py", line 1982, in wsgi_app
    response = self.full_dispatch_request()
  File "C:\Users\jackm\Desktop\tutor\flask\lib\site-packages\flask\app.py", line 1614, in full_dispatch_request
    rv = self.handle_user_exception(e)
  File "C:\Users\jackm\Desktop\tutor\flask\lib\site-packages\flask\app.py", line 1517, in handle_user_exception
    reraise(exc_type, exc_value, tb)
  File "C:\Users\jackm\Desktop\tutor\flask\lib\site-packages\flask\_compat.py", line 33, in reraise
    raise value
  File "C:\Users\jackm\Desktop\tutor\flask\lib\site-packages\flask\app.py", line 1612, in full_dispatch_request
    rv = self.dispatch_request()
  File "C:\Users\jackm\Desktop\tutor\flask\lib\site-packages\flask\app.py", line 1598, in dispatch_request
    return self.view_functions[rule.endpoint](**req.view_args)
  File "C:\Users\jackm\Desktop\tutor\app\views.py", line 53, in chat
    return redirect(url_for('/room'), roomname=form.roomname.data)
  File "C:\Users\jackm\Desktop\tutor\flask\lib\site-packages\flask\helpers.py", line 333, in url_for
    return appctx.app.handle_url_build_error(error, endpoint, values)
  File "C:\Users\jackm\Desktop\tutor\flask\lib\site-packages\flask\app.py", line 1805, in handle_url_build_error
    reraise(exc_type, exc_value, tb)
  File "C:\Users\jackm\Desktop\tutor\flask\lib\site-packages\flask\_compat.py", line 33, in reraise
    raise value
  File "C:\Users\jackm\Desktop\tutor\flask\lib\site-packages\flask\helpers.py", line 323, in url_for
    force_external=external)
  File "C:\Users\jackm\Desktop\tutor\flask\lib\site-packages\werkzeug\routing.py", line 1768, in build
    raise BuildError(endpoint, values, method, self)
werkzeug.routing.BuildError: Could not build url for endpoint '/room'. Did you mean 'room' instead?
2017-07-14 17:37:22,424 INFO: tutor startup [in C:\Users\jackm\Desktop\tutor\app\__init__.py:25]
2017-07-14 17:37:29,785 ERROR: Exception on /chat [POST] [in C:\Users\jackm\Desktop\tutor\flask\lib\site-packages\flask\app.py:1560]
Traceback (most recent call last):
  File "C:\Users\jackm\Desktop\tutor\flask\lib\site-packages\flask\app.py", line 1982, in wsgi_app
    response = self.full_dispatch_request()
  File "C:\Users\jackm\Desktop\tutor\flask\lib\site-packages\flask\app.py", line 1614, in full_dispatch_request
    rv = self.handle_user_exception(e)
  File "C:\Users\jackm\Desktop\tutor\flask\lib\site-packages\flask\app.py", line 1517, in handle_user_exception
    reraise(exc_type, exc_value, tb)
  File "C:\Users\jackm\Desktop\tutor\flask\lib\site-packages\flask\_compat.py", line 33, in reraise
    raise value
  File "C:\Users\jackm\Desktop\tutor\flask\lib\site-packages\flask\app.py", line 1612, in full_dispatch_request
    rv = self.dispatch_request()
  File "C:\Users\jackm\Desktop\tutor\flask\lib\site-packages\flask\app.py", line 1598, in dispatch_request
    return self.view_functions[rule.endpoint](**req.view_args)
  File "C:\Users\jackm\Desktop\tutor\app\views.py", line 53, in chat
    return redirect(url_for('room'), roomname=form.roomname.data)
  File "C:\Users\jackm\Desktop\tutor\flask\lib\site-packages\flask\helpers.py", line 333, in url_for
    return appctx.app.handle_url_build_error(error, endpoint, values)
  File "C:\Users\jackm\Desktop\tutor\flask\lib\site-packages\flask\app.py", line 1805, in handle_url_build_error
    reraise(exc_type, exc_value, tb)
  File "C:\Users\jackm\Desktop\tutor\flask\lib\site-packages\flask\_compat.py", line 33, in reraise
    raise value
  File "C:\Users\jackm\Desktop\tutor\flask\lib\site-packages\flask\helpers.py", line 323, in url_for
    force_external=external)
  File "C:\Users\jackm\Desktop\tutor\flask\lib\site-packages\werkzeug\routing.py", line 1768, in build
    raise BuildError(endpoint, values, method, self)
werkzeug.routing.BuildError: Could not build url for endpoint 'room'. Did you forget to specify values ['roomname']?
2017-07-14 17:39:41,571 INFO: tutor startup [in C:\Users\jackm\Desktop\tutor\app\__init__.py:25]
2017-07-14 17:43:05,838 INFO: tutor startup [in C:\Users\jackm\Desktop\tutor\app\__init__.py:25]
2017-07-14 17:44:32,882 INFO: tutor startup [in C:\Users\jackm\Desktop\tutor\app\__init__.py:25]
2017-07-14 17:45:28,745 INFO: tutor startup [in C:\Users\jackm\Desktop\tutor\app\__init__.py:25]
2017-07-14 17:47:23,229 INFO: tutor startup [in C:\Users\jackm\Desktop\tutor\app\__init__.py:25]
2017-07-14 17:51:26,382 INFO: tutor startup [in C:\Users\jackm\Desktop\tutor\app\__init__.py:25]
2017-07-14 18:03:51,268 INFO: tutor startup [in C:\Users\jackm\Desktop\tutor\app\__init__.py:25]
2017-07-14 18:05:59,066 INFO: tutor startup [in C:\Users\jackm\Desktop\tutor\app\__init__.py:25]
2017-07-14 18:10:40,065 INFO: tutor startup [in C:\Users\jackm\Desktop\tutor\app\__init__.py:25]
2017-07-14 18:20:29,171 INFO: tutor startup [in C:\Users\jackm\Desktop\tutor\app\__init__.py:25]
2017-07-15 15:34:29,332 INFO: tutor startup [in C:\Users\jackm\Desktop\tutor\app\__init__.py:25]
2017-07-15 16:08:15,356 INFO: tutor startup [in C:\Users\jackm\Desktop\tutor\app\__init__.py:25]
2017-07-15 16:17:25,926 INFO: tutor startup [in C:\Users\jackm\Desktop\tutor\app\__init__.py:25]
2017-07-15 16:18:20,429 INFO: tutor startup [in C:\Users\jackm\Desktop\tutor\app\__init__.py:25]
2017-07-15 16:20:26,636 INFO: tutor startup [in C:\Users\jackm\Desktop\tutor\app\__init__.py:25]
2017-07-15 16:21:01,451 INFO: tutor startup [in C:\Users\jackm\Desktop\tutor\app\__init__.py:25]
2017-07-15 16:21:42,441 INFO: tutor startup [in C:\Users\jackm\Desktop\tutor\app\__init__.py:25]
2017-07-16 15:29:13,443 INFO: tutor startup [in C:\Users\jackm\Desktop\tutor\app\__init__.py:25]
2017-07-16 15:46:00,036 INFO: tutor startup [in C:\Users\jackm\Desktop\tutor\app\__init__.py:25]
2017-07-16 15:56:14,028 INFO: tutor startup [in C:\Users\jackm\Desktop\tutor\app\__init__.py:25]
2017-07-16 15:56:33,866 INFO: tutor startup [in C:\Users\jackm\Desktop\tutor\app\__init__.py:25]
2017-07-16 15:58:38,835 INFO: tutor startup [in C:\Users\jackm\Desktop\tutor\app\__init__.py:25]
2017-07-16 15:58:53,499 INFO: tutor startup [in C:\Users\jackm\Desktop\tutor\app\__init__.py:25]
2017-07-16 16:57:16,141 INFO: tutor startup [in C:\Users\jackm\Desktop\tutor\app\__init__.py:25]
2017-07-16 17:00:58,007 INFO: tutor startup [in C:\Users\jackm\Desktop\tutor\app\__init__.py:25]
2017-07-16 17:03:53,026 INFO: tutor startup [in C:\Users\jackm\Desktop\tutor\app\__init__.py:25]
2017-07-16 17:04:21,574 INFO: tutor startup [in C:\Users\jackm\Desktop\tutor\app\__init__.py:25]
2017-07-16 17:05:02,507 INFO: tutor startup [in C:\Users\jackm\Desktop\tutor\app\__init__.py:25]
2017-07-16 17:07:28,059 INFO: tutor startup [in C:\Users\jackm\Desktop\tutor\app\__init__.py:25]
2017-07-16 17:09:24,260 INFO: tutor startup [in C:\Users\jackm\Desktop\tutor\app\__init__.py:25]
2017-07-16 17:11:20,127 INFO: tutor startup [in C:\Users\jackm\Desktop\tutor\app\__init__.py:25]
2017-07-16 17:12:50,939 INFO: tutor startup [in C:\Users\jackm\Desktop\tutor\app\__init__.py:25]
2017-07-16 17:14:14,466 INFO: tutor startup [in C:\Users\jackm\Desktop\tutor\app\__init__.py:25]
2017-07-16 17:52:19,900 INFO: tutor startup [in C:\Users\jackm\Desktop\tutor\app\__init__.py:25]
2017-07-16 17:52:41,469 INFO: tutor startup [in C:\Users\jackm\Desktop\tutor\app\__init__.py:25]
2017-07-16 17:56:27,779 INFO: tutor startup [in C:\Users\jackm\Desktop\tutor\app\__init__.py:25]
2017-07-16 18:01:10,177 INFO: tutor startup [in C:\Users\jackm\Desktop\tutor\app\__init__.py:25]
2017-07-16 18:54:57,468 INFO: tutor startup [in C:\Users\jackm\Desktop\tutor\app\__init__.py:25]
2017-07-16 19:01:50,609 INFO: tutor startup [in C:\Users\jackm\Desktop\tutor\app\__init__.py:25]
2017-07-16 19:06:48,269 INFO: tutor startup [in C:\Users\jackm\Desktop\tutor\app\__init__.py:25]
2017-07-16 19:09:17,326 INFO: tutor startup [in C:\Users\jackm\Desktop\tutor\app\__init__.py:25]
2017-07-16 19:13:40,626 INFO: tutor startup [in C:\Users\jackm\Desktop\tutor\app\__init__.py:25]
2017-07-16 19:18:16,517 INFO: tutor startup [in C:\Users\jackm\Desktop\tutor\app\__init__.py:25]
2017-07-16 19:27:32,216 INFO: tutor startup [in C:\Users\jackm\Desktop\tutor\app\__init__.py:25]
2017-07-17 10:50:06,915 INFO: tutor startup [in C:\Users\jackm\Desktop\tutor\app\__init__.py:25]
2017-07-17 10:51:27,111 INFO: tutor startup [in C:\Users\jackm\Desktop\tutor\app\__init__.py:25]
2017-07-17 10:53:03,827 INFO: tutor startup [in C:\Users\jackm\Desktop\tutor\app\__init__.py:25]
2017-07-17 10:54:17,958 INFO: tutor startup [in C:\Users\jackm\Desktop\tutor\app\__init__.py:25]
2017-07-17 11:00:07,833 INFO: tutor startup [in C:\Users\jackm\Desktop\tutor\app\__init__.py:25]
2017-07-17 11:01:35,221 INFO: tutor startup [in C:\Users\jackm\Desktop\tutor\app\__init__.py:25]
2017-07-17 11:02:57,452 INFO: tutor startup [in C:\Users\jackm\Desktop\tutor\app\__init__.py:25]
2017-07-17 11:03:50,691 INFO: tutor startup [in C:\Users\jackm\Desktop\tutor\app\__init__.py:25]
2017-07-17 11:05:30,720 INFO: tutor startup [in C:\Users\jackm\Desktop\tutor\app\__init__.py:25]
2017-07-17 11:06:43,867 INFO: tutor startup [in C:\Users\jackm\Desktop\tutor\app\__init__.py:25]
2017-07-17 11:10:07,461 INFO: tutor startup [in C:\Users\jackm\Desktop\tutor\app\__init__.py:25]
2017-07-17 11:11:22,350 INFO: tutor startup [in C:\Users\jackm\Desktop\tutor\app\__init__.py:25]
2017-07-17 11:12:42,958 INFO: tutor startup [in C:\Users\jackm\Desktop\tutor\app\__init__.py:25]
2017-07-17 11:13:58,072 INFO: tutor startup [in C:\Users\jackm\Desktop\tutor\app\__init__.py:25]
2017-07-17 11:16:17,292 INFO: tutor startup [in C:\Users\jackm\Desktop\tutor\app\__init__.py:25]
2017-07-17 11:21:00,814 INFO: tutor startup [in C:\Users\jackm\Desktop\tutor\app\__init__.py:25]
2017-07-17 11:21:33,201 INFO: tutor startup [in C:\Users\jackm\Desktop\tutor\app\__init__.py:25]
2017-07-17 11:27:24,806 INFO: tutor startup [in C:\Users\jackm\Desktop\tutor\app\__init__.py:25]
2017-07-17 11:29:36,772 INFO: tutor startup [in C:\Users\jackm\Desktop\tutor\app\__init__.py:25]
2017-07-17 11:30:39,354 INFO: tutor startup [in C:\Users\jackm\Desktop\tutor\app\__init__.py:25]
2017-07-17 11:39:43,342 INFO: tutor startup [in C:\Users\jackm\Desktop\tutor\app\__init__.py:25]
2017-07-17 11:39:46,326 INFO: tutor startup [in C:\Users\jackm\Desktop\tutor\app\__init__.py:25]
2017-07-17 11:42:45,341 INFO: tutor startup [in C:\Users\jackm\Desktop\tutor\app\__init__.py:25]
2017-07-17 11:42:52,247 INFO: tutor startup [in C:\Users\jackm\Desktop\tutor\app\__init__.py:25]
2017-07-17 11:48:21,452 INFO: tutor startup [in C:\Users\jackm\Desktop\tutor\app\__init__.py:25]
2017-07-17 11:50:19,169 INFO: tutor startup [in C:\Users\jackm\Desktop\tutor\app\__init__.py:25]
2017-07-17 11:50:23,775 INFO: tutor startup [in C:\Users\jackm\Desktop\tutor\app\__init__.py:25]
2017-07-17 11:51:18,256 INFO: tutor startup [in C:\Users\jackm\Desktop\tutor\app\__init__.py:25]
2017-07-17 11:52:47,483 INFO: tutor startup [in C:\Users\jackm\Desktop\tutor\app\__init__.py:25]
2017-07-17 11:52:52,046 INFO: tutor startup [in C:\Users\jackm\Desktop\tutor\app\__init__.py:25]
2017-07-17 11:53:21,786 INFO: tutor startup [in C:\Users\jackm\Desktop\tutor\app\__init__.py:25]
2017-07-17 11:56:25,912 INFO: tutor startup [in C:\Users\jackm\Desktop\tutor\app\__init__.py:25]
2017-07-17 11:56:37,013 INFO: tutor startup [in C:\Users\jackm\Desktop\tutor\app\__init__.py:25]
2017-07-17 11:57:52,847 INFO: tutor startup [in C:\Users\jackm\Desktop\tutor\app\__init__.py:25]
2017-07-17 11:58:57,517 INFO: tutor startup [in C:\Users\jackm\Desktop\tutor\app\__init__.py:25]
2017-07-17 12:00:54,711 INFO: tutor startup [in C:\Users\jackm\Desktop\tutor\app\__init__.py:25]
2017-07-17 12:01:59,658 INFO: tutor startup [in C:\Users\jackm\Desktop\tutor\app\__init__.py:25]
2017-07-17 21:50:13,947 INFO: tutor startup [in C:\Users\jackm\Desktop\tutor\app\__init__.py:25]
2017-07-17 21:51:54,817 INFO: tutor startup [in C:\Users\jackm\Desktop\tutor\app\__init__.py:25]
2017-07-17 21:53:19,126 INFO: tutor startup [in C:\Users\jackm\Desktop\tutor\app\__init__.py:25]
2017-07-17 21:53:22,684 INFO: tutor startup [in C:\Users\jackm\Desktop\tutor\app\__init__.py:25]
2017-07-17 21:55:29,597 INFO: tutor startup [in C:\Users\jackm\Desktop\tutor\app\__init__.py:25]
2017-07-17 22:08:43,699 INFO: tutor startup [in C:\Users\jackm\Desktop\tutor\app\__init__.py:25]
2017-07-17 22:08:45,917 ERROR: Exception on / [GET] [in C:\Users\jackm\Desktop\tutor\flask\lib\site-packages\flask\app.py:1560]
Traceback (most recent call last):
  File "C:\Users\jackm\Desktop\tutor\flask\lib\site-packages\sqlalchemy\engine\base.py", line 1182, in _execute_context
    context)
  File "C:\Users\jackm\Desktop\tutor\flask\lib\site-packages\sqlalchemy\engine\default.py", line 470, in do_execute
    cursor.execute(statement, parameters)
sqlite3.OperationalError: no such column: users.about_me

The above exception was the direct cause of the following exception:

Traceback (most recent call last):
  File "C:\Users\jackm\Desktop\tutor\flask\lib\site-packages\flask\app.py", line 1982, in wsgi_app
    response = self.full_dispatch_request()
  File "C:\Users\jackm\Desktop\tutor\flask\lib\site-packages\flask\app.py", line 1614, in full_dispatch_request
    rv = self.handle_user_exception(e)
  File "C:\Users\jackm\Desktop\tutor\flask\lib\site-packages\flask\app.py", line 1517, in handle_user_exception
    reraise(exc_type, exc_value, tb)
  File "C:\Users\jackm\Desktop\tutor\flask\lib\site-packages\flask\_compat.py", line 33, in reraise
    raise value
  File "C:\Users\jackm\Desktop\tutor\flask\lib\site-packages\flask\app.py", line 1612, in full_dispatch_request
    rv = self.dispatch_request()
  File "C:\Users\jackm\Desktop\tutor\flask\lib\site-packages\flask\app.py", line 1598, in dispatch_request
    return self.view_functions[rule.endpoint](**req.view_args)
  File "C:\Users\jackm\Desktop\tutor\app\views.py", line 17, in home
    user=g.user)
  File "C:\Users\jackm\Desktop\tutor\flask\lib\site-packages\flask\templating.py", line 132, in render_template
    ctx.app.update_template_context(context)
  File "C:\Users\jackm\Desktop\tutor\flask\lib\site-packages\flask\app.py", line 764, in update_template_context
    context.update(func())
  File "C:\Users\jackm\Desktop\tutor\flask\lib\site-packages\flask_login\utils.py", line 335, in _user_context_processor
    return dict(current_user=_get_user())
  File "C:\Users\jackm\Desktop\tutor\flask\lib\site-packages\flask_login\utils.py", line 302, in _get_user
    current_app.login_manager._load_user()
  File "C:\Users\jackm\Desktop\tutor\flask\lib\site-packages\flask_login\login_manager.py", line 317, in _load_user
    return self.reload_user()
  File "C:\Users\jackm\Desktop\tutor\flask\lib\site-packages\flask_login\login_manager.py", line 279, in reload_user
    user = self.user_callback(user_id)
  File "C:\Users\jackm\Desktop\tutor\app\__init__.py", line 15, in load_user
    return User.query.get(int(id))
  File "C:\Users\jackm\Desktop\tutor\flask\lib\site-packages\sqlalchemy\orm\query.py", line 864, in get
    return self._get_impl(ident, loading.load_on_ident)
  File "C:\Users\jackm\Desktop\tutor\flask\lib\site-packages\sqlalchemy\orm\query.py", line 897, in _get_impl
    return fallback_fn(self, key)
  File "C:\Users\jackm\Desktop\tutor\flask\lib\site-packages\sqlalchemy\orm\loading.py", line 223, in load_on_ident
    return q.one()
  File "C:\Users\jackm\Desktop\tutor\flask\lib\site-packages\sqlalchemy\orm\query.py", line 2814, in one
    ret = self.one_or_none()
  File "C:\Users\jackm\Desktop\tutor\flask\lib\site-packages\sqlalchemy\orm\query.py", line 2784, in one_or_none
    ret = list(self)
  File "C:\Users\jackm\Desktop\tutor\flask\lib\site-packages\sqlalchemy\orm\query.py", line 2855, in __iter__
    return self._execute_and_instances(context)
  File "C:\Users\jackm\Desktop\tutor\flask\lib\site-packages\sqlalchemy\orm\query.py", line 2878, in _execute_and_instances
    result = conn.execute(querycontext.statement, self._params)
  File "C:\Users\jackm\Desktop\tutor\flask\lib\site-packages\sqlalchemy\engine\base.py", line 945, in execute
    return meth(self, multiparams, params)
  File "C:\Users\jackm\Desktop\tutor\flask\lib\site-packages\sqlalchemy\sql\elements.py", line 263, in _execute_on_connection
    return connection._execute_clauseelement(self, multiparams, params)
  File "C:\Users\jackm\Desktop\tutor\flask\lib\site-packages\sqlalchemy\engine\base.py", line 1053, in _execute_clauseelement
    compiled_sql, distilled_params
  File "C:\Users\jackm\Desktop\tutor\flask\lib\site-packages\sqlalchemy\engine\base.py", line 1189, in _execute_context
    context)
  File "C:\Users\jackm\Desktop\tutor\flask\lib\site-packages\sqlalchemy\engine\base.py", line 1402, in _handle_dbapi_exception
    exc_info
  File "C:\Users\jackm\Desktop\tutor\flask\lib\site-packages\sqlalchemy\util\compat.py", line 203, in raise_from_cause
    reraise(type(exception), exception, tb=exc_tb, cause=cause)
  File "C:\Users\jackm\Desktop\tutor\flask\lib\site-packages\sqlalchemy\util\compat.py", line 186, in reraise
    raise value.with_traceback(tb)
  File "C:\Users\jackm\Desktop\tutor\flask\lib\site-packages\sqlalchemy\engine\base.py", line 1182, in _execute_context
    context)
  File "C:\Users\jackm\Desktop\tutor\flask\lib\site-packages\sqlalchemy\engine\default.py", line 470, in do_execute
    cursor.execute(statement, parameters)
sqlalchemy.exc.OperationalError: (sqlite3.OperationalError) no such column: users.about_me [SQL: 'SELECT users.id AS users_id, users.social_id AS users_social_id, users.nickname AS users_nickname, users.email AS users_email, users.auth_provider AS users_auth_provider, users.profile_picture_url AS users_profile_picture_url, users.about_me AS users_about_me, users.total_time_online AS users_total_time_online \nFROM users \nWHERE users.id = ?'] [parameters: (1,)]
2017-07-17 22:09:10,158 INFO: tutor startup [in C:\Users\jackm\Desktop\tutor\app\__init__.py:25]
2017-07-17 22:09:13,789 INFO: tutor startup [in C:\Users\jackm\Desktop\tutor\app\__init__.py:25]
2017-07-17 22:12:35,477 INFO: tutor startup [in C:\Users\jackm\Desktop\tutor\app\__init__.py:25]
2017-07-17 22:22:29,757 INFO: tutor startup [in C:\Users\jackm\Desktop\tutor\app\__init__.py:25]
2017-07-17 22:22:36,776 ERROR: Exception on /edit [GET] [in C:\Users\jackm\Desktop\tutor\flask\lib\site-packages\flask\app.py:1560]
Traceback (most recent call last):
  File "C:\Users\jackm\Desktop\tutor\flask\lib\site-packages\flask\app.py", line 1982, in wsgi_app
    response = self.full_dispatch_request()
  File "C:\Users\jackm\Desktop\tutor\flask\lib\site-packages\flask\app.py", line 1614, in full_dispatch_request
    rv = self.handle_user_exception(e)
  File "C:\Users\jackm\Desktop\tutor\flask\lib\site-packages\flask\app.py", line 1517, in handle_user_exception
    reraise(exc_type, exc_value, tb)
  File "C:\Users\jackm\Desktop\tutor\flask\lib\site-packages\flask\_compat.py", line 33, in reraise
    raise value
  File "C:\Users\jackm\Desktop\tutor\flask\lib\site-packages\flask\app.py", line 1612, in full_dispatch_request
    rv = self.dispatch_request()
  File "C:\Users\jackm\Desktop\tutor\flask\lib\site-packages\flask\app.py", line 1598, in dispatch_request
    return self.view_functions[rule.endpoint](**req.view_args)
  File "C:\Users\jackm\Desktop\tutor\flask\lib\site-packages\flask_login\utils.py", line 228, in decorated_view
    return func(*args, **kwargs)
  File "C:\Users\jackm\Desktop\tutor\app\views.py", line 32, in edit
    form = EditForm()
  File "C:\Users\jackm\Desktop\tutor\flask\lib\site-packages\wtforms\form.py", line 212, in __call__
    return type.__call__(cls, *args, **kwargs)
TypeError: __init__() missing 1 required positional argument: 'original_nickname'
2017-07-17 22:22:59,509 ERROR: Exception on /edit [GET] [in C:\Users\jackm\Desktop\tutor\flask\lib\site-packages\flask\app.py:1560]
Traceback (most recent call last):
  File "C:\Users\jackm\Desktop\tutor\flask\lib\site-packages\flask\app.py", line 1982, in wsgi_app
    response = self.full_dispatch_request()
  File "C:\Users\jackm\Desktop\tutor\flask\lib\site-packages\flask\app.py", line 1614, in full_dispatch_request
    rv = self.handle_user_exception(e)
  File "C:\Users\jackm\Desktop\tutor\flask\lib\site-packages\flask\app.py", line 1517, in handle_user_exception
    reraise(exc_type, exc_value, tb)
  File "C:\Users\jackm\Desktop\tutor\flask\lib\site-packages\flask\_compat.py", line 33, in reraise
    raise value
  File "C:\Users\jackm\Desktop\tutor\flask\lib\site-packages\flask\app.py", line 1612, in full_dispatch_request
    rv = self.dispatch_request()
  File "C:\Users\jackm\Desktop\tutor\flask\lib\site-packages\flask\app.py", line 1598, in dispatch_request
    return self.view_functions[rule.endpoint](**req.view_args)
  File "C:\Users\jackm\Desktop\tutor\flask\lib\site-packages\flask_login\utils.py", line 228, in decorated_view
    return func(*args, **kwargs)
  File "C:\Users\jackm\Desktop\tutor\app\views.py", line 32, in edit
    form = EditForm()
  File "C:\Users\jackm\Desktop\tutor\flask\lib\site-packages\wtforms\form.py", line 212, in __call__
    return type.__call__(cls, *args, **kwargs)
TypeError: __init__() missing 1 required positional argument: 'original_nickname'
2017-07-17 22:23:17,217 INFO: tutor startup [in C:\Users\jackm\Desktop\tutor\app\__init__.py:25]
2017-07-17 22:27:53,661 INFO: tutor startup [in C:\Users\jackm\Desktop\tutor\app\__init__.py:25]
2017-07-17 22:28:14,037 ERROR: Exception on /edit [POST] [in C:\Users\jackm\Desktop\tutor\flask\lib\site-packages\flask\app.py:1560]
Traceback (most recent call last):
  File "C:\Users\jackm\Desktop\tutor\flask\lib\site-packages\flask\app.py", line 1982, in wsgi_app
    response = self.full_dispatch_request()
  File "C:\Users\jackm\Desktop\tutor\flask\lib\site-packages\flask\app.py", line 1614, in full_dispatch_request
    rv = self.handle_user_exception(e)
  File "C:\Users\jackm\Desktop\tutor\flask\lib\site-packages\flask\app.py", line 1517, in handle_user_exception
    reraise(exc_type, exc_value, tb)
  File "C:\Users\jackm\Desktop\tutor\flask\lib\site-packages\flask\_compat.py", line 33, in reraise
    raise value
  File "C:\Users\jackm\Desktop\tutor\flask\lib\site-packages\flask\app.py", line 1612, in full_dispatch_request
    rv = self.dispatch_request()
  File "C:\Users\jackm\Desktop\tutor\flask\lib\site-packages\flask\app.py", line 1598, in dispatch_request
    return self.view_functions[rule.endpoint](**req.view_args)
  File "C:\Users\jackm\Desktop\tutor\flask\lib\site-packages\flask_login\utils.py", line 228, in decorated_view
    return func(*args, **kwargs)
  File "C:\Users\jackm\Desktop\tutor\app\views.py", line 33, in edit
    if form.validate_on_submit():
  File "C:\Users\jackm\Desktop\tutor\flask\lib\site-packages\flask_wtf\form.py", line 101, in validate_on_submit
    return self.is_submitted() and self.validate()
  File "C:\Users\jackm\Desktop\tutor\app\forms.py", line 19, in validate
    if self.nickname.data == self.original_nickname:
AttributeError: 'EditForm' object has no attribute 'original_nickname'
2017-07-17 22:28:38,041 ERROR: Exception on /edit [POST] [in C:\Users\jackm\Desktop\tutor\flask\lib\site-packages\flask\app.py:1560]
Traceback (most recent call last):
  File "C:\Users\jackm\Desktop\tutor\flask\lib\site-packages\flask\app.py", line 1982, in wsgi_app
    response = self.full_dispatch_request()
  File "C:\Users\jackm\Desktop\tutor\flask\lib\site-packages\flask\app.py", line 1614, in full_dispatch_request
    rv = self.handle_user_exception(e)
  File "C:\Users\jackm\Desktop\tutor\flask\lib\site-packages\flask\app.py", line 1517, in handle_user_exception
    reraise(exc_type, exc_value, tb)
  File "C:\Users\jackm\Desktop\tutor\flask\lib\site-packages\flask\_compat.py", line 33, in reraise
    raise value
  File "C:\Users\jackm\Desktop\tutor\flask\lib\site-packages\flask\app.py", line 1612, in full_dispatch_request
    rv = self.dispatch_request()
  File "C:\Users\jackm\Desktop\tutor\flask\lib\site-packages\flask\app.py", line 1598, in dispatch_request
    return self.view_functions[rule.endpoint](**req.view_args)
  File "C:\Users\jackm\Desktop\tutor\flask\lib\site-packages\flask_login\utils.py", line 228, in decorated_view
    return func(*args, **kwargs)
  File "C:\Users\jackm\Desktop\tutor\app\views.py", line 33, in edit
    if form.validate_on_submit():
  File "C:\Users\jackm\Desktop\tutor\flask\lib\site-packages\flask_wtf\form.py", line 101, in validate_on_submit
    return self.is_submitted() and self.validate()
  File "C:\Users\jackm\Desktop\tutor\app\forms.py", line 19, in validate
    if self.nickname.data == self.original_nickname:
AttributeError: 'EditForm' object has no attribute 'original_nickname'
2017-07-17 22:29:05,477 ERROR: Exception on /edit [POST] [in C:\Users\jackm\Desktop\tutor\flask\lib\site-packages\flask\app.py:1560]
Traceback (most recent call last):
  File "C:\Users\jackm\Desktop\tutor\flask\lib\site-packages\flask\app.py", line 1982, in wsgi_app
    response = self.full_dispatch_request()
  File "C:\Users\jackm\Desktop\tutor\flask\lib\site-packages\flask\app.py", line 1614, in full_dispatch_request
    rv = self.handle_user_exception(e)
  File "C:\Users\jackm\Desktop\tutor\flask\lib\site-packages\flask\app.py", line 1517, in handle_user_exception
    reraise(exc_type, exc_value, tb)
  File "C:\Users\jackm\Desktop\tutor\flask\lib\site-packages\flask\_compat.py", line 33, in reraise
    raise value
  File "C:\Users\jackm\Desktop\tutor\flask\lib\site-packages\flask\app.py", line 1612, in full_dispatch_request
    rv = self.dispatch_request()
  File "C:\Users\jackm\Desktop\tutor\flask\lib\site-packages\flask\app.py", line 1598, in dispatch_request
    return self.view_functions[rule.endpoint](**req.view_args)
  File "C:\Users\jackm\Desktop\tutor\flask\lib\site-packages\flask_login\utils.py", line 228, in decorated_view
    return func(*args, **kwargs)
  File "C:\Users\jackm\Desktop\tutor\app\views.py", line 33, in edit
    if form.validate_on_submit():
  File "C:\Users\jackm\Desktop\tutor\flask\lib\site-packages\flask_wtf\form.py", line 101, in validate_on_submit
    return self.is_submitted() and self.validate()
  File "C:\Users\jackm\Desktop\tutor\app\forms.py", line 19, in validate
    if self.nickname.data == self.original_nickname:
AttributeError: 'EditForm' object has no attribute 'original_nickname'
2017-07-17 22:29:46,748 INFO: tutor startup [in C:\Users\jackm\Desktop\tutor\app\__init__.py:25]
2017-07-17 22:29:54,269 ERROR: Exception on /edit [GET] [in C:\Users\jackm\Desktop\tutor\flask\lib\site-packages\flask\app.py:1560]
Traceback (most recent call last):
  File "C:\Users\jackm\Desktop\tutor\flask\lib\site-packages\flask\app.py", line 1982, in wsgi_app
    response = self.full_dispatch_request()
  File "C:\Users\jackm\Desktop\tutor\flask\lib\site-packages\flask\app.py", line 1614, in full_dispatch_request
    rv = self.handle_user_exception(e)
  File "C:\Users\jackm\Desktop\tutor\flask\lib\site-packages\flask\app.py", line 1517, in handle_user_exception
    reraise(exc_type, exc_value, tb)
  File "C:\Users\jackm\Desktop\tutor\flask\lib\site-packages\flask\_compat.py", line 33, in reraise
    raise value
  File "C:\Users\jackm\Desktop\tutor\flask\lib\site-packages\flask\app.py", line 1612, in full_dispatch_request
    rv = self.dispatch_request()
  File "C:\Users\jackm\Desktop\tutor\flask\lib\site-packages\flask\app.py", line 1598, in dispatch_request
    return self.view_functions[rule.endpoint](**req.view_args)
  File "C:\Users\jackm\Desktop\tutor\flask\lib\site-packages\flask_login\utils.py", line 228, in decorated_view
    return func(*args, **kwargs)
  File "C:\Users\jackm\Desktop\tutor\app\views.py", line 32, in edit
    form = EditForm()
  File "C:\Users\jackm\Desktop\tutor\flask\lib\site-packages\wtforms\form.py", line 212, in __call__
    return type.__call__(cls, *args, **kwargs)
TypeError: __init__() missing 1 required positional argument: 'original_nickname'
2017-07-17 22:30:14,852 INFO: tutor startup [in C:\Users\jackm\Desktop\tutor\app\__init__.py:25]
2017-07-17 22:35:10,979 INFO: tutor startup [in C:\Users\jackm\Desktop\tutor\app\__init__.py:25]
2017-07-17 22:37:08,226 INFO: tutor startup [in C:\Users\jackm\Desktop\tutor\app\__init__.py:25]
2017-07-18 10:45:17,601 INFO: tutor startup [in C:\Users\jackm\Desktop\tutor\app\__init__.py:25]
2017-07-18 10:48:11,871 INFO: tutor startup [in C:\Users\jackm\Desktop\tutor\app\__init__.py:25]
2017-07-21 17:51:45,083 INFO: tutor startup [in C:\Users\jackm\Desktop\tutor\app\__init__.py:25]
2017-07-21 17:52:52,062 INFO: tutor startup [in C:\Users\jackm\Desktop\tutor\app\__init__.py:25]
2017-07-21 17:53:25,728 INFO: tutor startup [in C:\Users\jackm\Desktop\tutor\app\__init__.py:25]
2017-07-21 17:53:56,906 INFO: tutor startup [in C:\Users\jackm\Desktop\tutor\app\__init__.py:25]
2017-07-21 18:03:15,817 INFO: tutor startup [in C:\Users\jackm\Desktop\tutor\app\__init__.py:25]
2017-07-21 18:03:28,895 INFO: tutor startup [in C:\Users\jackm\Desktop\tutor\app\__init__.py:25]
2017-07-21 18:06:37,962 INFO: tutor startup [in C:\Users\jackm\Desktop\tutor\app\__init__.py:25]
2017-07-21 18:08:36,092 INFO: tutor startup [in C:\Users\jackm\Desktop\tutor\app\__init__.py:25]
2017-07-21 18:08:50,722 INFO: tutor startup [in C:\Users\jackm\Desktop\tutor\app\__init__.py:25]
2017-07-21 18:10:06,587 INFO: tutor startup [in C:\Users\jackm\Desktop\tutor\app\__init__.py:25]
2017-07-21 18:10:39,369 INFO: tutor startup [in C:\Users\jackm\Desktop\tutor\app\__init__.py:25]
2017-07-21 18:12:03,274 INFO: tutor startup [in C:\Users\jackm\Desktop\tutor\app\__init__.py:25]
2017-07-21 18:14:44,723 INFO: tutor startup [in C:\Users\jackm\Desktop\tutor\app\__init__.py:25]
2017-07-21 18:15:30,497 INFO: tutor startup [in C:\Users\jackm\Desktop\tutor\app\__init__.py:25]
2017-07-21 18:16:15,502 INFO: tutor startup [in C:\Users\jackm\Desktop\tutor\app\__init__.py:25]
2017-07-21 18:20:45,219 INFO: tutor startup [in C:\Users\jackm\Desktop\tutor\app\__init__.py:25]
2017-07-21 18:22:45,137 INFO: tutor startup [in C:\Users\jackm\Desktop\tutor\app\__init__.py:25]
2017-07-21 18:35:32,640 INFO: tutor startup [in C:\Users\jackm\Desktop\tutor\app\__init__.py:25]
2017-07-21 18:35:41,757 INFO: tutor startup [in C:\Users\jackm\Desktop\tutor\app\__init__.py:25]
2017-07-21 18:36:08,016 INFO: tutor startup [in C:\Users\jackm\Desktop\tutor\app\__init__.py:25]
2017-07-21 18:42:13,857 INFO: tutor startup [in C:\Users\jackm\Desktop\tutor\app\__init__.py:25]
2017-07-21 18:42:33,605 INFO: tutor startup [in C:\Users\jackm\Desktop\tutor\app\__init__.py:25]
2017-07-21 18:42:40,140 INFO: tutor startup [in C:\Users\jackm\Desktop\tutor\app\__init__.py:25]
2017-07-21 18:43:54,141 INFO: tutor startup [in C:\Users\jackm\Desktop\tutor\app\__init__.py:25]
2017-07-21 18:44:01,891 INFO: tutor startup [in C:\Users\jackm\Desktop\tutor\app\__init__.py:25]
2017-07-21 18:45:15,622 INFO: tutor startup [in C:\Users\jackm\Desktop\tutor\app\__init__.py:25]
2017-07-21 18:45:21,841 INFO: tutor startup [in C:\Users\jackm\Desktop\tutor\app\__init__.py:25]
2017-07-21 18:46:57,516 INFO: tutor startup [in C:\Users\jackm\Desktop\tutor\app\__init__.py:25]
2017-07-21 18:51:23,963 INFO: tutor startup [in C:\Users\jackm\Desktop\tutor\app\__init__.py:25]
2017-07-21 18:51:32,510 INFO: tutor startup [in C:\Users\jackm\Desktop\tutor\app\__init__.py:25]
2017-07-21 18:52:34,330 INFO: tutor startup [in C:\Users\jackm\Desktop\tutor\app\__init__.py:25]
2017-07-21 18:52:57,961 INFO: tutor startup [in C:\Users\jackm\Desktop\tutor\app\__init__.py:25]
2017-07-21 18:53:40,665 INFO: tutor startup [in C:\Users\jackm\Desktop\tutor\app\__init__.py:25]
2017-07-21 19:12:38,217 INFO: tutor startup [in C:\Users\jackm\Desktop\tutor\app\__init__.py:25]
2017-07-21 19:12:48,805 INFO: tutor startup [in C:\Users\jackm\Desktop\tutor\app\__init__.py:25]
2017-07-21 19:19:26,920 INFO: tutor startup [in C:\Users\jackm\Desktop\tutor\app\__init__.py:25]
2017-07-21 19:19:35,276 INFO: tutor startup [in C:\Users\jackm\Desktop\tutor\app\__init__.py:25]
2017-07-21 19:23:49,647 INFO: tutor startup [in C:\Users\jackm\Desktop\tutor\app\__init__.py:25]
2017-07-21 19:26:07,179 INFO: tutor startup [in C:\Users\jackm\Desktop\tutor\app\__init__.py:25]
2017-07-21 19:34:24,831 INFO: tutor startup [in C:\Users\jackm\Desktop\tutor\app\__init__.py:25]
2017-07-21 19:36:32,942 INFO: tutor startup [in C:\Users\jackm\Desktop\tutor\app\__init__.py:25]
2017-07-21 19:37:49,783 INFO: tutor startup [in C:\Users\jackm\Desktop\tutor\app\__init__.py:25]
2017-07-21 19:38:47,526 INFO: tutor startup [in C:\Users\jackm\Desktop\tutor\app\__init__.py:25]
2017-07-21 19:47:33,428 INFO: tutor startup [in C:\Users\jackm\Desktop\tutor\app\__init__.py:25]
2017-07-21 19:48:06,554 ERROR: Exception on /room/jimmus [GET] [in C:\Users\jackm\Desktop\tutor\flask\lib\site-packages\flask\app.py:1560]
Traceback (most recent call last):
  File "C:\Users\jackm\Desktop\tutor\flask\lib\site-packages\flask\app.py", line 1982, in wsgi_app
    response = self.full_dispatch_request()
  File "C:\Users\jackm\Desktop\tutor\flask\lib\site-packages\flask\app.py", line 1614, in full_dispatch_request
    rv = self.handle_user_exception(e)
  File "C:\Users\jackm\Desktop\tutor\flask\lib\site-packages\flask\app.py", line 1517, in handle_user_exception
    reraise(exc_type, exc_value, tb)
  File "C:\Users\jackm\Desktop\tutor\flask\lib\site-packages\flask\_compat.py", line 33, in reraise
    raise value
  File "C:\Users\jackm\Desktop\tutor\flask\lib\site-packages\flask\app.py", line 1612, in full_dispatch_request
    rv = self.dispatch_request()
  File "C:\Users\jackm\Desktop\tutor\flask\lib\site-packages\flask\app.py", line 1598, in dispatch_request
    return self.view_functions[rule.endpoint](**req.view_args)
  File "C:\Users\jackm\Desktop\tutor\flask\lib\site-packages\flask_login\utils.py", line 228, in decorated_view
    return func(*args, **kwargs)
  File "C:\Users\jackm\Desktop\tutor\app\views.py", line 85, in room
    room(approve_user(g.user))
NameError: name 'approve_user' is not defined
2017-07-21 19:48:47,649 INFO: tutor startup [in C:\Users\jackm\Desktop\tutor\app\__init__.py:25]
2017-07-21 19:48:56,678 ERROR: Exception on /room/jimmus [GET] [in C:\Users\jackm\Desktop\tutor\flask\lib\site-packages\flask\app.py:1560]
Traceback (most recent call last):
  File "C:\Users\jackm\Desktop\tutor\flask\lib\site-packages\flask\app.py", line 1982, in wsgi_app
    response = self.full_dispatch_request()
  File "C:\Users\jackm\Desktop\tutor\flask\lib\site-packages\flask\app.py", line 1614, in full_dispatch_request
    rv = self.handle_user_exception(e)
  File "C:\Users\jackm\Desktop\tutor\flask\lib\site-packages\flask\app.py", line 1517, in handle_user_exception
    reraise(exc_type, exc_value, tb)
  File "C:\Users\jackm\Desktop\tutor\flask\lib\site-packages\flask\_compat.py", line 33, in reraise
    raise value
  File "C:\Users\jackm\Desktop\tutor\flask\lib\site-packages\flask\app.py", line 1612, in full_dispatch_request
    rv = self.dispatch_request()
  File "C:\Users\jackm\Desktop\tutor\flask\lib\site-packages\flask\app.py", line 1598, in dispatch_request
    return self.view_functions[rule.endpoint](**req.view_args)
  File "C:\Users\jackm\Desktop\tutor\flask\lib\site-packages\flask_login\utils.py", line 228, in decorated_view
    return func(*args, **kwargs)
  File "C:\Users\jackm\Desktop\tutor\app\views.py", line 85, in room
    room.approve_user(g.user)
  File "C:\Users\jackm\Desktop\tutor\app\models.py", line 59, in approve_user
    if not self.is_approved(user):
  File "C:\Users\jackm\Desktop\tutor\app\models.py", line 69, in is_approved
    return self.approved_users.filter(UserRoom.c.userId == user.id).count() > 0
  File "<string>", line 2, in filter
  File "C:\Users\jackm\Desktop\tutor\flask\lib\site-packages\sqlalchemy\orm\base.py", line 198, in generate
    self = args[0]._clone()
  File "C:\Users\jackm\Desktop\tutor\flask\lib\site-packages\sqlalchemy\orm\dynamic.py", line 278, in _clone
    orm_util.instance_str(instance), self.attr.key))
sqlalchemy.orm.exc.DetachedInstanceError: Parent instance <Room at 0x2c390a9b4e0> is not bound to a Session, and no contextual session is established; lazy load operation of attribute 'approved_users' cannot proceed
2017-07-21 19:49:14,545 ERROR: Exception on /room/ff [GET] [in C:\Users\jackm\Desktop\tutor\flask\lib\site-packages\flask\app.py:1560]
Traceback (most recent call last):
  File "C:\Users\jackm\Desktop\tutor\flask\lib\site-packages\flask\app.py", line 1982, in wsgi_app
    response = self.full_dispatch_request()
  File "C:\Users\jackm\Desktop\tutor\flask\lib\site-packages\flask\app.py", line 1614, in full_dispatch_request
    rv = self.handle_user_exception(e)
  File "C:\Users\jackm\Desktop\tutor\flask\lib\site-packages\flask\app.py", line 1517, in handle_user_exception
    reraise(exc_type, exc_value, tb)
  File "C:\Users\jackm\Desktop\tutor\flask\lib\site-packages\flask\_compat.py", line 33, in reraise
    raise value
  File "C:\Users\jackm\Desktop\tutor\flask\lib\site-packages\flask\app.py", line 1612, in full_dispatch_request
    rv = self.dispatch_request()
  File "C:\Users\jackm\Desktop\tutor\flask\lib\site-packages\flask\app.py", line 1598, in dispatch_request
    return self.view_functions[rule.endpoint](**req.view_args)
  File "C:\Users\jackm\Desktop\tutor\flask\lib\site-packages\flask_login\utils.py", line 228, in decorated_view
    return func(*args, **kwargs)
  File "C:\Users\jackm\Desktop\tutor\app\views.py", line 85, in room
    room.approve_user(g.user)
  File "C:\Users\jackm\Desktop\tutor\app\models.py", line 59, in approve_user
    if not self.is_approved(user):
  File "C:\Users\jackm\Desktop\tutor\app\models.py", line 69, in is_approved
    return self.approved_users.filter(UserRoom.c.userId == user.id).count() > 0
  File "<string>", line 2, in filter
  File "C:\Users\jackm\Desktop\tutor\flask\lib\site-packages\sqlalchemy\orm\base.py", line 198, in generate
    self = args[0]._clone()
  File "C:\Users\jackm\Desktop\tutor\flask\lib\site-packages\sqlalchemy\orm\dynamic.py", line 278, in _clone
    orm_util.instance_str(instance), self.attr.key))
sqlalchemy.orm.exc.DetachedInstanceError: Parent instance <Room at 0x2c390ad7080> is not bound to a Session, and no contextual session is established; lazy load operation of attribute 'approved_users' cannot proceed
2017-07-21 19:49:27,795 ERROR: Exception on /room/33fas [GET] [in C:\Users\jackm\Desktop\tutor\flask\lib\site-packages\flask\app.py:1560]
Traceback (most recent call last):
  File "C:\Users\jackm\Desktop\tutor\flask\lib\site-packages\flask\app.py", line 1982, in wsgi_app
    response = self.full_dispatch_request()
  File "C:\Users\jackm\Desktop\tutor\flask\lib\site-packages\flask\app.py", line 1614, in full_dispatch_request
    rv = self.handle_user_exception(e)
  File "C:\Users\jackm\Desktop\tutor\flask\lib\site-packages\flask\app.py", line 1517, in handle_user_exception
    reraise(exc_type, exc_value, tb)
  File "C:\Users\jackm\Desktop\tutor\flask\lib\site-packages\flask\_compat.py", line 33, in reraise
    raise value
  File "C:\Users\jackm\Desktop\tutor\flask\lib\site-packages\flask\app.py", line 1612, in full_dispatch_request
    rv = self.dispatch_request()
  File "C:\Users\jackm\Desktop\tutor\flask\lib\site-packages\flask\app.py", line 1598, in dispatch_request
    return self.view_functions[rule.endpoint](**req.view_args)
  File "C:\Users\jackm\Desktop\tutor\flask\lib\site-packages\flask_login\utils.py", line 228, in decorated_view
    return func(*args, **kwargs)
  File "C:\Users\jackm\Desktop\tutor\app\views.py", line 85, in room
    room.approve_user(g.user)
  File "C:\Users\jackm\Desktop\tutor\app\models.py", line 59, in approve_user
    if not self.is_approved(user):
  File "C:\Users\jackm\Desktop\tutor\app\models.py", line 69, in is_approved
    return self.approved_users.filter(UserRoom.c.userId == user.id).count() > 0
  File "<string>", line 2, in filter
  File "C:\Users\jackm\Desktop\tutor\flask\lib\site-packages\sqlalchemy\orm\base.py", line 198, in generate
    self = args[0]._clone()
  File "C:\Users\jackm\Desktop\tutor\flask\lib\site-packages\sqlalchemy\orm\dynamic.py", line 278, in _clone
    orm_util.instance_str(instance), self.attr.key))
sqlalchemy.orm.exc.DetachedInstanceError: Parent instance <Room at 0x2c390b11ef0> is not bound to a Session, and no contextual session is established; lazy load operation of attribute 'approved_users' cannot proceed
2017-07-21 19:49:32,948 ERROR: Exception on /room/33fas [GET] [in C:\Users\jackm\Desktop\tutor\flask\lib\site-packages\flask\app.py:1560]
Traceback (most recent call last):
  File "C:\Users\jackm\Desktop\tutor\flask\lib\site-packages\flask\app.py", line 1982, in wsgi_app
    response = self.full_dispatch_request()
  File "C:\Users\jackm\Desktop\tutor\flask\lib\site-packages\flask\app.py", line 1614, in full_dispatch_request
    rv = self.handle_user_exception(e)
  File "C:\Users\jackm\Desktop\tutor\flask\lib\site-packages\flask\app.py", line 1517, in handle_user_exception
    reraise(exc_type, exc_value, tb)
  File "C:\Users\jackm\Desktop\tutor\flask\lib\site-packages\flask\_compat.py", line 33, in reraise
    raise value
  File "C:\Users\jackm\Desktop\tutor\flask\lib\site-packages\flask\app.py", line 1612, in full_dispatch_request
    rv = self.dispatch_request()
  File "C:\Users\jackm\Desktop\tutor\flask\lib\site-packages\flask\app.py", line 1598, in dispatch_request
    return self.view_functions[rule.endpoint](**req.view_args)
  File "C:\Users\jackm\Desktop\tutor\flask\lib\site-packages\flask_login\utils.py", line 228, in decorated_view
    return func(*args, **kwargs)
  File "C:\Users\jackm\Desktop\tutor\app\views.py", line 85, in room
    room.approve_user(g.user)
  File "C:\Users\jackm\Desktop\tutor\app\models.py", line 59, in approve_user
    if not self.is_approved(user):
  File "C:\Users\jackm\Desktop\tutor\app\models.py", line 69, in is_approved
    return self.approved_users.filter(UserRoom.c.userId == user.id).count() > 0
  File "<string>", line 2, in filter
  File "C:\Users\jackm\Desktop\tutor\flask\lib\site-packages\sqlalchemy\orm\base.py", line 198, in generate
    self = args[0]._clone()
  File "C:\Users\jackm\Desktop\tutor\flask\lib\site-packages\sqlalchemy\orm\dynamic.py", line 278, in _clone
    orm_util.instance_str(instance), self.attr.key))
sqlalchemy.orm.exc.DetachedInstanceError: Parent instance <Room at 0x2c390b11eb8> is not bound to a Session, and no contextual session is established; lazy load operation of attribute 'approved_users' cannot proceed
2017-07-21 19:49:47,384 ERROR: Exception on /room/ffas [GET] [in C:\Users\jackm\Desktop\tutor\flask\lib\site-packages\flask\app.py:1560]
Traceback (most recent call last):
  File "C:\Users\jackm\Desktop\tutor\flask\lib\site-packages\flask\app.py", line 1982, in wsgi_app
    response = self.full_dispatch_request()
  File "C:\Users\jackm\Desktop\tutor\flask\lib\site-packages\flask\app.py", line 1614, in full_dispatch_request
    rv = self.handle_user_exception(e)
  File "C:\Users\jackm\Desktop\tutor\flask\lib\site-packages\flask\app.py", line 1517, in handle_user_exception
    reraise(exc_type, exc_value, tb)
  File "C:\Users\jackm\Desktop\tutor\flask\lib\site-packages\flask\_compat.py", line 33, in reraise
    raise value
  File "C:\Users\jackm\Desktop\tutor\flask\lib\site-packages\flask\app.py", line 1612, in full_dispatch_request
    rv = self.dispatch_request()
  File "C:\Users\jackm\Desktop\tutor\flask\lib\site-packages\flask\app.py", line 1598, in dispatch_request
    return self.view_functions[rule.endpoint](**req.view_args)
  File "C:\Users\jackm\Desktop\tutor\flask\lib\site-packages\flask_login\utils.py", line 228, in decorated_view
    return func(*args, **kwargs)
  File "C:\Users\jackm\Desktop\tutor\app\views.py", line 85, in room
    room.approve_user(g.user)
  File "C:\Users\jackm\Desktop\tutor\app\models.py", line 59, in approve_user
    if not self.is_approved(user):
  File "C:\Users\jackm\Desktop\tutor\app\models.py", line 69, in is_approved
    return self.approved_users.filter(UserRoom.c.userId == user.id).count() > 0
  File "<string>", line 2, in filter
  File "C:\Users\jackm\Desktop\tutor\flask\lib\site-packages\sqlalchemy\orm\base.py", line 198, in generate
    self = args[0]._clone()
  File "C:\Users\jackm\Desktop\tutor\flask\lib\site-packages\sqlalchemy\orm\dynamic.py", line 278, in _clone
    orm_util.instance_str(instance), self.attr.key))
sqlalchemy.orm.exc.DetachedInstanceError: Parent instance <Room at 0x2c390b4a908> is not bound to a Session, and no contextual session is established; lazy load operation of attribute 'approved_users' cannot proceed
2017-07-21 19:50:37,579 INFO: tutor startup [in C:\Users\jackm\Desktop\tutor\app\__init__.py:25]
2017-07-21 19:50:49,400 INFO: tutor startup [in C:\Users\jackm\Desktop\tutor\app\__init__.py:25]
2017-07-21 19:51:11,059 ERROR: Exception on /room/jimmus [GET] [in C:\Users\jackm\Desktop\tutor\flask\lib\site-packages\flask\app.py:1560]
Traceback (most recent call last):
  File "C:\Users\jackm\Desktop\tutor\flask\lib\site-packages\flask\app.py", line 1982, in wsgi_app
    response = self.full_dispatch_request()
  File "C:\Users\jackm\Desktop\tutor\flask\lib\site-packages\flask\app.py", line 1614, in full_dispatch_request
    rv = self.handle_user_exception(e)
  File "C:\Users\jackm\Desktop\tutor\flask\lib\site-packages\flask\app.py", line 1517, in handle_user_exception
    reraise(exc_type, exc_value, tb)
  File "C:\Users\jackm\Desktop\tutor\flask\lib\site-packages\flask\_compat.py", line 33, in reraise
    raise value
  File "C:\Users\jackm\Desktop\tutor\flask\lib\site-packages\flask\app.py", line 1612, in full_dispatch_request
    rv = self.dispatch_request()
  File "C:\Users\jackm\Desktop\tutor\flask\lib\site-packages\flask\app.py", line 1598, in dispatch_request
    return self.view_functions[rule.endpoint](**req.view_args)
  File "C:\Users\jackm\Desktop\tutor\flask\lib\site-packages\flask_login\utils.py", line 228, in decorated_view
    return func(*args, **kwargs)
  File "C:\Users\jackm\Desktop\tutor\app\views.py", line 85, in room
    room.approve_user(g.user)
  File "C:\Users\jackm\Desktop\tutor\app\models.py", line 59, in approve_user
    if not self.is_approved(user):
  File "C:\Users\jackm\Desktop\tutor\app\models.py", line 69, in is_approved
    return self.approved_users.filter(UserRoom.c.userId == user.id).count() > 0
  File "<string>", line 2, in filter
  File "C:\Users\jackm\Desktop\tutor\flask\lib\site-packages\sqlalchemy\orm\base.py", line 198, in generate
    self = args[0]._clone()
  File "C:\Users\jackm\Desktop\tutor\flask\lib\site-packages\sqlalchemy\orm\dynamic.py", line 278, in _clone
    orm_util.instance_str(instance), self.attr.key))
sqlalchemy.orm.exc.DetachedInstanceError: Parent instance <Room at 0x2383f047eb8> is not bound to a Session, and no contextual session is established; lazy load operation of attribute 'approved_users' cannot proceed
2017-07-21 19:53:01,997 INFO: tutor startup [in C:\Users\jackm\Desktop\tutor\app\__init__.py:25]
2017-07-21 19:53:18,905 ERROR: Exception on /room/jimmus [GET] [in C:\Users\jackm\Desktop\tutor\flask\lib\site-packages\flask\app.py:1560]
Traceback (most recent call last):
  File "C:\Users\jackm\Desktop\tutor\flask\lib\site-packages\flask\app.py", line 1982, in wsgi_app
    response = self.full_dispatch_request()
  File "C:\Users\jackm\Desktop\tutor\flask\lib\site-packages\flask\app.py", line 1614, in full_dispatch_request
    rv = self.handle_user_exception(e)
  File "C:\Users\jackm\Desktop\tutor\flask\lib\site-packages\flask\app.py", line 1517, in handle_user_exception
    reraise(exc_type, exc_value, tb)
  File "C:\Users\jackm\Desktop\tutor\flask\lib\site-packages\flask\_compat.py", line 33, in reraise
    raise value
  File "C:\Users\jackm\Desktop\tutor\flask\lib\site-packages\flask\app.py", line 1612, in full_dispatch_request
    rv = self.dispatch_request()
  File "C:\Users\jackm\Desktop\tutor\flask\lib\site-packages\flask\app.py", line 1598, in dispatch_request
    return self.view_functions[rule.endpoint](**req.view_args)
  File "C:\Users\jackm\Desktop\tutor\flask\lib\site-packages\flask_login\utils.py", line 228, in decorated_view
    return func(*args, **kwargs)
  File "C:\Users\jackm\Desktop\tutor\app\views.py", line 85, in room
    room.approve_user(g.user)
  File "C:\Users\jackm\Desktop\tutor\app\models.py", line 59, in approve_user
    if not self.is_approved(user):
  File "C:\Users\jackm\Desktop\tutor\app\models.py", line 69, in is_approved
    return self.approved_users.filter(UserRoom.c.userId == user.id).count() > 0
  File "<string>", line 2, in filter
  File "C:\Users\jackm\Desktop\tutor\flask\lib\site-packages\sqlalchemy\orm\base.py", line 198, in generate
    self = args[0]._clone()
  File "C:\Users\jackm\Desktop\tutor\flask\lib\site-packages\sqlalchemy\orm\dynamic.py", line 278, in _clone
    orm_util.instance_str(instance), self.attr.key))
sqlalchemy.orm.exc.DetachedInstanceError: Parent instance <Room at 0x1be76c786d8> is not bound to a Session, and no contextual session is established; lazy load operation of attribute 'approved_users' cannot proceed
2017-07-21 19:54:55,059 ERROR: Exception on /room/asdfafgjiisjdiu1 [GET] [in C:\Users\jackm\Desktop\tutor\flask\lib\site-packages\flask\app.py:1560]
Traceback (most recent call last):
  File "C:\Users\jackm\Desktop\tutor\flask\lib\site-packages\flask\app.py", line 1982, in wsgi_app
    response = self.full_dispatch_request()
  File "C:\Users\jackm\Desktop\tutor\flask\lib\site-packages\flask\app.py", line 1614, in full_dispatch_request
    rv = self.handle_user_exception(e)
  File "C:\Users\jackm\Desktop\tutor\flask\lib\site-packages\flask\app.py", line 1517, in handle_user_exception
    reraise(exc_type, exc_value, tb)
  File "C:\Users\jackm\Desktop\tutor\flask\lib\site-packages\flask\_compat.py", line 33, in reraise
    raise value
  File "C:\Users\jackm\Desktop\tutor\flask\lib\site-packages\flask\app.py", line 1612, in full_dispatch_request
    rv = self.dispatch_request()
  File "C:\Users\jackm\Desktop\tutor\flask\lib\site-packages\flask\app.py", line 1598, in dispatch_request
    return self.view_functions[rule.endpoint](**req.view_args)
  File "C:\Users\jackm\Desktop\tutor\flask\lib\site-packages\flask_login\utils.py", line 228, in decorated_view
    return func(*args, **kwargs)
  File "C:\Users\jackm\Desktop\tutor\app\views.py", line 85, in room
    room.approve_user(g.user)
  File "C:\Users\jackm\Desktop\tutor\app\models.py", line 59, in approve_user
    if not self.is_approved(user):
  File "C:\Users\jackm\Desktop\tutor\app\models.py", line 69, in is_approved
    return self.approved_users.filter(UserRoom.c.userId == user.id).count() > 0
  File "<string>", line 2, in filter
  File "C:\Users\jackm\Desktop\tutor\flask\lib\site-packages\sqlalchemy\orm\base.py", line 198, in generate
    self = args[0]._clone()
  File "C:\Users\jackm\Desktop\tutor\flask\lib\site-packages\sqlalchemy\orm\dynamic.py", line 278, in _clone
    orm_util.instance_str(instance), self.attr.key))
sqlalchemy.orm.exc.DetachedInstanceError: Parent instance <Room at 0x1be76c44160> is not bound to a Session, and no contextual session is established; lazy load operation of attribute 'approved_users' cannot proceed
2017-07-21 19:56:17,681 INFO: tutor startup [in C:\Users\jackm\Desktop\tutor\app\__init__.py:25]
2017-07-21 19:56:35,755 ERROR: Exception on /room/jimmus [GET] [in C:\Users\jackm\Desktop\tutor\flask\lib\site-packages\flask\app.py:1560]
Traceback (most recent call last):
  File "C:\Users\jackm\Desktop\tutor\flask\lib\site-packages\flask\app.py", line 1982, in wsgi_app
    response = self.full_dispatch_request()
  File "C:\Users\jackm\Desktop\tutor\flask\lib\site-packages\flask\app.py", line 1614, in full_dispatch_request
    rv = self.handle_user_exception(e)
  File "C:\Users\jackm\Desktop\tutor\flask\lib\site-packages\flask\app.py", line 1517, in handle_user_exception
    reraise(exc_type, exc_value, tb)
  File "C:\Users\jackm\Desktop\tutor\flask\lib\site-packages\flask\_compat.py", line 33, in reraise
    raise value
  File "C:\Users\jackm\Desktop\tutor\flask\lib\site-packages\flask\app.py", line 1612, in full_dispatch_request
    rv = self.dispatch_request()
  File "C:\Users\jackm\Desktop\tutor\flask\lib\site-packages\flask\app.py", line 1598, in dispatch_request
    return self.view_functions[rule.endpoint](**req.view_args)
  File "C:\Users\jackm\Desktop\tutor\flask\lib\site-packages\flask_login\utils.py", line 228, in decorated_view
    return func(*args, **kwargs)
  File "C:\Users\jackm\Desktop\tutor\app\views.py", line 85, in room
    room.approve_user(g.user)
  File "C:\Users\jackm\Desktop\tutor\app\models.py", line 59, in approve_user
    if not self.is_approved(user):
  File "C:\Users\jackm\Desktop\tutor\app\models.py", line 69, in is_approved
    return self.approved_users.filter(UserRoom.c.userId == user.id).count() > 0
  File "<string>", line 2, in filter
  File "C:\Users\jackm\Desktop\tutor\flask\lib\site-packages\sqlalchemy\orm\base.py", line 198, in generate
    self = args[0]._clone()
  File "C:\Users\jackm\Desktop\tutor\flask\lib\site-packages\sqlalchemy\orm\dynamic.py", line 278, in _clone
    orm_util.instance_str(instance), self.attr.key))
sqlalchemy.orm.exc.DetachedInstanceError: Parent instance <Room at 0x265665f9860> is not bound to a Session, and no contextual session is established; lazy load operation of attribute 'approved_users' cannot proceed
2017-07-21 19:57:49,502 INFO: tutor startup [in C:\Users\jackm\Desktop\tutor\app\__init__.py:25]
2017-07-21 19:57:54,157 ERROR: Exception on / [GET] [in C:\Users\jackm\Desktop\tutor\flask\lib\site-packages\flask\app.py:1560]
Traceback (most recent call last):
  File "C:\Users\jackm\Desktop\tutor\flask\lib\site-packages\sqlalchemy\engine\base.py", line 1182, in _execute_context
    context)
  File "C:\Users\jackm\Desktop\tutor\flask\lib\site-packages\sqlalchemy\engine\default.py", line 470, in do_execute
    cursor.execute(statement, parameters)
sqlite3.OperationalError: no such table: users

The above exception was the direct cause of the following exception:

Traceback (most recent call last):
  File "C:\Users\jackm\Desktop\tutor\flask\lib\site-packages\flask\app.py", line 1982, in wsgi_app
    response = self.full_dispatch_request()
  File "C:\Users\jackm\Desktop\tutor\flask\lib\site-packages\flask\app.py", line 1614, in full_dispatch_request
    rv = self.handle_user_exception(e)
  File "C:\Users\jackm\Desktop\tutor\flask\lib\site-packages\flask\app.py", line 1517, in handle_user_exception
    reraise(exc_type, exc_value, tb)
  File "C:\Users\jackm\Desktop\tutor\flask\lib\site-packages\flask\_compat.py", line 33, in reraise
    raise value
  File "C:\Users\jackm\Desktop\tutor\flask\lib\site-packages\flask\app.py", line 1612, in full_dispatch_request
    rv = self.dispatch_request()
  File "C:\Users\jackm\Desktop\tutor\flask\lib\site-packages\flask\app.py", line 1598, in dispatch_request
    return self.view_functions[rule.endpoint](**req.view_args)
  File "C:\Users\jackm\Desktop\tutor\app\views.py", line 17, in home
    user=g.user)
  File "C:\Users\jackm\Desktop\tutor\flask\lib\site-packages\flask\templating.py", line 132, in render_template
    ctx.app.update_template_context(context)
  File "C:\Users\jackm\Desktop\tutor\flask\lib\site-packages\flask\app.py", line 764, in update_template_context
    context.update(func())
  File "C:\Users\jackm\Desktop\tutor\flask\lib\site-packages\flask_login\utils.py", line 335, in _user_context_processor
    return dict(current_user=_get_user())
  File "C:\Users\jackm\Desktop\tutor\flask\lib\site-packages\flask_login\utils.py", line 302, in _get_user
    current_app.login_manager._load_user()
  File "C:\Users\jackm\Desktop\tutor\flask\lib\site-packages\flask_login\login_manager.py", line 311, in _load_user
    return self._load_from_cookie(request.cookies[cookie_name])
  File "C:\Users\jackm\Desktop\tutor\flask\lib\site-packages\flask_login\login_manager.py", line 350, in _load_from_cookie
    self.reload_user()
  File "C:\Users\jackm\Desktop\tutor\flask\lib\site-packages\flask_login\login_manager.py", line 279, in reload_user
    user = self.user_callback(user_id)
  File "C:\Users\jackm\Desktop\tutor\app\__init__.py", line 15, in load_user
    return User.query.get(int(id))
  File "C:\Users\jackm\Desktop\tutor\flask\lib\site-packages\sqlalchemy\orm\query.py", line 864, in get
    return self._get_impl(ident, loading.load_on_ident)
  File "C:\Users\jackm\Desktop\tutor\flask\lib\site-packages\sqlalchemy\orm\query.py", line 897, in _get_impl
    return fallback_fn(self, key)
  File "C:\Users\jackm\Desktop\tutor\flask\lib\site-packages\sqlalchemy\orm\loading.py", line 223, in load_on_ident
    return q.one()
  File "C:\Users\jackm\Desktop\tutor\flask\lib\site-packages\sqlalchemy\orm\query.py", line 2814, in one
    ret = self.one_or_none()
  File "C:\Users\jackm\Desktop\tutor\flask\lib\site-packages\sqlalchemy\orm\query.py", line 2784, in one_or_none
    ret = list(self)
  File "C:\Users\jackm\Desktop\tutor\flask\lib\site-packages\sqlalchemy\orm\query.py", line 2855, in __iter__
    return self._execute_and_instances(context)
  File "C:\Users\jackm\Desktop\tutor\flask\lib\site-packages\sqlalchemy\orm\query.py", line 2878, in _execute_and_instances
    result = conn.execute(querycontext.statement, self._params)
  File "C:\Users\jackm\Desktop\tutor\flask\lib\site-packages\sqlalchemy\engine\base.py", line 945, in execute
    return meth(self, multiparams, params)
  File "C:\Users\jackm\Desktop\tutor\flask\lib\site-packages\sqlalchemy\sql\elements.py", line 263, in _execute_on_connection
    return connection._execute_clauseelement(self, multiparams, params)
  File "C:\Users\jackm\Desktop\tutor\flask\lib\site-packages\sqlalchemy\engine\base.py", line 1053, in _execute_clauseelement
    compiled_sql, distilled_params
  File "C:\Users\jackm\Desktop\tutor\flask\lib\site-packages\sqlalchemy\engine\base.py", line 1189, in _execute_context
    context)
  File "C:\Users\jackm\Desktop\tutor\flask\lib\site-packages\sqlalchemy\engine\base.py", line 1402, in _handle_dbapi_exception
    exc_info
  File "C:\Users\jackm\Desktop\tutor\flask\lib\site-packages\sqlalchemy\util\compat.py", line 203, in raise_from_cause
    reraise(type(exception), exception, tb=exc_tb, cause=cause)
  File "C:\Users\jackm\Desktop\tutor\flask\lib\site-packages\sqlalchemy\util\compat.py", line 186, in reraise
    raise value.with_traceback(tb)
  File "C:\Users\jackm\Desktop\tutor\flask\lib\site-packages\sqlalchemy\engine\base.py", line 1182, in _execute_context
    context)
  File "C:\Users\jackm\Desktop\tutor\flask\lib\site-packages\sqlalchemy\engine\default.py", line 470, in do_execute
    cursor.execute(statement, parameters)
sqlalchemy.exc.OperationalError: (sqlite3.OperationalError) no such table: users [SQL: 'SELECT users.id AS users_id, users.social_id AS users_social_id, users.nickname AS users_nickname, users.email AS users_email, users.about_me AS users_about_me, users.profile_picture_url AS users_profile_picture_url, users.last_room_password AS users_last_room_password, users.auth_provider AS users_auth_provider, users.total_time_online AS users_total_time_online \nFROM users \nWHERE users.id = ?'] [parameters: (1,)]
2017-07-21 19:57:55,338 ERROR: Exception on /favicon.ico [GET] [in C:\Users\jackm\Desktop\tutor\flask\lib\site-packages\flask\app.py:1560]
Traceback (most recent call last):
  File "C:\Users\jackm\Desktop\tutor\flask\lib\site-packages\flask\app.py", line 1612, in full_dispatch_request
    rv = self.dispatch_request()
  File "C:\Users\jackm\Desktop\tutor\flask\lib\site-packages\flask\app.py", line 1590, in dispatch_request
    self.raise_routing_exception(req)
  File "C:\Users\jackm\Desktop\tutor\flask\lib\site-packages\flask\app.py", line 1573, in raise_routing_exception
    raise request.routing_exception
  File "C:\Users\jackm\Desktop\tutor\flask\lib\site-packages\flask\ctx.py", line 294, in match_request
    self.url_adapter.match(return_rule=True)
  File "C:\Users\jackm\Desktop\tutor\flask\lib\site-packages\werkzeug\routing.py", line 1573, in match
    raise NotFound()
werkzeug.exceptions.NotFound: 404 Not Found: The requested URL was not found on the server.  If you entered the URL manually please check your spelling and try again.

During handling of the above exception, another exception occurred:

Traceback (most recent call last):
  File "C:\Users\jackm\Desktop\tutor\flask\lib\site-packages\sqlalchemy\engine\base.py", line 1182, in _execute_context
    context)
  File "C:\Users\jackm\Desktop\tutor\flask\lib\site-packages\sqlalchemy\engine\default.py", line 470, in do_execute
    cursor.execute(statement, parameters)
sqlite3.OperationalError: no such table: users

The above exception was the direct cause of the following exception:

Traceback (most recent call last):
  File "C:\Users\jackm\Desktop\tutor\flask\lib\site-packages\flask\app.py", line 1982, in wsgi_app
    response = self.full_dispatch_request()
  File "C:\Users\jackm\Desktop\tutor\flask\lib\site-packages\flask\app.py", line 1614, in full_dispatch_request
    rv = self.handle_user_exception(e)
  File "C:\Users\jackm\Desktop\tutor\flask\lib\site-packages\flask\app.py", line 1512, in handle_user_exception
    return self.handle_http_exception(e)
  File "C:\Users\jackm\Desktop\tutor\flask\lib\site-packages\flask\app.py", line 1471, in handle_http_exception
    return handler(e)
  File "C:\Users\jackm\Desktop\tutor\app\views.py", line 47, in not_found_error
    return render_template('404.html'), 404
  File "C:\Users\jackm\Desktop\tutor\flask\lib\site-packages\flask\templating.py", line 132, in render_template
    ctx.app.update_template_context(context)
  File "C:\Users\jackm\Desktop\tutor\flask\lib\site-packages\flask\app.py", line 764, in update_template_context
    context.update(func())
  File "C:\Users\jackm\Desktop\tutor\flask\lib\site-packages\flask_login\utils.py", line 335, in _user_context_processor
    return dict(current_user=_get_user())
  File "C:\Users\jackm\Desktop\tutor\flask\lib\site-packages\flask_login\utils.py", line 302, in _get_user
    current_app.login_manager._load_user()
  File "C:\Users\jackm\Desktop\tutor\flask\lib\site-packages\flask_login\login_manager.py", line 311, in _load_user
    return self._load_from_cookie(request.cookies[cookie_name])
  File "C:\Users\jackm\Desktop\tutor\flask\lib\site-packages\flask_login\login_manager.py", line 350, in _load_from_cookie
    self.reload_user()
  File "C:\Users\jackm\Desktop\tutor\flask\lib\site-packages\flask_login\login_manager.py", line 279, in reload_user
    user = self.user_callback(user_id)
  File "C:\Users\jackm\Desktop\tutor\app\__init__.py", line 15, in load_user
    return User.query.get(int(id))
  File "C:\Users\jackm\Desktop\tutor\flask\lib\site-packages\sqlalchemy\orm\query.py", line 864, in get
    return self._get_impl(ident, loading.load_on_ident)
  File "C:\Users\jackm\Desktop\tutor\flask\lib\site-packages\sqlalchemy\orm\query.py", line 897, in _get_impl
    return fallback_fn(self, key)
  File "C:\Users\jackm\Desktop\tutor\flask\lib\site-packages\sqlalchemy\orm\loading.py", line 223, in load_on_ident
    return q.one()
  File "C:\Users\jackm\Desktop\tutor\flask\lib\site-packages\sqlalchemy\orm\query.py", line 2814, in one
    ret = self.one_or_none()
  File "C:\Users\jackm\Desktop\tutor\flask\lib\site-packages\sqlalchemy\orm\query.py", line 2784, in one_or_none
    ret = list(self)
  File "C:\Users\jackm\Desktop\tutor\flask\lib\site-packages\sqlalchemy\orm\query.py", line 2855, in __iter__
    return self._execute_and_instances(context)
  File "C:\Users\jackm\Desktop\tutor\flask\lib\site-packages\sqlalchemy\orm\query.py", line 2878, in _execute_and_instances
    result = conn.execute(querycontext.statement, self._params)
  File "C:\Users\jackm\Desktop\tutor\flask\lib\site-packages\sqlalchemy\engine\base.py", line 945, in execute
    return meth(self, multiparams, params)
  File "C:\Users\jackm\Desktop\tutor\flask\lib\site-packages\sqlalchemy\sql\elements.py", line 263, in _execute_on_connection
    return connection._execute_clauseelement(self, multiparams, params)
  File "C:\Users\jackm\Desktop\tutor\flask\lib\site-packages\sqlalchemy\engine\base.py", line 1053, in _execute_clauseelement
    compiled_sql, distilled_params
  File "C:\Users\jackm\Desktop\tutor\flask\lib\site-packages\sqlalchemy\engine\base.py", line 1189, in _execute_context
    context)
  File "C:\Users\jackm\Desktop\tutor\flask\lib\site-packages\sqlalchemy\engine\base.py", line 1402, in _handle_dbapi_exception
    exc_info
  File "C:\Users\jackm\Desktop\tutor\flask\lib\site-packages\sqlalchemy\util\compat.py", line 203, in raise_from_cause
    reraise(type(exception), exception, tb=exc_tb, cause=cause)
  File "C:\Users\jackm\Desktop\tutor\flask\lib\site-packages\sqlalchemy\util\compat.py", line 186, in reraise
    raise value.with_traceback(tb)
  File "C:\Users\jackm\Desktop\tutor\flask\lib\site-packages\sqlalchemy\engine\base.py", line 1182, in _execute_context
    context)
  File "C:\Users\jackm\Desktop\tutor\flask\lib\site-packages\sqlalchemy\engine\default.py", line 470, in do_execute
    cursor.execute(statement, parameters)
sqlalchemy.exc.OperationalError: (sqlite3.OperationalError) no such table: users [SQL: 'SELECT users.id AS users_id, users.social_id AS users_social_id, users.nickname AS users_nickname, users.email AS users_email, users.about_me AS users_about_me, users.profile_picture_url AS users_profile_picture_url, users.last_room_password AS users_last_room_password, users.auth_provider AS users_auth_provider, users.total_time_online AS users_total_time_online \nFROM users \nWHERE users.id = ?'] [parameters: (1,)]
2017-07-21 19:58:08,153 INFO: tutor startup [in C:\Users\jackm\Desktop\tutor\app\__init__.py:25]
2017-07-21 19:58:11,962 INFO: tutor startup [in C:\Users\jackm\Desktop\tutor\app\__init__.py:25]
2017-07-21 19:58:19,359 INFO: tutor startup [in C:\Users\jackm\Desktop\tutor\app\__init__.py:25]
2017-07-21 19:58:43,940 ERROR: Exception on /room/jimmus [GET] [in C:\Users\jackm\Desktop\tutor\flask\lib\site-packages\flask\app.py:1560]
Traceback (most recent call last):
  File "C:\Users\jackm\Desktop\tutor\flask\lib\site-packages\flask\app.py", line 1982, in wsgi_app
    response = self.full_dispatch_request()
  File "C:\Users\jackm\Desktop\tutor\flask\lib\site-packages\flask\app.py", line 1614, in full_dispatch_request
    rv = self.handle_user_exception(e)
  File "C:\Users\jackm\Desktop\tutor\flask\lib\site-packages\flask\app.py", line 1517, in handle_user_exception
    reraise(exc_type, exc_value, tb)
  File "C:\Users\jackm\Desktop\tutor\flask\lib\site-packages\flask\_compat.py", line 33, in reraise
    raise value
  File "C:\Users\jackm\Desktop\tutor\flask\lib\site-packages\flask\app.py", line 1612, in full_dispatch_request
    rv = self.dispatch_request()
  File "C:\Users\jackm\Desktop\tutor\flask\lib\site-packages\flask\app.py", line 1598, in dispatch_request
    return self.view_functions[rule.endpoint](**req.view_args)
  File "C:\Users\jackm\Desktop\tutor\flask\lib\site-packages\flask_login\utils.py", line 228, in decorated_view
    return func(*args, **kwargs)
  File "C:\Users\jackm\Desktop\tutor\app\views.py", line 85, in room
    room.approve_user(g.user)
  File "C:\Users\jackm\Desktop\tutor\app\models.py", line 59, in approve_user
    if not self.is_approved(user):
  File "C:\Users\jackm\Desktop\tutor\app\models.py", line 69, in is_approved
    return self.approved_users.filter(UserRoom.c.userId == user.id).count() > 0
  File "<string>", line 2, in filter
  File "C:\Users\jackm\Desktop\tutor\flask\lib\site-packages\sqlalchemy\orm\base.py", line 198, in generate
    self = args[0]._clone()
  File "C:\Users\jackm\Desktop\tutor\flask\lib\site-packages\sqlalchemy\orm\dynamic.py", line 278, in _clone
    orm_util.instance_str(instance), self.attr.key))
sqlalchemy.orm.exc.DetachedInstanceError: Parent instance <Room at 0x1a9230979e8> is not bound to a Session, and no contextual session is established; lazy load operation of attribute 'approved_users' cannot proceed
2017-07-21 21:23:41,456 INFO: tutor startup [in C:\Users\jackm\Desktop\tutor\app\__init__.py:25]
2017-07-21 21:25:16,943 INFO: tutor startup [in C:\Users\jackm\Desktop\tutor\app\__init__.py:25]
2017-07-21 21:26:09,765 INFO: tutor startup [in C:\Users\jackm\Desktop\tutor\app\__init__.py:25]
2017-07-21 21:30:09,168 INFO: tutor startup [in C:\Users\jackm\Desktop\tutor\app\__init__.py:25]
2017-07-21 21:30:52,571 INFO: tutor startup [in C:\Users\jackm\Desktop\tutor\app\__init__.py:25]
2017-07-21 21:31:43,641 INFO: tutor startup [in C:\Users\jackm\Desktop\tutor\app\__init__.py:25]
2017-07-21 21:34:00,260 INFO: tutor startup [in C:\Users\jackm\Desktop\tutor\app\__init__.py:25]
2017-07-21 21:35:25,823 INFO: tutor startup [in C:\Users\jackm\Desktop\tutor\app\__init__.py:25]
2017-07-22 16:58:08,404 INFO: tutor startup [in C:\Users\jackm\Desktop\tutor\app\__init__.py:25]
2017-07-22 17:00:23,977 INFO: tutor startup [in C:\Users\jackm\Desktop\tutor\app\__init__.py:25]
2017-07-22 17:03:43,551 INFO: tutor startup [in C:\Users\jackm\Desktop\tutor\app\__init__.py:25]
2017-07-22 17:03:48,416 INFO: tutor startup [in C:\Users\jackm\Desktop\tutor\app\__init__.py:25]
2017-07-22 17:04:27,411 ERROR: Exception on /room/jimmus [GET] [in C:\Users\jackm\Desktop\tutor\flask\lib\site-packages\flask\app.py:1560]
Traceback (most recent call last):
  File "C:\Users\jackm\Desktop\tutor\flask\lib\site-packages\flask\app.py", line 1982, in wsgi_app
    response = self.full_dispatch_request()
  File "C:\Users\jackm\Desktop\tutor\flask\lib\site-packages\flask\app.py", line 1614, in full_dispatch_request
    rv = self.handle_user_exception(e)
  File "C:\Users\jackm\Desktop\tutor\flask\lib\site-packages\flask\app.py", line 1517, in handle_user_exception
    reraise(exc_type, exc_value, tb)
  File "C:\Users\jackm\Desktop\tutor\flask\lib\site-packages\flask\_compat.py", line 33, in reraise
    raise value
  File "C:\Users\jackm\Desktop\tutor\flask\lib\site-packages\flask\app.py", line 1612, in full_dispatch_request
    rv = self.dispatch_request()
  File "C:\Users\jackm\Desktop\tutor\flask\lib\site-packages\flask\app.py", line 1598, in dispatch_request
    return self.view_functions[rule.endpoint](**req.view_args)
  File "C:\Users\jackm\Desktop\tutor\flask\lib\site-packages\flask_login\utils.py", line 228, in decorated_view
    return func(*args, **kwargs)
  File "C:\Users\jackm\Desktop\tutor\app\views.py", line 87, in room
    room.approve_user(g.user)
  File "C:\Users\jackm\Desktop\tutor\app\models.py", line 59, in approve_user
    if not self.is_approved(user):
  File "C:\Users\jackm\Desktop\tutor\app\models.py", line 69, in is_approved
    return self.approved_users.filter(UserRoom.c.userId == user.id).count() > 0
  File "<string>", line 2, in filter
  File "C:\Users\jackm\Desktop\tutor\flask\lib\site-packages\sqlalchemy\orm\base.py", line 198, in generate
    self = args[0]._clone()
  File "C:\Users\jackm\Desktop\tutor\flask\lib\site-packages\sqlalchemy\orm\dynamic.py", line 278, in _clone
    orm_util.instance_str(instance), self.attr.key))
sqlalchemy.orm.exc.DetachedInstanceError: Parent instance <Room at 0x2848eafcb38> is not bound to a Session, and no contextual session is established; lazy load operation of attribute 'approved_users' cannot proceed
2017-07-22 17:04:38,566 ERROR: Exception on /room/jimmus [GET] [in C:\Users\jackm\Desktop\tutor\flask\lib\site-packages\flask\app.py:1560]
Traceback (most recent call last):
  File "C:\Users\jackm\Desktop\tutor\flask\lib\site-packages\flask\app.py", line 1982, in wsgi_app
    response = self.full_dispatch_request()
  File "C:\Users\jackm\Desktop\tutor\flask\lib\site-packages\flask\app.py", line 1614, in full_dispatch_request
    rv = self.handle_user_exception(e)
  File "C:\Users\jackm\Desktop\tutor\flask\lib\site-packages\flask\app.py", line 1517, in handle_user_exception
    reraise(exc_type, exc_value, tb)
  File "C:\Users\jackm\Desktop\tutor\flask\lib\site-packages\flask\_compat.py", line 33, in reraise
    raise value
  File "C:\Users\jackm\Desktop\tutor\flask\lib\site-packages\flask\app.py", line 1612, in full_dispatch_request
    rv = self.dispatch_request()
  File "C:\Users\jackm\Desktop\tutor\flask\lib\site-packages\flask\app.py", line 1598, in dispatch_request
    return self.view_functions[rule.endpoint](**req.view_args)
  File "C:\Users\jackm\Desktop\tutor\flask\lib\site-packages\flask_login\utils.py", line 228, in decorated_view
    return func(*args, **kwargs)
  File "C:\Users\jackm\Desktop\tutor\app\views.py", line 87, in room
    room.approve_user(g.user)
  File "C:\Users\jackm\Desktop\tutor\app\models.py", line 59, in approve_user
    if not self.is_approved(user):
  File "C:\Users\jackm\Desktop\tutor\app\models.py", line 69, in is_approved
    return self.approved_users.filter(UserRoom.c.userId == user.id).count() > 0
  File "<string>", line 2, in filter
  File "C:\Users\jackm\Desktop\tutor\flask\lib\site-packages\sqlalchemy\orm\base.py", line 198, in generate
    self = args[0]._clone()
  File "C:\Users\jackm\Desktop\tutor\flask\lib\site-packages\sqlalchemy\orm\dynamic.py", line 278, in _clone
    orm_util.instance_str(instance), self.attr.key))
sqlalchemy.orm.exc.DetachedInstanceError: Parent instance <Room at 0x2848ec7a668> is not bound to a Session, and no contextual session is established; lazy load operation of attribute 'approved_users' cannot proceed
2017-07-22 17:05:35,554 ERROR: Exception on /room/gimmus [GET] [in C:\Users\jackm\Desktop\tutor\flask\lib\site-packages\flask\app.py:1560]
Traceback (most recent call last):
  File "C:\Users\jackm\Desktop\tutor\flask\lib\site-packages\flask\app.py", line 1982, in wsgi_app
    response = self.full_dispatch_request()
  File "C:\Users\jackm\Desktop\tutor\flask\lib\site-packages\flask\app.py", line 1614, in full_dispatch_request
    rv = self.handle_user_exception(e)
  File "C:\Users\jackm\Desktop\tutor\flask\lib\site-packages\flask\app.py", line 1517, in handle_user_exception
    reraise(exc_type, exc_value, tb)
  File "C:\Users\jackm\Desktop\tutor\flask\lib\site-packages\flask\_compat.py", line 33, in reraise
    raise value
  File "C:\Users\jackm\Desktop\tutor\flask\lib\site-packages\flask\app.py", line 1612, in full_dispatch_request
    rv = self.dispatch_request()
  File "C:\Users\jackm\Desktop\tutor\flask\lib\site-packages\flask\app.py", line 1598, in dispatch_request
    return self.view_functions[rule.endpoint](**req.view_args)
  File "C:\Users\jackm\Desktop\tutor\flask\lib\site-packages\flask_login\utils.py", line 228, in decorated_view
    return func(*args, **kwargs)
  File "C:\Users\jackm\Desktop\tutor\app\views.py", line 87, in room
    room.approve_user(g.user)
  File "C:\Users\jackm\Desktop\tutor\app\models.py", line 59, in approve_user
    if not self.is_approved(user):
  File "C:\Users\jackm\Desktop\tutor\app\models.py", line 69, in is_approved
    return self.approved_users.filter(UserRoom.c.userId == user.id).count() > 0
  File "<string>", line 2, in filter
  File "C:\Users\jackm\Desktop\tutor\flask\lib\site-packages\sqlalchemy\orm\base.py", line 198, in generate
    self = args[0]._clone()
  File "C:\Users\jackm\Desktop\tutor\flask\lib\site-packages\sqlalchemy\orm\dynamic.py", line 278, in _clone
    orm_util.instance_str(instance), self.attr.key))
sqlalchemy.orm.exc.DetachedInstanceError: Parent instance <Room at 0x2848ecb4940> is not bound to a Session, and no contextual session is established; lazy load operation of attribute 'approved_users' cannot proceed
2017-07-22 17:08:58,675 INFO: tutor startup [in C:\Users\jackm\Desktop\tutor\app\__init__.py:25]
2017-07-22 17:09:14,862 ERROR: Exception on /room/jimmus [GET] [in C:\Users\jackm\Desktop\tutor\flask\lib\site-packages\flask\app.py:1560]
Traceback (most recent call last):
  File "C:\Users\jackm\Desktop\tutor\flask\lib\site-packages\sqlalchemy\orm\session.py", line 1707, in add
    state = attributes.instance_state(instance)
AttributeError: 'NoneType' object has no attribute '_sa_instance_state'

During handling of the above exception, another exception occurred:

Traceback (most recent call last):
  File "C:\Users\jackm\Desktop\tutor\flask\lib\site-packages\flask\app.py", line 1982, in wsgi_app
    response = self.full_dispatch_request()
  File "C:\Users\jackm\Desktop\tutor\flask\lib\site-packages\flask\app.py", line 1614, in full_dispatch_request
    rv = self.handle_user_exception(e)
  File "C:\Users\jackm\Desktop\tutor\flask\lib\site-packages\flask\app.py", line 1517, in handle_user_exception
    reraise(exc_type, exc_value, tb)
  File "C:\Users\jackm\Desktop\tutor\flask\lib\site-packages\flask\_compat.py", line 33, in reraise
    raise value
  File "C:\Users\jackm\Desktop\tutor\flask\lib\site-packages\flask\app.py", line 1612, in full_dispatch_request
    rv = self.dispatch_request()
  File "C:\Users\jackm\Desktop\tutor\flask\lib\site-packages\flask\app.py", line 1598, in dispatch_request
    return self.view_functions[rule.endpoint](**req.view_args)
  File "C:\Users\jackm\Desktop\tutor\flask\lib\site-packages\flask_login\utils.py", line 228, in decorated_view
    return func(*args, **kwargs)
  File "C:\Users\jackm\Desktop\tutor\app\views.py", line 84, in room
    db.session.add(room)
  File "C:\Users\jackm\Desktop\tutor\flask\lib\site-packages\sqlalchemy\orm\scoping.py", line 157, in do
    return getattr(self.registry(), name)(*args, **kwargs)
  File "C:\Users\jackm\Desktop\tutor\flask\lib\site-packages\sqlalchemy\orm\session.py", line 1709, in add
    raise exc.UnmappedInstanceError(instance)
sqlalchemy.orm.exc.UnmappedInstanceError: Class 'builtins.NoneType' is not mapped
2017-07-22 17:10:10,917 INFO: tutor startup [in C:\Users\jackm\Desktop\tutor\app\__init__.py:25]
2017-07-22 17:36:03,373 INFO: tutor startup [in C:\Users\jackm\Desktop\tutor\app\__init__.py:25]
2017-07-22 17:42:35,162 INFO: tutor startup [in C:\Users\jackm\Desktop\tutor\app\__init__.py:25]
2017-07-22 17:44:26,538 INFO: tutor startup [in C:\Users\jackm\Desktop\tutor\app\__init__.py:25]
2017-07-22 17:47:59,556 INFO: tutor startup [in C:\Users\jackm\Desktop\tutor\app\__init__.py:25]
2017-07-22 17:50:38,242 INFO: tutor startup [in C:\Users\jackm\Desktop\tutor\app\__init__.py:25]
2017-07-22 19:02:27,023 INFO: tutor startup [in C:\Users\jackm\Desktop\tutor\app\__init__.py:25]
2017-07-23 11:36:18,779 INFO: tutor startup [in C:\Users\jackm\Desktop\tutor\app\__init__.py:25]
2017-07-23 11:37:02,456 INFO: tutor startup [in C:\Users\jackm\Desktop\tutor\app\__init__.py:25]
2017-07-23 12:30:03,162 INFO: tutor startup [in C:\Users\jackm\Desktop\tutor\app\__init__.py:25]
2017-07-23 12:32:09,046 INFO: tutor startup [in C:\Users\jackm\Desktop\tutor\app\__init__.py:25]
2017-07-23 12:32:52,089 INFO: tutor startup [in C:\Users\jackm\Desktop\tutor\app\__init__.py:25]
2017-07-23 12:34:05,188 INFO: tutor startup [in C:\Users\jackm\Desktop\tutor\app\__init__.py:25]
2017-07-23 12:34:14,468 INFO: tutor startup [in C:\Users\jackm\Desktop\tutor\app\__init__.py:25]
2017-07-23 12:35:16,661 INFO: tutor startup [in C:\Users\jackm\Desktop\tutor\app\__init__.py:25]
2017-07-23 12:35:21,402 INFO: tutor startup [in C:\Users\jackm\Desktop\tutor\app\__init__.py:25]
2017-07-23 12:35:26,223 ERROR: Exception on / [GET] [in C:\Users\jackm\Desktop\tutor\flask\lib\site-packages\flask\app.py:1560]
Traceback (most recent call last):
  File "C:\Users\jackm\Desktop\tutor\flask\lib\site-packages\flask\app.py", line 1982, in wsgi_app
    response = self.full_dispatch_request()
  File "C:\Users\jackm\Desktop\tutor\flask\lib\site-packages\flask\app.py", line 1614, in full_dispatch_request
    rv = self.handle_user_exception(e)
  File "C:\Users\jackm\Desktop\tutor\flask\lib\site-packages\flask\app.py", line 1517, in handle_user_exception
    reraise(exc_type, exc_value, tb)
  File "C:\Users\jackm\Desktop\tutor\flask\lib\site-packages\flask\_compat.py", line 33, in reraise
    raise value
  File "C:\Users\jackm\Desktop\tutor\flask\lib\site-packages\flask\app.py", line 1610, in full_dispatch_request
    rv = self.preprocess_request()
  File "C:\Users\jackm\Desktop\tutor\flask\lib\site-packages\flask\app.py", line 1831, in preprocess_request
    rv = func()
  File "C:\Users\jackm\Desktop\tutor\app\views.py", line 12, in before_request
    if request.endpoint != 'room':
NameError: name 'request' is not defined
2017-07-23 12:35:27,459 ERROR: Exception on /favicon.ico [GET] [in C:\Users\jackm\Desktop\tutor\flask\lib\site-packages\flask\app.py:1560]
Traceback (most recent call last):
  File "C:\Users\jackm\Desktop\tutor\flask\lib\site-packages\flask\app.py", line 1982, in wsgi_app
    response = self.full_dispatch_request()
  File "C:\Users\jackm\Desktop\tutor\flask\lib\site-packages\flask\app.py", line 1614, in full_dispatch_request
    rv = self.handle_user_exception(e)
  File "C:\Users\jackm\Desktop\tutor\flask\lib\site-packages\flask\app.py", line 1517, in handle_user_exception
    reraise(exc_type, exc_value, tb)
  File "C:\Users\jackm\Desktop\tutor\flask\lib\site-packages\flask\_compat.py", line 33, in reraise
    raise value
  File "C:\Users\jackm\Desktop\tutor\flask\lib\site-packages\flask\app.py", line 1610, in full_dispatch_request
    rv = self.preprocess_request()
  File "C:\Users\jackm\Desktop\tutor\flask\lib\site-packages\flask\app.py", line 1831, in preprocess_request
    rv = func()
  File "C:\Users\jackm\Desktop\tutor\app\views.py", line 12, in before_request
    if request.endpoint != 'room':
NameError: name 'request' is not defined
2017-07-23 12:35:46,870 INFO: tutor startup [in C:\Users\jackm\Desktop\tutor\app\__init__.py:25]
2017-07-23 12:35:50,479 ERROR: Exception on / [GET] [in C:\Users\jackm\Desktop\tutor\flask\lib\site-packages\flask\app.py:1560]
Traceback (most recent call last):
  File "C:\Users\jackm\Desktop\tutor\flask\lib\site-packages\flask\app.py", line 1982, in wsgi_app
    response = self.full_dispatch_request()
  File "C:\Users\jackm\Desktop\tutor\flask\lib\site-packages\flask\app.py", line 1614, in full_dispatch_request
    rv = self.handle_user_exception(e)
  File "C:\Users\jackm\Desktop\tutor\flask\lib\site-packages\flask\app.py", line 1517, in handle_user_exception
    reraise(exc_type, exc_value, tb)
  File "C:\Users\jackm\Desktop\tutor\flask\lib\site-packages\flask\_compat.py", line 33, in reraise
    raise value
  File "C:\Users\jackm\Desktop\tutor\flask\lib\site-packages\flask\app.py", line 1610, in full_dispatch_request
    rv = self.preprocess_request()
  File "C:\Users\jackm\Desktop\tutor\flask\lib\site-packages\flask\app.py", line 1831, in preprocess_request
    rv = func()
  File "C:\Users\jackm\Desktop\tutor\app\views.py", line 16, in before_request
    rooms = Room.query.filter_by(Room.is_approved(g.user)==True).all()
TypeError: is_approved() missing 1 required positional argument: 'user'
2017-07-23 12:35:51,433 ERROR: Exception on /favicon.ico [GET] [in C:\Users\jackm\Desktop\tutor\flask\lib\site-packages\flask\app.py:1560]
Traceback (most recent call last):
  File "C:\Users\jackm\Desktop\tutor\flask\lib\site-packages\flask\app.py", line 1982, in wsgi_app
    response = self.full_dispatch_request()
  File "C:\Users\jackm\Desktop\tutor\flask\lib\site-packages\flask\app.py", line 1614, in full_dispatch_request
    rv = self.handle_user_exception(e)
  File "C:\Users\jackm\Desktop\tutor\flask\lib\site-packages\flask\app.py", line 1517, in handle_user_exception
    reraise(exc_type, exc_value, tb)
  File "C:\Users\jackm\Desktop\tutor\flask\lib\site-packages\flask\_compat.py", line 33, in reraise
    raise value
  File "C:\Users\jackm\Desktop\tutor\flask\lib\site-packages\flask\app.py", line 1610, in full_dispatch_request
    rv = self.preprocess_request()
  File "C:\Users\jackm\Desktop\tutor\flask\lib\site-packages\flask\app.py", line 1831, in preprocess_request
    rv = func()
  File "C:\Users\jackm\Desktop\tutor\app\views.py", line 16, in before_request
    rooms = Room.query.filter_by(Room.is_approved(g.user)==True).all()
TypeError: is_approved() missing 1 required positional argument: 'user'
2017-07-23 12:37:50,411 INFO: tutor startup [in C:\Users\jackm\Desktop\tutor\app\__init__.py:25]
2017-07-23 12:37:52,938 ERROR: Exception on / [GET] [in C:\Users\jackm\Desktop\tutor\flask\lib\site-packages\flask\app.py:1560]
Traceback (most recent call last):
  File "C:\Users\jackm\Desktop\tutor\flask\lib\site-packages\flask\app.py", line 1982, in wsgi_app
    response = self.full_dispatch_request()
  File "C:\Users\jackm\Desktop\tutor\flask\lib\site-packages\flask\app.py", line 1614, in full_dispatch_request
    rv = self.handle_user_exception(e)
  File "C:\Users\jackm\Desktop\tutor\flask\lib\site-packages\flask\app.py", line 1517, in handle_user_exception
    reraise(exc_type, exc_value, tb)
  File "C:\Users\jackm\Desktop\tutor\flask\lib\site-packages\flask\_compat.py", line 33, in reraise
    raise value
  File "C:\Users\jackm\Desktop\tutor\flask\lib\site-packages\flask\app.py", line 1610, in full_dispatch_request
    rv = self.preprocess_request()
  File "C:\Users\jackm\Desktop\tutor\flask\lib\site-packages\flask\app.py", line 1831, in preprocess_request
    rv = func()
  File "C:\Users\jackm\Desktop\tutor\app\views.py", line 16, in before_request
    rooms = Room.query.filter_by(approved_users.filter(UserRoom.c.userId==g.user.id)).all()
NameError: name 'approved_users' is not defined
2017-07-23 12:37:53,937 ERROR: Exception on /favicon.ico [GET] [in C:\Users\jackm\Desktop\tutor\flask\lib\site-packages\flask\app.py:1560]
Traceback (most recent call last):
  File "C:\Users\jackm\Desktop\tutor\flask\lib\site-packages\flask\app.py", line 1982, in wsgi_app
    response = self.full_dispatch_request()
  File "C:\Users\jackm\Desktop\tutor\flask\lib\site-packages\flask\app.py", line 1614, in full_dispatch_request
    rv = self.handle_user_exception(e)
  File "C:\Users\jackm\Desktop\tutor\flask\lib\site-packages\flask\app.py", line 1517, in handle_user_exception
    reraise(exc_type, exc_value, tb)
  File "C:\Users\jackm\Desktop\tutor\flask\lib\site-packages\flask\_compat.py", line 33, in reraise
    raise value
  File "C:\Users\jackm\Desktop\tutor\flask\lib\site-packages\flask\app.py", line 1610, in full_dispatch_request
    rv = self.preprocess_request()
  File "C:\Users\jackm\Desktop\tutor\flask\lib\site-packages\flask\app.py", line 1831, in preprocess_request
    rv = func()
  File "C:\Users\jackm\Desktop\tutor\app\views.py", line 16, in before_request
    rooms = Room.query.filter_by(approved_users.filter(UserRoom.c.userId==g.user.id)).all()
NameError: name 'approved_users' is not defined
2017-07-23 12:37:57,310 ERROR: Exception on / [GET] [in C:\Users\jackm\Desktop\tutor\flask\lib\site-packages\flask\app.py:1560]
Traceback (most recent call last):
  File "C:\Users\jackm\Desktop\tutor\flask\lib\site-packages\flask\app.py", line 1982, in wsgi_app
    response = self.full_dispatch_request()
  File "C:\Users\jackm\Desktop\tutor\flask\lib\site-packages\flask\app.py", line 1614, in full_dispatch_request
    rv = self.handle_user_exception(e)
  File "C:\Users\jackm\Desktop\tutor\flask\lib\site-packages\flask\app.py", line 1517, in handle_user_exception
    reraise(exc_type, exc_value, tb)
  File "C:\Users\jackm\Desktop\tutor\flask\lib\site-packages\flask\_compat.py", line 33, in reraise
    raise value
  File "C:\Users\jackm\Desktop\tutor\flask\lib\site-packages\flask\app.py", line 1610, in full_dispatch_request
    rv = self.preprocess_request()
  File "C:\Users\jackm\Desktop\tutor\flask\lib\site-packages\flask\app.py", line 1831, in preprocess_request
    rv = func()
  File "C:\Users\jackm\Desktop\tutor\app\views.py", line 16, in before_request
    rooms = Room.query.filter_by(approved_users.filter(UserRoom.c.userId==g.user.id)).all()
NameError: name 'approved_users' is not defined
2017-07-23 12:37:57,560 ERROR: Exception on /favicon.ico [GET] [in C:\Users\jackm\Desktop\tutor\flask\lib\site-packages\flask\app.py:1560]
Traceback (most recent call last):
  File "C:\Users\jackm\Desktop\tutor\flask\lib\site-packages\flask\app.py", line 1982, in wsgi_app
    response = self.full_dispatch_request()
  File "C:\Users\jackm\Desktop\tutor\flask\lib\site-packages\flask\app.py", line 1614, in full_dispatch_request
    rv = self.handle_user_exception(e)
  File "C:\Users\jackm\Desktop\tutor\flask\lib\site-packages\flask\app.py", line 1517, in handle_user_exception
    reraise(exc_type, exc_value, tb)
  File "C:\Users\jackm\Desktop\tutor\flask\lib\site-packages\flask\_compat.py", line 33, in reraise
    raise value
  File "C:\Users\jackm\Desktop\tutor\flask\lib\site-packages\flask\app.py", line 1610, in full_dispatch_request
    rv = self.preprocess_request()
  File "C:\Users\jackm\Desktop\tutor\flask\lib\site-packages\flask\app.py", line 1831, in preprocess_request
    rv = func()
  File "C:\Users\jackm\Desktop\tutor\app\views.py", line 16, in before_request
    rooms = Room.query.filter_by(approved_users.filter(UserRoom.c.userId==g.user.id)).all()
NameError: name 'approved_users' is not defined
2017-07-23 12:38:18,620 INFO: tutor startup [in C:\Users\jackm\Desktop\tutor\app\__init__.py:25]
2017-07-23 12:38:21,205 ERROR: Exception on / [GET] [in C:\Users\jackm\Desktop\tutor\flask\lib\site-packages\flask\app.py:1560]
Traceback (most recent call last):
  File "C:\Users\jackm\Desktop\tutor\flask\lib\site-packages\sqlalchemy\orm\attributes.py", line 185, in __getattr__
    return getattr(self.comparator, key)
AttributeError: 'Comparator' object has no attribute 'filter'

During handling of the above exception, another exception occurred:

Traceback (most recent call last):
  File "C:\Users\jackm\Desktop\tutor\flask\lib\site-packages\flask\app.py", line 1982, in wsgi_app
    response = self.full_dispatch_request()
  File "C:\Users\jackm\Desktop\tutor\flask\lib\site-packages\flask\app.py", line 1614, in full_dispatch_request
    rv = self.handle_user_exception(e)
  File "C:\Users\jackm\Desktop\tutor\flask\lib\site-packages\flask\app.py", line 1517, in handle_user_exception
    reraise(exc_type, exc_value, tb)
  File "C:\Users\jackm\Desktop\tutor\flask\lib\site-packages\flask\_compat.py", line 33, in reraise
    raise value
  File "C:\Users\jackm\Desktop\tutor\flask\lib\site-packages\flask\app.py", line 1610, in full_dispatch_request
    rv = self.preprocess_request()
  File "C:\Users\jackm\Desktop\tutor\flask\lib\site-packages\flask\app.py", line 1831, in preprocess_request
    rv = func()
  File "C:\Users\jackm\Desktop\tutor\app\views.py", line 16, in before_request
    rooms = Room.query.filter_by(Room.approved_users.filter(UserRoom.c.userId==g.user.id)).all()
  File "C:\Users\jackm\Desktop\tutor\flask\lib\site-packages\sqlalchemy\orm\attributes.py", line 193, in __getattr__
    key)
AttributeError: Neither 'InstrumentedAttribute' object nor 'Comparator' object associated with Room.approved_users has an attribute 'filter'
2017-07-23 12:38:22,228 ERROR: Exception on /favicon.ico [GET] [in C:\Users\jackm\Desktop\tutor\flask\lib\site-packages\flask\app.py:1560]
Traceback (most recent call last):
  File "C:\Users\jackm\Desktop\tutor\flask\lib\site-packages\sqlalchemy\orm\attributes.py", line 185, in __getattr__
    return getattr(self.comparator, key)
AttributeError: 'Comparator' object has no attribute 'filter'

During handling of the above exception, another exception occurred:

Traceback (most recent call last):
  File "C:\Users\jackm\Desktop\tutor\flask\lib\site-packages\flask\app.py", line 1982, in wsgi_app
    response = self.full_dispatch_request()
  File "C:\Users\jackm\Desktop\tutor\flask\lib\site-packages\flask\app.py", line 1614, in full_dispatch_request
    rv = self.handle_user_exception(e)
  File "C:\Users\jackm\Desktop\tutor\flask\lib\site-packages\flask\app.py", line 1517, in handle_user_exception
    reraise(exc_type, exc_value, tb)
  File "C:\Users\jackm\Desktop\tutor\flask\lib\site-packages\flask\_compat.py", line 33, in reraise
    raise value
  File "C:\Users\jackm\Desktop\tutor\flask\lib\site-packages\flask\app.py", line 1610, in full_dispatch_request
    rv = self.preprocess_request()
  File "C:\Users\jackm\Desktop\tutor\flask\lib\site-packages\flask\app.py", line 1831, in preprocess_request
    rv = func()
  File "C:\Users\jackm\Desktop\tutor\app\views.py", line 16, in before_request
    rooms = Room.query.filter_by(Room.approved_users.filter(UserRoom.c.userId==g.user.id)).all()
  File "C:\Users\jackm\Desktop\tutor\flask\lib\site-packages\sqlalchemy\orm\attributes.py", line 193, in __getattr__
    key)
AttributeError: Neither 'InstrumentedAttribute' object nor 'Comparator' object associated with Room.approved_users has an attribute 'filter'
2017-07-23 12:47:37,213 INFO: tutor startup [in C:\Users\jackm\Desktop\tutor\app\__init__.py:25]
2017-07-23 12:49:16,264 INFO: tutor startup [in C:\Users\jackm\Desktop\tutor\app\__init__.py:25]
2017-07-23 12:51:19,037 INFO: tutor startup [in C:\Users\jackm\Desktop\tutor\app\__init__.py:25]
2017-07-23 12:52:47,150 INFO: tutor startup [in C:\Users\jackm\Desktop\tutor\app\__init__.py:25]
2017-07-23 12:56:27,344 INFO: tutor startup [in C:\Users\jackm\Desktop\tutor\app\__init__.py:25]
2017-07-23 12:56:37,916 INFO: tutor startup [in C:\Users\jackm\Desktop\tutor\app\__init__.py:25]
2017-07-23 12:57:35,063 INFO: tutor startup [in C:\Users\jackm\Desktop\tutor\app\__init__.py:25]
2017-07-23 12:58:34,282 INFO: tutor startup [in C:\Users\jackm\Desktop\tutor\app\__init__.py:25]
2017-07-23 13:03:06,357 INFO: tutor startup [in C:\Users\jackm\Desktop\tutor\app\__init__.py:25]
2017-07-23 13:04:20,492 INFO: tutor startup [in C:\Users\jackm\Desktop\tutor\app\__init__.py:25]
2017-07-23 13:11:46,322 INFO: tutor startup [in C:\Users\jackm\Desktop\tutor\app\__init__.py:25]
2017-07-23 13:23:16,893 INFO: tutor startup [in C:\Users\jackm\Desktop\tutor\app\__init__.py:25]
2017-07-23 13:26:52,461 INFO: tutor startup [in C:\Users\jackm\Desktop\tutor\app\__init__.py:25]
2017-07-23 13:29:14,950 INFO: tutor startup [in C:\Users\jackm\Desktop\tutor\app\__init__.py:25]
2017-07-23 13:30:30,933 INFO: tutor startup [in C:\Users\jackm\Desktop\tutor\app\__init__.py:25]
2017-07-23 13:56:01,159 INFO: tutor startup [in C:\Users\jackm\Desktop\tutor\app\__init__.py:25]
2017-07-23 13:58:51,363 INFO: tutor startup [in C:\Users\jackm\Desktop\tutor\app\__init__.py:25]
2017-07-23 14:04:45,909 INFO: tutor startup [in C:\Users\jackm\Desktop\tutor\app\__init__.py:25]
2017-07-23 14:07:10,893 INFO: tutor startup [in C:\Users\jackm\Desktop\tutor\app\__init__.py:25]
2017-07-23 14:12:39,407 INFO: tutor startup [in C:\Users\jackm\Desktop\tutor\app\__init__.py:25]
2017-07-23 14:15:05,951 INFO: tutor startup [in C:\Users\jackm\Desktop\tutor\app\__init__.py:25]
2017-07-23 14:16:14,238 INFO: tutor startup [in C:\Users\jackm\Desktop\tutor\app\__init__.py:25]
2017-07-23 14:35:07,164 INFO: tutor startup [in C:\Users\jackm\Desktop\tutor\app\__init__.py:25]
2017-07-23 14:44:01,625 INFO: tutor startup [in C:\Users\jackm\Desktop\tutor\app\__init__.py:25]
2017-07-23 14:46:26,729 INFO: tutor startup [in C:\Users\jackm\Desktop\tutor\app\__init__.py:25]
2017-07-23 14:53:16,950 INFO: tutor startup [in C:\Users\jackm\Desktop\tutor\app\__init__.py:25]
2017-07-23 15:00:08,688 INFO: tutor startup [in C:\Users\jackm\Desktop\tutor\app\__init__.py:25]
2017-07-23 15:03:22,506 INFO: tutor startup [in C:\Users\jackm\Desktop\tutor\app\__init__.py:25]
2017-07-23 15:05:16,528 INFO: tutor startup [in C:\Users\jackm\Desktop\tutor\app\__init__.py:25]
2017-07-23 15:08:01,105 INFO: tutor startup [in C:\Users\jackm\Desktop\tutor\app\__init__.py:25]
2017-07-23 15:13:23,202 INFO: tutor startup [in C:\Users\jackm\Desktop\tutor\app\__init__.py:25]
2017-07-27 16:11:30,605 INFO: tutor startup [in C:\Users\jackm\Desktop\tutor\app\__init__.py:25]
2017-07-27 16:20:23,406 INFO: tutor startup [in C:\Users\jackm\Desktop\tutor\app\__init__.py:42]
2017-07-27 16:23:05,081 INFO: tutor startup [in C:\Users\jackm\Desktop\tutor\app\__init__.py:42]
2017-07-27 16:24:52,449 INFO: tutor startup [in C:\Users\jackm\Desktop\tutor\app\__init__.py:42]
2017-07-27 16:25:04,563 INFO: tutor startup [in C:\Users\jackm\Desktop\tutor\app\__init__.py:42]
2017-07-27 16:27:24,146 INFO: tutor startup [in C:\Users\jackm\Desktop\tutor\app\__init__.py:25]
2017-07-28 08:46:36,571 INFO: tutor startup [in C:\Users\jackm\Desktop\tutor\app\__init__.py:25]
2017-08-01 15:44:42,088 INFO: tutor startup [in C:\Users\jackm\Desktop\tutor\app\__init__.py:25]
2017-08-01 16:00:58,464 INFO: tutor startup [in C:\Users\jackm\Desktop\tutor\app\__init__.py:28]
2017-08-01 16:01:02,271 INFO: tutor startup [in C:\Users\jackm\Desktop\tutor\app\__init__.py:28]
2017-08-01 16:01:38,251 ERROR: Exception on /chat [POST] [in C:\Users\jackm\Desktop\tutor\flask\lib\site-packages\flask\app.py:1560]
Traceback (most recent call last):
  File "C:\Users\jackm\Desktop\tutor\flask\lib\site-packages\redis\connection.py", line 439, in connect
    sock = self._connect()
  File "C:\Users\jackm\Desktop\tutor\flask\lib\site-packages\redis\connection.py", line 494, in _connect
    raise err
  File "C:\Users\jackm\Desktop\tutor\flask\lib\site-packages\redis\connection.py", line 482, in _connect
    sock.connect(socket_address)
ConnectionRefusedError: [WinError 10061] No connection could be made because the target machine actively refused it

During handling of the above exception, another exception occurred:

Traceback (most recent call last):
  File "C:\Users\jackm\Desktop\tutor\flask\lib\site-packages\redis\client.py", line 2165, in _execute
    return command(*args)
  File "C:\Users\jackm\Desktop\tutor\flask\lib\site-packages\redis\connection.py", line 563, in send_command
    self.send_packed_command(self.pack_command(*args))
  File "C:\Users\jackm\Desktop\tutor\flask\lib\site-packages\redis\connection.py", line 538, in send_packed_command
    self.connect()
  File "C:\Users\jackm\Desktop\tutor\flask\lib\site-packages\redis\connection.py", line 442, in connect
    raise ConnectionError(self._error_message(e))
redis.exceptions.ConnectionError: Error 10061 connecting to localhost:6379. No connection could be made because the target machine actively refused it.

During handling of the above exception, another exception occurred:

Traceback (most recent call last):
  File "C:\Users\jackm\Desktop\tutor\flask\lib\site-packages\redis\connection.py", line 439, in connect
    sock = self._connect()
  File "C:\Users\jackm\Desktop\tutor\flask\lib\site-packages\redis\connection.py", line 494, in _connect
    raise err
  File "C:\Users\jackm\Desktop\tutor\flask\lib\site-packages\redis\connection.py", line 482, in _connect
    sock.connect(socket_address)
ConnectionRefusedError: [WinError 10061] No connection could be made because the target machine actively refused it

During handling of the above exception, another exception occurred:

Traceback (most recent call last):
  File "C:\Users\jackm\Desktop\tutor\flask\lib\site-packages\kombu\connection.py", line 414, in _reraise_as_library_errors
    yield
  File "C:\Users\jackm\Desktop\tutor\flask\lib\site-packages\celery\app\base.py", line 736, in send_task
    self.backend.on_task_call(P, task_id)
  File "C:\Users\jackm\Desktop\tutor\flask\lib\site-packages\celery\backends\redis.py", line 189, in on_task_call
    self.result_consumer.consume_from(task_id)
  File "C:\Users\jackm\Desktop\tutor\flask\lib\site-packages\celery\backends\redis.py", line 75, in consume_from
    return self.start(task_id)
  File "C:\Users\jackm\Desktop\tutor\flask\lib\site-packages\celery\backends\redis.py", line 57, in start
    self._consume_from(initial_task_id)
  File "C:\Users\jackm\Desktop\tutor\flask\lib\site-packages\celery\backends\redis.py", line 82, in _consume_from
    self._pubsub.subscribe(key)
  File "C:\Users\jackm\Desktop\tutor\flask\lib\site-packages\redis\client.py", line 2229, in subscribe
    ret_val = self.execute_command('SUBSCRIBE', *iterkeys(new_channels))
  File "C:\Users\jackm\Desktop\tutor\flask\lib\site-packages\redis\client.py", line 2161, in execute_command
    self._execute(connection, connection.send_command, *args)
  File "C:\Users\jackm\Desktop\tutor\flask\lib\site-packages\redis\client.py", line 2172, in _execute
    connection.connect()
  File "C:\Users\jackm\Desktop\tutor\flask\lib\site-packages\redis\connection.py", line 442, in connect
    raise ConnectionError(self._error_message(e))
redis.exceptions.ConnectionError: Error 10061 connecting to localhost:6379. No connection could be made because the target machine actively refused it.

During handling of the above exception, another exception occurred:

Traceback (most recent call last):
  File "C:\Users\jackm\Desktop\tutor\flask\lib\site-packages\flask\app.py", line 1982, in wsgi_app
    response = self.full_dispatch_request()
  File "C:\Users\jackm\Desktop\tutor\flask\lib\site-packages\flask\app.py", line 1614, in full_dispatch_request
    rv = self.handle_user_exception(e)
  File "C:\Users\jackm\Desktop\tutor\flask\lib\site-packages\flask\app.py", line 1517, in handle_user_exception
    reraise(exc_type, exc_value, tb)
  File "C:\Users\jackm\Desktop\tutor\flask\lib\site-packages\flask\_compat.py", line 33, in reraise
    raise value
  File "C:\Users\jackm\Desktop\tutor\flask\lib\site-packages\flask\app.py", line 1612, in full_dispatch_request
    rv = self.dispatch_request()
  File "C:\Users\jackm\Desktop\tutor\flask\lib\site-packages\flask\app.py", line 1598, in dispatch_request
    return self.view_functions[rule.endpoint](**req.view_args)
  File "C:\Users\jackm\Desktop\tutor\flask\lib\site-packages\flask_login\utils.py", line 228, in decorated_view
    return func(*args, **kwargs)
  File "C:\Users\jackm\Desktop\tutor\app\views.py", line 86, in chat
    delete_room.apply_async(args=[room.roomname], countdown=10)
  File "C:\Users\jackm\Desktop\tutor\flask\lib\site-packages\celery\app\task.py", line 536, in apply_async
    **options
  File "C:\Users\jackm\Desktop\tutor\flask\lib\site-packages\celery\app\base.py", line 737, in send_task
    amqp.send_task_message(P, name, message, **options)
  File "C:\Users\jackm\Anaconda3\lib\contextlib.py", line 100, in __exit__
    self.gen.throw(type, value, traceback)
  File "C:\Users\jackm\Desktop\tutor\flask\lib\site-packages\kombu\connection.py", line 419, in _reraise_as_library_errors
    sys.exc_info()[2])
  File "C:\Users\jackm\Desktop\tutor\flask\lib\site-packages\vine\five.py", line 178, in reraise
    raise value.with_traceback(tb)
  File "C:\Users\jackm\Desktop\tutor\flask\lib\site-packages\kombu\connection.py", line 414, in _reraise_as_library_errors
    yield
  File "C:\Users\jackm\Desktop\tutor\flask\lib\site-packages\celery\app\base.py", line 736, in send_task
    self.backend.on_task_call(P, task_id)
  File "C:\Users\jackm\Desktop\tutor\flask\lib\site-packages\celery\backends\redis.py", line 189, in on_task_call
    self.result_consumer.consume_from(task_id)
  File "C:\Users\jackm\Desktop\tutor\flask\lib\site-packages\celery\backends\redis.py", line 75, in consume_from
    return self.start(task_id)
  File "C:\Users\jackm\Desktop\tutor\flask\lib\site-packages\celery\backends\redis.py", line 57, in start
    self._consume_from(initial_task_id)
  File "C:\Users\jackm\Desktop\tutor\flask\lib\site-packages\celery\backends\redis.py", line 82, in _consume_from
    self._pubsub.subscribe(key)
  File "C:\Users\jackm\Desktop\tutor\flask\lib\site-packages\redis\client.py", line 2229, in subscribe
    ret_val = self.execute_command('SUBSCRIBE', *iterkeys(new_channels))
  File "C:\Users\jackm\Desktop\tutor\flask\lib\site-packages\redis\client.py", line 2161, in execute_command
    self._execute(connection, connection.send_command, *args)
  File "C:\Users\jackm\Desktop\tutor\flask\lib\site-packages\redis\client.py", line 2172, in _execute
    connection.connect()
  File "C:\Users\jackm\Desktop\tutor\flask\lib\site-packages\redis\connection.py", line 442, in connect
    raise ConnectionError(self._error_message(e))
kombu.exceptions.OperationalError: Error 10061 connecting to localhost:6379. No connection could be made because the target machine actively refused it.
2017-08-01 16:14:02,173 INFO: tutor startup [in C:\Users\jackm\Desktop\tutor\app\__init__.py:28]
2017-08-01 16:27:15,154 INFO: tutor startup [in C:\Users\jackm\Desktop\tutor\app\__init__.py:28]
2017-08-01 16:34:15,619 INFO: tutor startup [in C:\Users\jackm\Desktop\tutor\app\__init__.py:28]
2017-08-01 16:35:07,777 INFO: tutor startup [in C:\Users\jackm\Desktop\tutor\app\__init__.py:28]
2017-08-01 16:42:00,194 INFO: tutor startup [in C:\Users\jackm\Desktop\tutor\app\__init__.py:28]
2017-08-01 16:48:10,750 INFO: tutor startup [in C:\Users\jackm\Desktop\tutor\app\__init__.py:41]
2017-08-01 16:48:34,350 INFO: tutor startup [in C:\Users\jackm\Desktop\tutor\app\__init__.py:41]
2017-08-01 16:51:20,743 INFO: tutor startup [in C:\Users\jackm\Desktop\tutor\app\__init__.py:41]
2017-08-01 16:53:13,087 INFO: tutor startup [in C:\Users\jackm\Desktop\tutor\app\__init__.py:41]
2017-08-01 16:59:41,786 INFO: tutor startup [in C:\Users\jackm\Desktop\tutor\app\__init__.py:41]
2017-08-01 17:00:01,774 INFO: tutor startup [in C:\Users\jackm\Desktop\tutor\app\__init__.py:41]
2017-08-01 17:01:51,517 INFO: tutor startup [in C:\Users\jackm\Desktop\tutor\app\__init__.py:41]
2017-08-01 17:06:03,271 INFO: tutor startup [in C:\Users\jackm\Desktop\tutor\app\__init__.py:41]
2017-08-01 17:06:09,923 INFO: tutor startup [in C:\Users\jackm\Desktop\tutor\app\__init__.py:41]
2017-08-01 17:10:30,591 INFO: tutor startup [in C:\Users\jackm\Desktop\tutor\app\__init__.py:41]
2017-08-01 17:12:01,451 INFO: tutor startup [in C:\Users\jackm\Desktop\tutor\app\__init__.py:25]
2017-08-01 20:29:30,587 INFO: tutor startup [in C:\Users\jackm\Desktop\tutor\app\__init__.py:25]
2017-08-02 10:22:13,358 INFO: tutor startup [in C:\Users\jackm\Desktop\tutor\app\__init__.py:25]
2017-08-02 10:54:40,532 INFO: tutor startup [in C:\Users\jackm\Desktop\tutor\app\__init__.py:42]
2017-08-02 10:55:44,430 INFO: tutor startup [in C:\Users\jackm\Desktop\tutor\app\__init__.py:42]
2017-08-02 10:55:46,338 INFO: tutor startup [in C:\Users\jackm\Desktop\tutor\app\__init__.py:42]
2017-08-02 10:55:46,433 INFO: tutor startup [in C:\Users\jackm\Desktop\tutor\app\__init__.py:42]
2017-08-02 10:55:46,543 INFO: tutor startup [in C:\Users\jackm\Desktop\tutor\app\__init__.py:42]
2017-08-02 10:55:46,677 INFO: tutor startup [in C:\Users\jackm\Desktop\tutor\app\__init__.py:42]
2017-08-02 10:58:40,701 INFO: tutor startup [in C:\Users\jackm\Desktop\tutor\app\__init__.py:42]
2017-08-02 10:58:42,552 INFO: tutor startup [in C:\Users\jackm\Desktop\tutor\app\__init__.py:42]
2017-08-02 10:58:42,635 INFO: tutor startup [in C:\Users\jackm\Desktop\tutor\app\__init__.py:42]
2017-08-02 10:58:42,743 INFO: tutor startup [in C:\Users\jackm\Desktop\tutor\app\__init__.py:42]
2017-08-02 10:58:42,790 INFO: tutor startup [in C:\Users\jackm\Desktop\tutor\app\__init__.py:42]
2017-08-02 10:59:05,672 INFO: tutor startup [in C:\Users\jackm\Desktop\tutor\app\__init__.py:42]
2017-08-02 11:03:24,165 INFO: tutor startup [in C:\Users\jackm\Desktop\tutor\app\__init__.py:51]
2017-08-02 11:03:50,939 INFO: tutor startup [in C:\Users\jackm\Desktop\tutor\app\__init__.py:51]
2017-08-02 11:04:21,514 INFO: tutor startup [in C:\Users\jackm\Desktop\tutor\app\__init__.py:51]
2017-08-02 11:07:17,572 INFO: tutor startup [in C:\Users\jackm\Desktop\tutor\app\__init__.py:42]
2017-08-02 11:16:02,373 INFO: tutor startup [in C:\Users\jackm\Desktop\tutor\app\__init__.py:42]
2017-08-02 11:27:50,987 INFO: tutor startup [in C:\Users\jackm\Desktop\tutor\app\__init__.py:42]
2017-08-02 11:27:52,846 INFO: tutor startup [in C:\Users\jackm\Desktop\tutor\app\__init__.py:42]
2017-08-02 11:27:52,961 INFO: tutor startup [in C:\Users\jackm\Desktop\tutor\app\__init__.py:42]
2017-08-02 11:27:53,082 INFO: tutor startup [in C:\Users\jackm\Desktop\tutor\app\__init__.py:42]
2017-08-02 11:27:53,175 INFO: tutor startup [in C:\Users\jackm\Desktop\tutor\app\__init__.py:42]
2017-08-02 11:28:01,148 INFO: tutor startup [in C:\Users\jackm\Desktop\tutor\app\__init__.py:42]
2017-08-02 11:28:07,207 ERROR: Exception on /process/jack [GET] [in C:\Users\jackm\Desktop\tutor\flask\lib\site-packages\flask\app.py:1560]
Traceback (most recent call last):
  File "C:\Users\jackm\Desktop\tutor\flask\lib\site-packages\flask\app.py", line 1982, in wsgi_app
    response = self.full_dispatch_request()
  File "C:\Users\jackm\Desktop\tutor\flask\lib\site-packages\flask\app.py", line 1614, in full_dispatch_request
    rv = self.handle_user_exception(e)
  File "C:\Users\jackm\Desktop\tutor\flask\lib\site-packages\flask\app.py", line 1517, in handle_user_exception
    reraise(exc_type, exc_value, tb)
  File "C:\Users\jackm\Desktop\tutor\flask\lib\site-packages\flask\_compat.py", line 33, in reraise
    raise value
  File "C:\Users\jackm\Desktop\tutor\flask\lib\site-packages\flask\app.py", line 1612, in full_dispatch_request
    rv = self.dispatch_request()
  File "C:\Users\jackm\Desktop\tutor\flask\lib\site-packages\flask\app.py", line 1598, in dispatch_request
    return self.view_functions[rule.endpoint](**req.view_args)
  File "C:\Users\jackm\Desktop\tutor\app\views.py", line 147, in process
    tasks.reverse.delay(name)
NameError: name 'tasks' is not defined
2017-08-02 11:28:34,308 INFO: tutor startup [in C:\Users\jackm\Desktop\tutor\app\__init__.py:42]
2017-08-02 11:29:27,533 INFO: tutor startup [in C:\Users\jackm\Desktop\tutor\app\__init__.py:42]
2017-08-02 11:29:40,730 INFO: tutor startup [in C:\Users\jackm\Desktop\tutor\app\__init__.py:42]
2017-08-02 11:34:53,937 INFO: tutor startup [in C:\Users\jackm\Desktop\tutor\app\__init__.py:42]
2017-08-02 11:35:01,011 INFO: tutor startup [in C:\Users\jackm\Desktop\tutor\app\__init__.py:42]
2017-08-02 11:36:27,771 INFO: tutor startup [in C:\Users\jackm\Desktop\tutor\app\__init__.py:42]
2017-08-02 11:37:22,046 INFO: tutor startup [in C:\Users\jackm\Desktop\tutor\app\__init__.py:42]
2017-08-02 11:37:26,928 INFO: tutor startup [in C:\Users\jackm\Desktop\tutor\app\__init__.py:42]
2017-08-02 11:39:17,119 INFO: tutor startup [in C:\Users\jackm\Desktop\tutor\app\__init__.py:42]
2017-08-02 11:49:28,195 INFO: tutor startup [in C:\Users\jackm\Desktop\tutor\app\__init__.py:42]
2017-08-02 11:50:52,316 INFO: tutor startup [in C:\Users\jackm\Desktop\tutor\app\__init__.py:42]
2017-08-02 11:55:44,472 INFO: tutor startup [in C:\Users\jackm\Desktop\tutor\app\__init__.py:42]
2017-08-02 11:57:05,974 INFO: tutor startup [in C:\Users\jackm\Desktop\tutor\app\__init__.py:42]
2017-08-02 11:57:41,151 INFO: tutor startup [in C:\Users\jackm\Desktop\tutor\app\__init__.py:42]
2017-08-02 11:58:04,808 INFO: tutor startup [in C:\Users\jackm\Desktop\tutor\app\__init__.py:42]
2017-08-02 12:00:30,453 INFO: tutor startup [in C:\Users\jackm\Desktop\tutor\app\__init__.py:42]
2017-08-02 12:01:48,868 INFO: tutor startup [in C:\Users\jackm\Desktop\tutor\app\__init__.py:42]
2017-08-02 12:03:21,225 INFO: tutor startup [in C:\Users\jackm\Desktop\tutor\app\__init__.py:42]
2017-08-02 12:04:42,119 INFO: tutor startup [in C:\Users\jackm\Desktop\tutor\app\__init__.py:42]
2017-08-02 12:05:09,395 INFO: tutor startup [in C:\Users\jackm\Desktop\tutor\app\__init__.py:42]
2017-08-02 12:05:38,807 INFO: tutor startup [in C:\Users\jackm\Desktop\tutor\app\__init__.py:42]
2017-08-02 12:06:10,514 INFO: tutor startup [in C:\Users\jackm\Desktop\tutor\app\__init__.py:42]
2017-08-02 12:12:45,342 INFO: tutor startup [in C:\Users\jackm\Desktop\tutor\app\__init__.py:42]
2017-08-02 12:13:26,723 INFO: tutor startup [in C:\Users\jackm\Desktop\tutor\app\__init__.py:42]
2017-08-02 12:13:47,387 INFO: tutor startup [in C:\Users\jackm\Desktop\tutor\app\__init__.py:42]
2017-08-02 12:14:47,718 INFO: tutor startup [in C:\Users\jackm\Desktop\tutor\app\__init__.py:42]
2017-08-02 12:15:02,913 INFO: tutor startup [in C:\Users\jackm\Desktop\tutor\app\__init__.py:42]
2017-08-02 12:17:15,117 INFO: tutor startup [in C:\Users\jackm\Desktop\tutor\app\__init__.py:42]
2017-08-02 12:22:37,968 INFO: tutor startup [in C:\Users\jackm\Desktop\tutor\app\__init__.py:42]
2017-08-02 12:25:58,790 INFO: tutor startup [in C:\Users\jackm\Desktop\tutor\app\__init__.py:42]
2017-08-02 12:27:06,848 INFO: tutor startup [in C:\Users\jackm\Desktop\tutor\app\__init__.py:42]
2017-08-02 12:30:01,939 INFO: tutor startup [in C:\Users\jackm\Desktop\tutor\app\__init__.py:42]
2017-08-02 12:31:41,234 INFO: tutor startup [in C:\Users\jackm\Desktop\tutor\app\__init__.py:42]
2017-08-02 12:34:15,791 INFO: tutor startup [in C:\Users\jackm\Desktop\tutor\app\__init__.py:42]
2017-08-02 12:34:41,054 INFO: tutor startup [in C:\Users\jackm\Desktop\tutor\app\__init__.py:42]
2017-08-02 12:36:11,409 INFO: tutor startup [in C:\Users\jackm\Desktop\tutor\app\__init__.py:42]
2017-08-02 12:42:12,664 INFO: tutor startup [in C:\Users\jackm\Desktop\tutor\app\__init__.py:42]
2017-08-02 12:45:13,872 INFO: tutor startup [in C:\Users\jackm\Desktop\tutor\app\__init__.py:42]
2017-08-02 12:45:47,712 INFO: tutor startup [in C:\Users\jackm\Desktop\tutor\app\__init__.py:42]
2017-08-02 12:47:14,445 INFO: tutor startup [in C:\Users\jackm\Desktop\tutor\app\__init__.py:42]
2017-08-02 12:48:05,721 INFO: tutor startup [in C:\Users\jackm\Desktop\tutor\app\__init__.py:42]
2017-08-02 12:50:02,282 INFO: tutor startup [in C:\Users\jackm\Desktop\tutor\app\__init__.py:42]
2017-08-02 12:50:36,050 INFO: tutor startup [in C:\Users\jackm\Desktop\tutor\app\__init__.py:42]
2017-08-02 12:51:20,779 INFO: tutor startup [in C:\Users\jackm\Desktop\tutor\app\__init__.py:42]
2017-08-02 12:51:59,780 INFO: tutor startup [in C:\Users\jackm\Desktop\tutor\app\__init__.py:42]
2017-08-02 12:52:19,273 INFO: tutor startup [in C:\Users\jackm\Desktop\tutor\app\__init__.py:42]
2017-08-02 12:52:45,842 INFO: tutor startup [in C:\Users\jackm\Desktop\tutor\app\__init__.py:42]
2017-08-02 12:54:08,642 INFO: tutor startup [in C:\Users\jackm\Desktop\tutor\app\__init__.py:42]
2017-08-02 12:56:18,043 INFO: tutor startup [in C:\Users\jackm\Desktop\tutor\app\__init__.py:42]
2017-08-02 12:57:25,862 INFO: tutor startup [in C:\Users\jackm\Desktop\tutor\app\__init__.py:42]
2017-08-02 12:57:41,985 INFO: tutor startup [in C:\Users\jackm\Desktop\tutor\app\__init__.py:42]
2017-08-02 13:03:30,012 INFO: tutor startup [in C:\Users\jackm\Desktop\tutor\app\__init__.py:42]
2017-08-02 13:04:04,036 INFO: tutor startup [in C:\Users\jackm\Desktop\tutor\app\__init__.py:42]
2017-08-02 13:07:49,394 INFO: tutor startup [in C:\Users\jackm\Desktop\tutor\app\__init__.py:42]
2017-08-02 13:08:38,172 INFO: tutor startup [in C:\Users\jackm\Desktop\tutor\app\__init__.py:42]
2017-08-02 13:14:33,351 INFO: tutor startup [in C:\Users\jackm\Desktop\tutor\app\__init__.py:42]
2017-08-02 13:16:10,825 INFO: tutor startup [in C:\Users\jackm\Desktop\tutor\app\__init__.py:42]
2017-08-02 13:16:34,214 INFO: tutor startup [in C:\Users\jackm\Desktop\tutor\app\__init__.py:42]
2017-08-02 13:16:49,329 INFO: tutor startup [in C:\Users\jackm\Desktop\tutor\app\__init__.py:42]
2017-08-02 13:18:20,501 INFO: tutor startup [in C:\Users\jackm\Desktop\tutor\app\__init__.py:42]
2017-08-02 13:23:01,536 INFO: tutor startup [in C:\Users\jackm\Desktop\tutor\app\__init__.py:42]
2017-08-02 13:23:54,477 INFO: tutor startup [in C:\Users\jackm\Desktop\tutor\app\__init__.py:42]
2017-08-02 13:29:27,572 INFO: tutor startup [in C:\Users\jackm\Desktop\tutor\app\__init__.py:42]
2017-08-02 13:29:54,907 INFO: tutor startup [in C:\Users\jackm\Desktop\tutor\app\__init__.py:42]
2017-08-02 13:30:17,668 INFO: tutor startup [in C:\Users\jackm\Desktop\tutor\app\__init__.py:42]
2017-08-02 13:30:58,668 INFO: tutor startup [in C:\Users\jackm\Desktop\tutor\app\__init__.py:42]
2017-08-02 13:31:19,490 INFO: tutor startup [in C:\Users\jackm\Desktop\tutor\app\__init__.py:42]
2017-08-02 13:32:47,934 INFO: tutor startup [in C:\Users\jackm\Desktop\tutor\app\__init__.py:42]
2017-08-02 13:33:25,199 INFO: tutor startup [in C:\Users\jackm\Desktop\tutor\app\__init__.py:42]
2017-08-02 13:33:50,499 INFO: tutor startup [in C:\Users\jackm\Desktop\tutor\app\__init__.py:42]
2017-08-02 13:37:07,455 INFO: tutor startup [in C:\Users\jackm\Desktop\tutor\app\__init__.py:42]
2017-08-02 13:37:14,080 ERROR: Exception on / [GET] [in C:\Users\jackm\Desktop\tutor\flask\lib\site-packages\flask\app.py:1560]
Traceback (most recent call last):
  File "C:\Users\jackm\Desktop\tutor\flask\lib\site-packages\flask\app.py", line 1982, in wsgi_app
    response = self.full_dispatch_request()
  File "C:\Users\jackm\Desktop\tutor\flask\lib\site-packages\flask\app.py", line 1614, in full_dispatch_request
    rv = self.handle_user_exception(e)
  File "C:\Users\jackm\Desktop\tutor\flask\lib\site-packages\flask\app.py", line 1517, in handle_user_exception
    reraise(exc_type, exc_value, tb)
  File "C:\Users\jackm\Desktop\tutor\flask\lib\site-packages\flask\_compat.py", line 33, in reraise
    raise value
  File "C:\Users\jackm\Desktop\tutor\flask\lib\site-packages\flask\app.py", line 1612, in full_dispatch_request
    rv = self.dispatch_request()
  File "C:\Users\jackm\Desktop\tutor\flask\lib\site-packages\flask\app.py", line 1598, in dispatch_request
    return self.view_functions[rule.endpoint](**req.view_args)
  File "C:\Users\jackm\Desktop\tutor\app\views.py", line 21, in home
    user=g.user)
  File "C:\Users\jackm\Desktop\tutor\flask\lib\site-packages\flask\templating.py", line 134, in render_template
    context, ctx.app)
  File "C:\Users\jackm\Desktop\tutor\flask\lib\site-packages\flask\templating.py", line 116, in _render
    rv = template.render(context)
  File "C:\Users\jackm\Desktop\tutor\flask\lib\site-packages\jinja2\asyncsupport.py", line 76, in render
    return original_render(self, *args, **kwargs)
  File "C:\Users\jackm\Desktop\tutor\flask\lib\site-packages\jinja2\environment.py", line 1008, in render
    return self.environment.handle_exception(exc_info, True)
  File "C:\Users\jackm\Desktop\tutor\flask\lib\site-packages\jinja2\environment.py", line 780, in handle_exception
    reraise(exc_type, exc_value, tb)
  File "C:\Users\jackm\Desktop\tutor\flask\lib\site-packages\jinja2\_compat.py", line 37, in reraise
    raise value.with_traceback(tb)
  File "C:\Users\jackm\Desktop\tutor\app\templates\base.html", line 64, in template
    {% else %}
  File "C:\Users\jackm\Desktop\tutor\flask\lib\site-packages\jinja2\environment.py", line 1005, in render
    return concat(self.root_render_func(self.new_context(vars)))
  File "C:\Users\jackm\Desktop\tutor\app\templates\home.html", line 1, in top-level template code
    {% extends "base.html" %}
  File "C:\Users\jackm\Desktop\tutor\flask\lib\site-packages\jinja2\environment.py", line 780, in handle_exception
    reraise(exc_type, exc_value, tb)
  File "C:\Users\jackm\Desktop\tutor\flask\lib\site-packages\jinja2\_compat.py", line 37, in reraise
    raise value.with_traceback(tb)
  File "C:\Users\jackm\Desktop\tutor\app\templates\base.html", line 64, in template
    {% else %}
  File "C:\Users\jackm\Desktop\tutor\flask\lib\site-packages\jinja2\environment.py", line 497, in _parse
    return Parser(self, source, name, encode_filename(filename)).parse()
  File "C:\Users\jackm\Desktop\tutor\flask\lib\site-packages\jinja2\parser.py", line 896, in parse
    result = nodes.Template(self.subparse(), lineno=1)
  File "C:\Users\jackm\Desktop\tutor\flask\lib\site-packages\jinja2\parser.py", line 878, in subparse
    rv = self.parse_statement()
  File "C:\Users\jackm\Desktop\tutor\flask\lib\site-packages\jinja2\parser.py", line 144, in parse_statement
    self.fail_unknown_tag(token.value, token.lineno)
  File "C:\Users\jackm\Desktop\tutor\flask\lib\site-packages\jinja2\parser.py", line 97, in fail_unknown_tag
    return self._fail_ut_eof(name, self._end_token_stack, lineno)
  File "C:\Users\jackm\Desktop\tutor\flask\lib\site-packages\jinja2\parser.py", line 90, in _fail_ut_eof
    self.fail(' '.join(message), lineno)
  File "C:\Users\jackm\Desktop\tutor\flask\lib\site-packages\jinja2\parser.py", line 59, in fail
    raise exc(msg, lineno, self.name, self.filename)
jinja2.exceptions.TemplateSyntaxError: Encountered unknown tag 'else'.
2017-08-02 13:37:15,160 ERROR: Exception on /favicon.ico [GET] [in C:\Users\jackm\Desktop\tutor\flask\lib\site-packages\flask\app.py:1560]
Traceback (most recent call last):
  File "C:\Users\jackm\Desktop\tutor\flask\lib\site-packages\flask\app.py", line 1612, in full_dispatch_request
    rv = self.dispatch_request()
  File "C:\Users\jackm\Desktop\tutor\flask\lib\site-packages\flask\app.py", line 1590, in dispatch_request
    self.raise_routing_exception(req)
  File "C:\Users\jackm\Desktop\tutor\flask\lib\site-packages\flask\app.py", line 1573, in raise_routing_exception
    raise request.routing_exception
  File "C:\Users\jackm\Desktop\tutor\flask\lib\site-packages\flask\ctx.py", line 294, in match_request
    self.url_adapter.match(return_rule=True)
  File "C:\Users\jackm\Desktop\tutor\flask\lib\site-packages\werkzeug\routing.py", line 1573, in match
    raise NotFound()
werkzeug.exceptions.NotFound: 404 Not Found: The requested URL was not found on the server.  If you entered the URL manually please check your spelling and try again.

During handling of the above exception, another exception occurred:

Traceback (most recent call last):
  File "C:\Users\jackm\Desktop\tutor\flask\lib\site-packages\flask\app.py", line 1982, in wsgi_app
    response = self.full_dispatch_request()
  File "C:\Users\jackm\Desktop\tutor\flask\lib\site-packages\flask\app.py", line 1614, in full_dispatch_request
    rv = self.handle_user_exception(e)
  File "C:\Users\jackm\Desktop\tutor\flask\lib\site-packages\flask\app.py", line 1512, in handle_user_exception
    return self.handle_http_exception(e)
  File "C:\Users\jackm\Desktop\tutor\flask\lib\site-packages\flask\app.py", line 1471, in handle_http_exception
    return handler(e)
  File "C:\Users\jackm\Desktop\tutor\app\views.py", line 51, in not_found_error
    return render_template('404.html'), 404
  File "C:\Users\jackm\Desktop\tutor\flask\lib\site-packages\flask\templating.py", line 134, in render_template
    context, ctx.app)
  File "C:\Users\jackm\Desktop\tutor\flask\lib\site-packages\flask\templating.py", line 116, in _render
    rv = template.render(context)
  File "C:\Users\jackm\Desktop\tutor\flask\lib\site-packages\jinja2\asyncsupport.py", line 76, in render
    return original_render(self, *args, **kwargs)
  File "C:\Users\jackm\Desktop\tutor\flask\lib\site-packages\jinja2\environment.py", line 1008, in render
    return self.environment.handle_exception(exc_info, True)
  File "C:\Users\jackm\Desktop\tutor\flask\lib\site-packages\jinja2\environment.py", line 780, in handle_exception
    reraise(exc_type, exc_value, tb)
  File "C:\Users\jackm\Desktop\tutor\flask\lib\site-packages\jinja2\_compat.py", line 37, in reraise
    raise value.with_traceback(tb)
  File "C:\Users\jackm\Desktop\tutor\app\templates\base.html", line 64, in template
    {% else %}
  File "C:\Users\jackm\Desktop\tutor\flask\lib\site-packages\jinja2\environment.py", line 1005, in render
    return concat(self.root_render_func(self.new_context(vars)))
  File "C:\Users\jackm\Desktop\tutor\app\templates\404.html", line 1, in top-level template code
    {% extends "base.html" %}
  File "C:\Users\jackm\Desktop\tutor\flask\lib\site-packages\jinja2\environment.py", line 780, in handle_exception
    reraise(exc_type, exc_value, tb)
  File "C:\Users\jackm\Desktop\tutor\flask\lib\site-packages\jinja2\_compat.py", line 37, in reraise
    raise value.with_traceback(tb)
  File "C:\Users\jackm\Desktop\tutor\app\templates\base.html", line 64, in template
    {% else %}
  File "C:\Users\jackm\Desktop\tutor\flask\lib\site-packages\jinja2\environment.py", line 497, in _parse
    return Parser(self, source, name, encode_filename(filename)).parse()
  File "C:\Users\jackm\Desktop\tutor\flask\lib\site-packages\jinja2\parser.py", line 896, in parse
    result = nodes.Template(self.subparse(), lineno=1)
  File "C:\Users\jackm\Desktop\tutor\flask\lib\site-packages\jinja2\parser.py", line 878, in subparse
    rv = self.parse_statement()
  File "C:\Users\jackm\Desktop\tutor\flask\lib\site-packages\jinja2\parser.py", line 144, in parse_statement
    self.fail_unknown_tag(token.value, token.lineno)
  File "C:\Users\jackm\Desktop\tutor\flask\lib\site-packages\jinja2\parser.py", line 97, in fail_unknown_tag
    return self._fail_ut_eof(name, self._end_token_stack, lineno)
  File "C:\Users\jackm\Desktop\tutor\flask\lib\site-packages\jinja2\parser.py", line 90, in _fail_ut_eof
    self.fail(' '.join(message), lineno)
  File "C:\Users\jackm\Desktop\tutor\flask\lib\site-packages\jinja2\parser.py", line 59, in fail
    raise exc(msg, lineno, self.name, self.filename)
jinja2.exceptions.TemplateSyntaxError: Encountered unknown tag 'else'.
2017-08-02 13:37:26,515 INFO: tutor startup [in C:\Users\jackm\Desktop\tutor\app\__init__.py:42]
2017-08-02 13:38:25,676 INFO: tutor startup [in C:\Users\jackm\Desktop\tutor\app\__init__.py:42]
2017-08-02 13:39:02,772 INFO: tutor startup [in C:\Users\jackm\Desktop\tutor\app\__init__.py:42]
2017-08-02 13:40:09,012 INFO: tutor startup [in C:\Users\jackm\Desktop\tutor\app\__init__.py:42]
2017-08-02 13:40:24,302 INFO: tutor startup [in C:\Users\jackm\Desktop\tutor\app\__init__.py:42]
2017-08-02 13:41:26,575 INFO: tutor startup [in C:\Users\jackm\Desktop\tutor\app\__init__.py:42]
2017-08-02 13:42:17,941 INFO: tutor startup [in C:\Users\jackm\Desktop\tutor\app\__init__.py:42]
2017-08-02 13:43:10,450 INFO: tutor startup [in C:\Users\jackm\Desktop\tutor\app\__init__.py:42]
2017-08-02 13:43:12,566 ERROR: Exception on /home [GET] [in C:\Users\jackm\Desktop\tutor\flask\lib\site-packages\flask\app.py:1560]
Traceback (most recent call last):
  File "C:\Users\jackm\Desktop\tutor\flask\lib\site-packages\flask\app.py", line 1982, in wsgi_app
    response = self.full_dispatch_request()
  File "C:\Users\jackm\Desktop\tutor\flask\lib\site-packages\flask\app.py", line 1614, in full_dispatch_request
    rv = self.handle_user_exception(e)
  File "C:\Users\jackm\Desktop\tutor\flask\lib\site-packages\flask\app.py", line 1517, in handle_user_exception
    reraise(exc_type, exc_value, tb)
  File "C:\Users\jackm\Desktop\tutor\flask\lib\site-packages\flask\_compat.py", line 33, in reraise
    raise value
  File "C:\Users\jackm\Desktop\tutor\flask\lib\site-packages\flask\app.py", line 1612, in full_dispatch_request
    rv = self.dispatch_request()
  File "C:\Users\jackm\Desktop\tutor\flask\lib\site-packages\flask\app.py", line 1598, in dispatch_request
    return self.view_functions[rule.endpoint](**req.view_args)
  File "C:\Users\jackm\Desktop\tutor\app\views.py", line 21, in home
    user=g.user)
  File "C:\Users\jackm\Desktop\tutor\flask\lib\site-packages\flask\templating.py", line 134, in render_template
    context, ctx.app)
  File "C:\Users\jackm\Desktop\tutor\flask\lib\site-packages\flask\templating.py", line 116, in _render
    rv = template.render(context)
  File "C:\Users\jackm\Desktop\tutor\flask\lib\site-packages\jinja2\asyncsupport.py", line 76, in render
    return original_render(self, *args, **kwargs)
  File "C:\Users\jackm\Desktop\tutor\flask\lib\site-packages\jinja2\environment.py", line 1008, in render
    return self.environment.handle_exception(exc_info, True)
  File "C:\Users\jackm\Desktop\tutor\flask\lib\site-packages\jinja2\environment.py", line 780, in handle_exception
    reraise(exc_type, exc_value, tb)
  File "C:\Users\jackm\Desktop\tutor\flask\lib\site-packages\jinja2\_compat.py", line 37, in reraise
    raise value.with_traceback(tb)
  File "C:\Users\jackm\Desktop\tutor\app\templates\base.html", line 60, in template
    <a class="dropdown-item" href="{{ url_for('user', current_user.nickname)">Profile</a>
  File "C:\Users\jackm\Desktop\tutor\flask\lib\site-packages\jinja2\environment.py", line 1005, in render
    return concat(self.root_render_func(self.new_context(vars)))
  File "C:\Users\jackm\Desktop\tutor\app\templates\home.html", line 1, in top-level template code
    {% extends "base.html" %}
  File "C:\Users\jackm\Desktop\tutor\flask\lib\site-packages\jinja2\environment.py", line 780, in handle_exception
    reraise(exc_type, exc_value, tb)
  File "C:\Users\jackm\Desktop\tutor\flask\lib\site-packages\jinja2\_compat.py", line 37, in reraise
    raise value.with_traceback(tb)
  File "C:\Users\jackm\Desktop\tutor\app\templates\base.html", line 60, in template
    <a class="dropdown-item" href="{{ url_for('user', current_user.nickname)">Profile</a>
  File "C:\Users\jackm\Desktop\tutor\flask\lib\site-packages\jinja2\environment.py", line 497, in _parse
    return Parser(self, source, name, encode_filename(filename)).parse()
  File "C:\Users\jackm\Desktop\tutor\flask\lib\site-packages\jinja2\parser.py", line 896, in parse
    result = nodes.Template(self.subparse(), lineno=1)
  File "C:\Users\jackm\Desktop\tutor\flask\lib\site-packages\jinja2\parser.py", line 878, in subparse
    rv = self.parse_statement()
  File "C:\Users\jackm\Desktop\tutor\flask\lib\site-packages\jinja2\parser.py", line 130, in parse_statement
    return getattr(self, 'parse_' + self.stream.current.value)()
  File "C:\Users\jackm\Desktop\tutor\flask\lib\site-packages\jinja2\parser.py", line 212, in parse_if
    'name:endif'))
  File "C:\Users\jackm\Desktop\tutor\flask\lib\site-packages\jinja2\parser.py", line 165, in parse_statements
    result = self.subparse(end_tokens)
  File "C:\Users\jackm\Desktop\tutor\flask\lib\site-packages\jinja2\parser.py", line 871, in subparse
    self.stream.expect('variable_end')
  File "C:\Users\jackm\Desktop\tutor\flask\lib\site-packages\jinja2\lexer.py", line 386, in expect
    self.name, self.filename)
jinja2.exceptions.TemplateSyntaxError: expected token 'end of print statement', got 'string'
2017-08-02 13:43:13,529 ERROR: Exception on /favicon.ico [GET] [in C:\Users\jackm\Desktop\tutor\flask\lib\site-packages\flask\app.py:1560]
Traceback (most recent call last):
  File "C:\Users\jackm\Desktop\tutor\flask\lib\site-packages\flask\app.py", line 1612, in full_dispatch_request
    rv = self.dispatch_request()
  File "C:\Users\jackm\Desktop\tutor\flask\lib\site-packages\flask\app.py", line 1590, in dispatch_request
    self.raise_routing_exception(req)
  File "C:\Users\jackm\Desktop\tutor\flask\lib\site-packages\flask\app.py", line 1573, in raise_routing_exception
    raise request.routing_exception
  File "C:\Users\jackm\Desktop\tutor\flask\lib\site-packages\flask\ctx.py", line 294, in match_request
    self.url_adapter.match(return_rule=True)
  File "C:\Users\jackm\Desktop\tutor\flask\lib\site-packages\werkzeug\routing.py", line 1573, in match
    raise NotFound()
werkzeug.exceptions.NotFound: 404 Not Found: The requested URL was not found on the server.  If you entered the URL manually please check your spelling and try again.

During handling of the above exception, another exception occurred:

Traceback (most recent call last):
  File "C:\Users\jackm\Desktop\tutor\flask\lib\site-packages\flask\app.py", line 1982, in wsgi_app
    response = self.full_dispatch_request()
  File "C:\Users\jackm\Desktop\tutor\flask\lib\site-packages\flask\app.py", line 1614, in full_dispatch_request
    rv = self.handle_user_exception(e)
  File "C:\Users\jackm\Desktop\tutor\flask\lib\site-packages\flask\app.py", line 1512, in handle_user_exception
    return self.handle_http_exception(e)
  File "C:\Users\jackm\Desktop\tutor\flask\lib\site-packages\flask\app.py", line 1471, in handle_http_exception
    return handler(e)
  File "C:\Users\jackm\Desktop\tutor\app\views.py", line 51, in not_found_error
    return render_template('404.html'), 404
  File "C:\Users\jackm\Desktop\tutor\flask\lib\site-packages\flask\templating.py", line 134, in render_template
    context, ctx.app)
  File "C:\Users\jackm\Desktop\tutor\flask\lib\site-packages\flask\templating.py", line 116, in _render
    rv = template.render(context)
  File "C:\Users\jackm\Desktop\tutor\flask\lib\site-packages\jinja2\asyncsupport.py", line 76, in render
    return original_render(self, *args, **kwargs)
  File "C:\Users\jackm\Desktop\tutor\flask\lib\site-packages\jinja2\environment.py", line 1008, in render
    return self.environment.handle_exception(exc_info, True)
  File "C:\Users\jackm\Desktop\tutor\flask\lib\site-packages\jinja2\environment.py", line 780, in handle_exception
    reraise(exc_type, exc_value, tb)
  File "C:\Users\jackm\Desktop\tutor\flask\lib\site-packages\jinja2\_compat.py", line 37, in reraise
    raise value.with_traceback(tb)
  File "C:\Users\jackm\Desktop\tutor\app\templates\base.html", line 60, in template
    <a class="dropdown-item" href="{{ url_for('user', current_user.nickname)">Profile</a>
  File "C:\Users\jackm\Desktop\tutor\flask\lib\site-packages\jinja2\environment.py", line 1005, in render
    return concat(self.root_render_func(self.new_context(vars)))
  File "C:\Users\jackm\Desktop\tutor\app\templates\404.html", line 1, in top-level template code
    {% extends "base.html" %}
  File "C:\Users\jackm\Desktop\tutor\flask\lib\site-packages\jinja2\environment.py", line 780, in handle_exception
    reraise(exc_type, exc_value, tb)
  File "C:\Users\jackm\Desktop\tutor\flask\lib\site-packages\jinja2\_compat.py", line 37, in reraise
    raise value.with_traceback(tb)
  File "C:\Users\jackm\Desktop\tutor\app\templates\base.html", line 60, in template
    <a class="dropdown-item" href="{{ url_for('user', current_user.nickname)">Profile</a>
  File "C:\Users\jackm\Desktop\tutor\flask\lib\site-packages\jinja2\environment.py", line 497, in _parse
    return Parser(self, source, name, encode_filename(filename)).parse()
  File "C:\Users\jackm\Desktop\tutor\flask\lib\site-packages\jinja2\parser.py", line 896, in parse
    result = nodes.Template(self.subparse(), lineno=1)
  File "C:\Users\jackm\Desktop\tutor\flask\lib\site-packages\jinja2\parser.py", line 878, in subparse
    rv = self.parse_statement()
  File "C:\Users\jackm\Desktop\tutor\flask\lib\site-packages\jinja2\parser.py", line 130, in parse_statement
    return getattr(self, 'parse_' + self.stream.current.value)()
  File "C:\Users\jackm\Desktop\tutor\flask\lib\site-packages\jinja2\parser.py", line 212, in parse_if
    'name:endif'))
  File "C:\Users\jackm\Desktop\tutor\flask\lib\site-packages\jinja2\parser.py", line 165, in parse_statements
    result = self.subparse(end_tokens)
  File "C:\Users\jackm\Desktop\tutor\flask\lib\site-packages\jinja2\parser.py", line 871, in subparse
    self.stream.expect('variable_end')
  File "C:\Users\jackm\Desktop\tutor\flask\lib\site-packages\jinja2\lexer.py", line 386, in expect
    self.name, self.filename)
jinja2.exceptions.TemplateSyntaxError: expected token 'end of print statement', got 'string'
2017-08-02 13:43:26,586 INFO: tutor startup [in C:\Users\jackm\Desktop\tutor\app\__init__.py:42]
2017-08-02 13:43:28,429 ERROR: Exception on /home [GET] [in C:\Users\jackm\Desktop\tutor\flask\lib\site-packages\flask\app.py:1560]
Traceback (most recent call last):
  File "C:\Users\jackm\Desktop\tutor\flask\lib\site-packages\flask\app.py", line 1982, in wsgi_app
    response = self.full_dispatch_request()
  File "C:\Users\jackm\Desktop\tutor\flask\lib\site-packages\flask\app.py", line 1614, in full_dispatch_request
    rv = self.handle_user_exception(e)
  File "C:\Users\jackm\Desktop\tutor\flask\lib\site-packages\flask\app.py", line 1517, in handle_user_exception
    reraise(exc_type, exc_value, tb)
  File "C:\Users\jackm\Desktop\tutor\flask\lib\site-packages\flask\_compat.py", line 33, in reraise
    raise value
  File "C:\Users\jackm\Desktop\tutor\flask\lib\site-packages\flask\app.py", line 1612, in full_dispatch_request
    rv = self.dispatch_request()
  File "C:\Users\jackm\Desktop\tutor\flask\lib\site-packages\flask\app.py", line 1598, in dispatch_request
    return self.view_functions[rule.endpoint](**req.view_args)
  File "C:\Users\jackm\Desktop\tutor\app\views.py", line 21, in home
    user=g.user)
  File "C:\Users\jackm\Desktop\tutor\flask\lib\site-packages\flask\templating.py", line 134, in render_template
    context, ctx.app)
  File "C:\Users\jackm\Desktop\tutor\flask\lib\site-packages\flask\templating.py", line 116, in _render
    rv = template.render(context)
  File "C:\Users\jackm\Desktop\tutor\flask\lib\site-packages\jinja2\asyncsupport.py", line 76, in render
    return original_render(self, *args, **kwargs)
  File "C:\Users\jackm\Desktop\tutor\flask\lib\site-packages\jinja2\environment.py", line 1008, in render
    return self.environment.handle_exception(exc_info, True)
  File "C:\Users\jackm\Desktop\tutor\flask\lib\site-packages\jinja2\environment.py", line 780, in handle_exception
    reraise(exc_type, exc_value, tb)
  File "C:\Users\jackm\Desktop\tutor\flask\lib\site-packages\jinja2\_compat.py", line 37, in reraise
    raise value.with_traceback(tb)
  File "C:\Users\jackm\Desktop\tutor\app\templates\home.html", line 1, in top-level template code
    {% extends "base.html" %}
  File "C:\Users\jackm\Desktop\tutor\app\templates\base.html", line 60, in top-level template code
    <a class="dropdown-item" href="{{ url_for('user', current_user.nickname) }}">Profile</a>
TypeError: url_for() takes 1 positional argument but 2 were given
2017-08-02 13:43:29,349 ERROR: Exception on /favicon.ico [GET] [in C:\Users\jackm\Desktop\tutor\flask\lib\site-packages\flask\app.py:1560]
Traceback (most recent call last):
  File "C:\Users\jackm\Desktop\tutor\flask\lib\site-packages\flask\app.py", line 1612, in full_dispatch_request
    rv = self.dispatch_request()
  File "C:\Users\jackm\Desktop\tutor\flask\lib\site-packages\flask\app.py", line 1590, in dispatch_request
    self.raise_routing_exception(req)
  File "C:\Users\jackm\Desktop\tutor\flask\lib\site-packages\flask\app.py", line 1573, in raise_routing_exception
    raise request.routing_exception
  File "C:\Users\jackm\Desktop\tutor\flask\lib\site-packages\flask\ctx.py", line 294, in match_request
    self.url_adapter.match(return_rule=True)
  File "C:\Users\jackm\Desktop\tutor\flask\lib\site-packages\werkzeug\routing.py", line 1573, in match
    raise NotFound()
werkzeug.exceptions.NotFound: 404 Not Found: The requested URL was not found on the server.  If you entered the URL manually please check your spelling and try again.

During handling of the above exception, another exception occurred:

Traceback (most recent call last):
  File "C:\Users\jackm\Desktop\tutor\flask\lib\site-packages\flask\app.py", line 1982, in wsgi_app
    response = self.full_dispatch_request()
  File "C:\Users\jackm\Desktop\tutor\flask\lib\site-packages\flask\app.py", line 1614, in full_dispatch_request
    rv = self.handle_user_exception(e)
  File "C:\Users\jackm\Desktop\tutor\flask\lib\site-packages\flask\app.py", line 1512, in handle_user_exception
    return self.handle_http_exception(e)
  File "C:\Users\jackm\Desktop\tutor\flask\lib\site-packages\flask\app.py", line 1471, in handle_http_exception
    return handler(e)
  File "C:\Users\jackm\Desktop\tutor\app\views.py", line 51, in not_found_error
    return render_template('404.html'), 404
  File "C:\Users\jackm\Desktop\tutor\flask\lib\site-packages\flask\templating.py", line 134, in render_template
    context, ctx.app)
  File "C:\Users\jackm\Desktop\tutor\flask\lib\site-packages\flask\templating.py", line 116, in _render
    rv = template.render(context)
  File "C:\Users\jackm\Desktop\tutor\flask\lib\site-packages\jinja2\asyncsupport.py", line 76, in render
    return original_render(self, *args, **kwargs)
  File "C:\Users\jackm\Desktop\tutor\flask\lib\site-packages\jinja2\environment.py", line 1008, in render
    return self.environment.handle_exception(exc_info, True)
  File "C:\Users\jackm\Desktop\tutor\flask\lib\site-packages\jinja2\environment.py", line 780, in handle_exception
    reraise(exc_type, exc_value, tb)
  File "C:\Users\jackm\Desktop\tutor\flask\lib\site-packages\jinja2\_compat.py", line 37, in reraise
    raise value.with_traceback(tb)
  File "C:\Users\jackm\Desktop\tutor\app\templates\404.html", line 1, in top-level template code
    {% extends "base.html" %}
  File "C:\Users\jackm\Desktop\tutor\app\templates\base.html", line 60, in top-level template code
    <a class="dropdown-item" href="{{ url_for('user', current_user.nickname) }}">Profile</a>
TypeError: url_for() takes 1 positional argument but 2 were given
2017-08-02 13:43:55,940 INFO: tutor startup [in C:\Users\jackm\Desktop\tutor\app\__init__.py:42]
2017-08-02 13:43:57,734 ERROR: Exception on /home [GET] [in C:\Users\jackm\Desktop\tutor\flask\lib\site-packages\flask\app.py:1560]
Traceback (most recent call last):
  File "C:\Users\jackm\Desktop\tutor\flask\lib\site-packages\flask\app.py", line 1982, in wsgi_app
    response = self.full_dispatch_request()
  File "C:\Users\jackm\Desktop\tutor\flask\lib\site-packages\flask\app.py", line 1614, in full_dispatch_request
    rv = self.handle_user_exception(e)
  File "C:\Users\jackm\Desktop\tutor\flask\lib\site-packages\flask\app.py", line 1517, in handle_user_exception
    reraise(exc_type, exc_value, tb)
  File "C:\Users\jackm\Desktop\tutor\flask\lib\site-packages\flask\_compat.py", line 33, in reraise
    raise value
  File "C:\Users\jackm\Desktop\tutor\flask\lib\site-packages\flask\app.py", line 1612, in full_dispatch_request
    rv = self.dispatch_request()
  File "C:\Users\jackm\Desktop\tutor\flask\lib\site-packages\flask\app.py", line 1598, in dispatch_request
    return self.view_functions[rule.endpoint](**req.view_args)
  File "C:\Users\jackm\Desktop\tutor\app\views.py", line 21, in home
    user=g.user)
  File "C:\Users\jackm\Desktop\tutor\flask\lib\site-packages\flask\templating.py", line 134, in render_template
    context, ctx.app)
  File "C:\Users\jackm\Desktop\tutor\flask\lib\site-packages\flask\templating.py", line 116, in _render
    rv = template.render(context)
  File "C:\Users\jackm\Desktop\tutor\flask\lib\site-packages\jinja2\asyncsupport.py", line 76, in render
    return original_render(self, *args, **kwargs)
  File "C:\Users\jackm\Desktop\tutor\flask\lib\site-packages\jinja2\environment.py", line 1008, in render
    return self.environment.handle_exception(exc_info, True)
  File "C:\Users\jackm\Desktop\tutor\flask\lib\site-packages\jinja2\environment.py", line 780, in handle_exception
    reraise(exc_type, exc_value, tb)
  File "C:\Users\jackm\Desktop\tutor\flask\lib\site-packages\jinja2\_compat.py", line 37, in reraise
    raise value.with_traceback(tb)
  File "C:\Users\jackm\Desktop\tutor\app\templates\home.html", line 1, in top-level template code
    {% extends "base.html" %}
  File "C:\Users\jackm\Desktop\tutor\app\templates\base.html", line 60, in top-level template code
    <a class="dropdown-item" href="{{ url_for('user/current_user.nickname') }}">Profile</a>
  File "C:\Users\jackm\Desktop\tutor\flask\lib\site-packages\flask\helpers.py", line 333, in url_for
    return appctx.app.handle_url_build_error(error, endpoint, values)
  File "C:\Users\jackm\Desktop\tutor\flask\lib\site-packages\flask\app.py", line 1805, in handle_url_build_error
    reraise(exc_type, exc_value, tb)
  File "C:\Users\jackm\Desktop\tutor\flask\lib\site-packages\flask\_compat.py", line 33, in reraise
    raise value
  File "C:\Users\jackm\Desktop\tutor\flask\lib\site-packages\flask\helpers.py", line 323, in url_for
    force_external=external)
  File "C:\Users\jackm\Desktop\tutor\flask\lib\site-packages\werkzeug\routing.py", line 1768, in build
    raise BuildError(endpoint, values, method, self)
werkzeug.routing.BuildError: Could not build url for endpoint 'user/current_user.nickname'. Did you mean 'user' instead?
2017-08-02 13:43:58,670 ERROR: Exception on /favicon.ico [GET] [in C:\Users\jackm\Desktop\tutor\flask\lib\site-packages\flask\app.py:1560]
Traceback (most recent call last):
  File "C:\Users\jackm\Desktop\tutor\flask\lib\site-packages\flask\app.py", line 1612, in full_dispatch_request
    rv = self.dispatch_request()
  File "C:\Users\jackm\Desktop\tutor\flask\lib\site-packages\flask\app.py", line 1590, in dispatch_request
    self.raise_routing_exception(req)
  File "C:\Users\jackm\Desktop\tutor\flask\lib\site-packages\flask\app.py", line 1573, in raise_routing_exception
    raise request.routing_exception
  File "C:\Users\jackm\Desktop\tutor\flask\lib\site-packages\flask\ctx.py", line 294, in match_request
    self.url_adapter.match(return_rule=True)
  File "C:\Users\jackm\Desktop\tutor\flask\lib\site-packages\werkzeug\routing.py", line 1573, in match
    raise NotFound()
werkzeug.exceptions.NotFound: 404 Not Found: The requested URL was not found on the server.  If you entered the URL manually please check your spelling and try again.

During handling of the above exception, another exception occurred:

Traceback (most recent call last):
  File "C:\Users\jackm\Desktop\tutor\flask\lib\site-packages\flask\app.py", line 1982, in wsgi_app
    response = self.full_dispatch_request()
  File "C:\Users\jackm\Desktop\tutor\flask\lib\site-packages\flask\app.py", line 1614, in full_dispatch_request
    rv = self.handle_user_exception(e)
  File "C:\Users\jackm\Desktop\tutor\flask\lib\site-packages\flask\app.py", line 1512, in handle_user_exception
    return self.handle_http_exception(e)
  File "C:\Users\jackm\Desktop\tutor\flask\lib\site-packages\flask\app.py", line 1471, in handle_http_exception
    return handler(e)
  File "C:\Users\jackm\Desktop\tutor\app\views.py", line 51, in not_found_error
    return render_template('404.html'), 404
  File "C:\Users\jackm\Desktop\tutor\flask\lib\site-packages\flask\templating.py", line 134, in render_template
    context, ctx.app)
  File "C:\Users\jackm\Desktop\tutor\flask\lib\site-packages\flask\templating.py", line 116, in _render
    rv = template.render(context)
  File "C:\Users\jackm\Desktop\tutor\flask\lib\site-packages\jinja2\asyncsupport.py", line 76, in render
    return original_render(self, *args, **kwargs)
  File "C:\Users\jackm\Desktop\tutor\flask\lib\site-packages\jinja2\environment.py", line 1008, in render
    return self.environment.handle_exception(exc_info, True)
  File "C:\Users\jackm\Desktop\tutor\flask\lib\site-packages\jinja2\environment.py", line 780, in handle_exception
    reraise(exc_type, exc_value, tb)
  File "C:\Users\jackm\Desktop\tutor\flask\lib\site-packages\jinja2\_compat.py", line 37, in reraise
    raise value.with_traceback(tb)
  File "C:\Users\jackm\Desktop\tutor\app\templates\404.html", line 1, in top-level template code
    {% extends "base.html" %}
  File "C:\Users\jackm\Desktop\tutor\app\templates\base.html", line 60, in top-level template code
    <a class="dropdown-item" href="{{ url_for('user/current_user.nickname') }}">Profile</a>
  File "C:\Users\jackm\Desktop\tutor\flask\lib\site-packages\flask\helpers.py", line 333, in url_for
    return appctx.app.handle_url_build_error(error, endpoint, values)
  File "C:\Users\jackm\Desktop\tutor\flask\lib\site-packages\flask\app.py", line 1805, in handle_url_build_error
    reraise(exc_type, exc_value, tb)
  File "C:\Users\jackm\Desktop\tutor\flask\lib\site-packages\flask\_compat.py", line 33, in reraise
    raise value
  File "C:\Users\jackm\Desktop\tutor\flask\lib\site-packages\flask\helpers.py", line 323, in url_for
    force_external=external)
  File "C:\Users\jackm\Desktop\tutor\flask\lib\site-packages\werkzeug\routing.py", line 1768, in build
    raise BuildError(endpoint, values, method, self)
werkzeug.routing.BuildError: Could not build url for endpoint 'user/current_user.nickname'. Did you mean 'user' instead?
2017-08-02 13:44:47,689 INFO: tutor startup [in C:\Users\jackm\Desktop\tutor\app\__init__.py:42]
2017-08-02 13:44:50,333 ERROR: Exception on /home [GET] [in C:\Users\jackm\Desktop\tutor\flask\lib\site-packages\flask\app.py:1560]
Traceback (most recent call last):
  File "C:\Users\jackm\Desktop\tutor\flask\lib\site-packages\flask\app.py", line 1982, in wsgi_app
    response = self.full_dispatch_request()
  File "C:\Users\jackm\Desktop\tutor\flask\lib\site-packages\flask\app.py", line 1614, in full_dispatch_request
    rv = self.handle_user_exception(e)
  File "C:\Users\jackm\Desktop\tutor\flask\lib\site-packages\flask\app.py", line 1517, in handle_user_exception
    reraise(exc_type, exc_value, tb)
  File "C:\Users\jackm\Desktop\tutor\flask\lib\site-packages\flask\_compat.py", line 33, in reraise
    raise value
  File "C:\Users\jackm\Desktop\tutor\flask\lib\site-packages\flask\app.py", line 1612, in full_dispatch_request
    rv = self.dispatch_request()
  File "C:\Users\jackm\Desktop\tutor\flask\lib\site-packages\flask\app.py", line 1598, in dispatch_request
    return self.view_functions[rule.endpoint](**req.view_args)
  File "C:\Users\jackm\Desktop\tutor\app\views.py", line 21, in home
    user=g.user)
  File "C:\Users\jackm\Desktop\tutor\flask\lib\site-packages\flask\templating.py", line 134, in render_template
    context, ctx.app)
  File "C:\Users\jackm\Desktop\tutor\flask\lib\site-packages\flask\templating.py", line 116, in _render
    rv = template.render(context)
  File "C:\Users\jackm\Desktop\tutor\flask\lib\site-packages\jinja2\asyncsupport.py", line 76, in render
    return original_render(self, *args, **kwargs)
  File "C:\Users\jackm\Desktop\tutor\flask\lib\site-packages\jinja2\environment.py", line 1008, in render
    return self.environment.handle_exception(exc_info, True)
  File "C:\Users\jackm\Desktop\tutor\flask\lib\site-packages\jinja2\environment.py", line 780, in handle_exception
    reraise(exc_type, exc_value, tb)
  File "C:\Users\jackm\Desktop\tutor\flask\lib\site-packages\jinja2\_compat.py", line 37, in reraise
    raise value.with_traceback(tb)
  File "C:\Users\jackm\Desktop\tutor\app\templates\home.html", line 1, in top-level template code
    {% extends "base.html" %}
  File "C:\Users\jackm\Desktop\tutor\app\templates\base.html", line 60, in top-level template code
    <a class="dropdown-item" href="{{ url_for('user', variable=current_user.nickname) }}">Profile</a>
  File "C:\Users\jackm\Desktop\tutor\flask\lib\site-packages\flask\helpers.py", line 333, in url_for
    return appctx.app.handle_url_build_error(error, endpoint, values)
  File "C:\Users\jackm\Desktop\tutor\flask\lib\site-packages\flask\app.py", line 1805, in handle_url_build_error
    reraise(exc_type, exc_value, tb)
  File "C:\Users\jackm\Desktop\tutor\flask\lib\site-packages\flask\_compat.py", line 33, in reraise
    raise value
  File "C:\Users\jackm\Desktop\tutor\flask\lib\site-packages\flask\helpers.py", line 323, in url_for
    force_external=external)
  File "C:\Users\jackm\Desktop\tutor\flask\lib\site-packages\werkzeug\routing.py", line 1768, in build
    raise BuildError(endpoint, values, method, self)
werkzeug.routing.BuildError: Could not build url for endpoint 'user' with values ['variable']. Did you forget to specify values ['nickname']?
2017-08-02 13:44:51,362 ERROR: Exception on /favicon.ico [GET] [in C:\Users\jackm\Desktop\tutor\flask\lib\site-packages\flask\app.py:1560]
Traceback (most recent call last):
  File "C:\Users\jackm\Desktop\tutor\flask\lib\site-packages\flask\app.py", line 1612, in full_dispatch_request
    rv = self.dispatch_request()
  File "C:\Users\jackm\Desktop\tutor\flask\lib\site-packages\flask\app.py", line 1590, in dispatch_request
    self.raise_routing_exception(req)
  File "C:\Users\jackm\Desktop\tutor\flask\lib\site-packages\flask\app.py", line 1573, in raise_routing_exception
    raise request.routing_exception
  File "C:\Users\jackm\Desktop\tutor\flask\lib\site-packages\flask\ctx.py", line 294, in match_request
    self.url_adapter.match(return_rule=True)
  File "C:\Users\jackm\Desktop\tutor\flask\lib\site-packages\werkzeug\routing.py", line 1573, in match
    raise NotFound()
werkzeug.exceptions.NotFound: 404 Not Found: The requested URL was not found on the server.  If you entered the URL manually please check your spelling and try again.

During handling of the above exception, another exception occurred:

Traceback (most recent call last):
  File "C:\Users\jackm\Desktop\tutor\flask\lib\site-packages\flask\app.py", line 1982, in wsgi_app
    response = self.full_dispatch_request()
  File "C:\Users\jackm\Desktop\tutor\flask\lib\site-packages\flask\app.py", line 1614, in full_dispatch_request
    rv = self.handle_user_exception(e)
  File "C:\Users\jackm\Desktop\tutor\flask\lib\site-packages\flask\app.py", line 1512, in handle_user_exception
    return self.handle_http_exception(e)
  File "C:\Users\jackm\Desktop\tutor\flask\lib\site-packages\flask\app.py", line 1471, in handle_http_exception
    return handler(e)
  File "C:\Users\jackm\Desktop\tutor\app\views.py", line 51, in not_found_error
    return render_template('404.html'), 404
  File "C:\Users\jackm\Desktop\tutor\flask\lib\site-packages\flask\templating.py", line 134, in render_template
    context, ctx.app)
  File "C:\Users\jackm\Desktop\tutor\flask\lib\site-packages\flask\templating.py", line 116, in _render
    rv = template.render(context)
  File "C:\Users\jackm\Desktop\tutor\flask\lib\site-packages\jinja2\asyncsupport.py", line 76, in render
    return original_render(self, *args, **kwargs)
  File "C:\Users\jackm\Desktop\tutor\flask\lib\site-packages\jinja2\environment.py", line 1008, in render
    return self.environment.handle_exception(exc_info, True)
  File "C:\Users\jackm\Desktop\tutor\flask\lib\site-packages\jinja2\environment.py", line 780, in handle_exception
    reraise(exc_type, exc_value, tb)
  File "C:\Users\jackm\Desktop\tutor\flask\lib\site-packages\jinja2\_compat.py", line 37, in reraise
    raise value.with_traceback(tb)
  File "C:\Users\jackm\Desktop\tutor\app\templates\404.html", line 1, in top-level template code
    {% extends "base.html" %}
  File "C:\Users\jackm\Desktop\tutor\app\templates\base.html", line 60, in top-level template code
    <a class="dropdown-item" href="{{ url_for('user', variable=current_user.nickname) }}">Profile</a>
  File "C:\Users\jackm\Desktop\tutor\flask\lib\site-packages\flask\helpers.py", line 333, in url_for
    return appctx.app.handle_url_build_error(error, endpoint, values)
  File "C:\Users\jackm\Desktop\tutor\flask\lib\site-packages\flask\app.py", line 1805, in handle_url_build_error
    reraise(exc_type, exc_value, tb)
  File "C:\Users\jackm\Desktop\tutor\flask\lib\site-packages\flask\_compat.py", line 33, in reraise
    raise value
  File "C:\Users\jackm\Desktop\tutor\flask\lib\site-packages\flask\helpers.py", line 323, in url_for
    force_external=external)
  File "C:\Users\jackm\Desktop\tutor\flask\lib\site-packages\werkzeug\routing.py", line 1768, in build
    raise BuildError(endpoint, values, method, self)
werkzeug.routing.BuildError: Could not build url for endpoint 'user' with values ['variable']. Did you forget to specify values ['nickname']?
2017-08-02 13:45:07,302 INFO: tutor startup [in C:\Users\jackm\Desktop\tutor\app\__init__.py:42]
2017-08-02 13:46:22,019 INFO: tutor startup [in C:\Users\jackm\Desktop\tutor\app\__init__.py:42]
2017-08-02 13:49:06,403 INFO: tutor startup [in C:\Users\jackm\Desktop\tutor\app\__init__.py:42]
2017-08-02 13:56:26,930 INFO: tutor startup [in C:\Users\jackm\Desktop\tutor\app\__init__.py:42]
2017-08-02 13:56:48,132 INFO: tutor startup [in C:\Users\jackm\Desktop\tutor\app\__init__.py:42]
2017-08-02 13:57:17,254 INFO: tutor startup [in C:\Users\jackm\Desktop\tutor\app\__init__.py:42]
2017-08-02 13:58:35,256 INFO: tutor startup [in C:\Users\jackm\Desktop\tutor\app\__init__.py:42]
2017-08-02 14:03:27,643 INFO: tutor startup [in C:\Users\jackm\Desktop\tutor\app\__init__.py:42]
2017-08-02 14:08:56,803 INFO: tutor startup [in C:\Users\jackm\Desktop\tutor\app\__init__.py:42]
2017-08-02 14:09:57,197 INFO: tutor startup [in C:\Users\jackm\Desktop\tutor\app\__init__.py:42]
2017-08-02 14:10:21,774 INFO: tutor startup [in C:\Users\jackm\Desktop\tutor\app\__init__.py:42]
2017-08-02 14:10:38,082 INFO: tutor startup [in C:\Users\jackm\Desktop\tutor\app\__init__.py:42]
2017-08-02 14:10:50,878 INFO: tutor startup [in C:\Users\jackm\Desktop\tutor\app\__init__.py:42]
2017-08-02 14:11:08,810 INFO: tutor startup [in C:\Users\jackm\Desktop\tutor\app\__init__.py:42]
2017-08-02 14:11:19,773 INFO: tutor startup [in C:\Users\jackm\Desktop\tutor\app\__init__.py:42]
2017-08-02 14:14:48,465 INFO: tutor startup [in C:\Users\jackm\Desktop\tutor\app\__init__.py:42]
2017-08-02 14:15:13,229 INFO: tutor startup [in C:\Users\jackm\Desktop\tutor\app\__init__.py:42]
2017-08-02 15:10:17,089 INFO: tutor startup [in C:\Users\jackm\Desktop\tutor\app\__init__.py:42]
2017-08-02 15:15:48,573 INFO: tutor startup [in C:\Users\jackm\Desktop\tutor\app\__init__.py:42]
2017-08-02 15:15:50,704 ERROR: Exception on /login [GET] [in C:\Users\jackm\Desktop\tutor\flask\lib\site-packages\flask\app.py:1560]
Traceback (most recent call last):
  File "C:\Users\jackm\Desktop\tutor\flask\lib\site-packages\flask\app.py", line 1982, in wsgi_app
    response = self.full_dispatch_request()
  File "C:\Users\jackm\Desktop\tutor\flask\lib\site-packages\flask\app.py", line 1614, in full_dispatch_request
    rv = self.handle_user_exception(e)
  File "C:\Users\jackm\Desktop\tutor\flask\lib\site-packages\flask\app.py", line 1517, in handle_user_exception
    reraise(exc_type, exc_value, tb)
  File "C:\Users\jackm\Desktop\tutor\flask\lib\site-packages\flask\_compat.py", line 33, in reraise
    raise value
  File "C:\Users\jackm\Desktop\tutor\flask\lib\site-packages\flask\app.py", line 1612, in full_dispatch_request
    rv = self.dispatch_request()
  File "C:\Users\jackm\Desktop\tutor\flask\lib\site-packages\flask\app.py", line 1598, in dispatch_request
    return self.view_functions[rule.endpoint](**req.view_args)
  File "C:\Users\jackm\Desktop\tutor\app\views.py", line 66, in login
    user=g.user)
  File "C:\Users\jackm\Desktop\tutor\flask\lib\site-packages\flask\templating.py", line 134, in render_template
    context, ctx.app)
  File "C:\Users\jackm\Desktop\tutor\flask\lib\site-packages\flask\templating.py", line 116, in _render
    rv = template.render(context)
  File "C:\Users\jackm\Desktop\tutor\flask\lib\site-packages\jinja2\asyncsupport.py", line 76, in render
    return original_render(self, *args, **kwargs)
  File "C:\Users\jackm\Desktop\tutor\flask\lib\site-packages\jinja2\environment.py", line 1008, in render
    return self.environment.handle_exception(exc_info, True)
  File "C:\Users\jackm\Desktop\tutor\flask\lib\site-packages\jinja2\environment.py", line 780, in handle_exception
    reraise(exc_type, exc_value, tb)
  File "C:\Users\jackm\Desktop\tutor\flask\lib\site-packages\jinja2\_compat.py", line 37, in reraise
    raise value.with_traceback(tb)
  File "C:\Users\jackm\Desktop\tutor\app\templates\login.html", line 1, in top-level template code
    {% extends "base.html" %}
  File "C:\Users\jackm\Desktop\tutor\app\templates\base.html", line 93, in top-level template code
    {% block content %}{% endblock %}
  File "C:\Users\jackm\Desktop\tutor\app\templates\login.html", line 20, in block "content"
    <a href="{{ url_for('authorize', provider=facebook) }}" class="btn azm-social azm-btn azm-border-bottom azm-facebook"><i class="fa fa-facebook"></i> Log in with Facebook</a>
  File "C:\Users\jackm\Desktop\tutor\flask\lib\site-packages\flask\helpers.py", line 333, in url_for
    return appctx.app.handle_url_build_error(error, endpoint, values)
  File "C:\Users\jackm\Desktop\tutor\flask\lib\site-packages\flask\app.py", line 1805, in handle_url_build_error
    reraise(exc_type, exc_value, tb)
  File "C:\Users\jackm\Desktop\tutor\flask\lib\site-packages\flask\_compat.py", line 33, in reraise
    raise value
  File "C:\Users\jackm\Desktop\tutor\flask\lib\site-packages\flask\helpers.py", line 323, in url_for
    force_external=external)
  File "C:\Users\jackm\Desktop\tutor\flask\lib\site-packages\werkzeug\routing.py", line 1768, in build
    raise BuildError(endpoint, values, method, self)
werkzeug.routing.BuildError: Could not build url for endpoint 'authorize' with values ['provider']. Did you mean 'oauth_authorize' instead?
2017-08-02 15:16:41,568 INFO: tutor startup [in C:\Users\jackm\Desktop\tutor\app\__init__.py:42]
2017-08-02 15:19:59,947 INFO: tutor startup [in C:\Users\jackm\Desktop\tutor\app\__init__.py:42]
2017-08-02 15:26:40,826 INFO: tutor startup [in C:\Users\jackm\Desktop\tutor\app\__init__.py:42]
2017-08-02 15:27:35,908 INFO: tutor startup [in C:\Users\jackm\Desktop\tutor\app\__init__.py:42]
2017-08-02 15:27:37,115 INFO: tutor startup [in C:\Users\jackm\Desktop\tutor\app\__init__.py:42]
2017-08-02 16:07:30,072 INFO: tutor startup [in C:\Users\jackm\Desktop\tutor\app\__init__.py:42]
2017-08-02 16:13:49,664 INFO: tutor startup [in C:\Users\jackm\Desktop\tutor\app\__init__.py:42]
2017-08-02 16:15:26,001 INFO: tutor startup [in C:\Users\jackm\Desktop\tutor\app\__init__.py:42]
2017-08-02 21:56:57,964 INFO: tutor startup [in C:\Users\jackm\Desktop\tutor\app\__init__.py:42]
2017-08-03 09:25:54,681 INFO: tutor startup [in C:\Users\jackm\Desktop\tutor\app\__init__.py:42]
2017-08-03 09:28:18,544 INFO: tutor startup [in C:\Users\jackm\Desktop\tutor\app\__init__.py:42]
2017-08-03 09:28:20,326 INFO: tutor startup [in C:\Users\jackm\Desktop\tutor\app\__init__.py:42]
2017-08-03 09:30:04,012 INFO: tutor startup [in C:\Users\jackm\Desktop\tutor\app\__init__.py:42]
2017-08-03 09:30:05,096 INFO: tutor startup [in C:\Users\jackm\Desktop\tutor\app\__init__.py:42]
2017-08-03 10:17:02,950 INFO: tutor startup [in C:\Users\jackm\Desktop\tutor\app\__init__.py:42]
2017-08-03 10:30:26,998 INFO: tutor startup [in C:\Users\jackm\Desktop\tutor\app\__init__.py:44]
2017-08-03 10:30:42,106 ERROR: Exception on /chat [POST] [in C:\Users\jackm\Desktop\tutor\flask\lib\site-packages\flask\app.py:1560]
Traceback (most recent call last):
  File "C:\Users\jackm\Desktop\tutor\flask\lib\site-packages\redis\connection.py", line 439, in connect
    sock = self._connect()
  File "C:\Users\jackm\Desktop\tutor\flask\lib\site-packages\redis\connection.py", line 494, in _connect
    raise err
  File "C:\Users\jackm\Desktop\tutor\flask\lib\site-packages\redis\connection.py", line 482, in _connect
    sock.connect(socket_address)
ConnectionRefusedError: [WinError 10061] No connection could be made because the target machine actively refused it

During handling of the above exception, another exception occurred:

Traceback (most recent call last):
  File "C:\Users\jackm\Desktop\tutor\flask\lib\site-packages\redis\client.py", line 2165, in _execute
    return command(*args)
  File "C:\Users\jackm\Desktop\tutor\flask\lib\site-packages\redis\connection.py", line 563, in send_command
    self.send_packed_command(self.pack_command(*args))
  File "C:\Users\jackm\Desktop\tutor\flask\lib\site-packages\redis\connection.py", line 538, in send_packed_command
    self.connect()
  File "C:\Users\jackm\Desktop\tutor\flask\lib\site-packages\redis\connection.py", line 442, in connect
    raise ConnectionError(self._error_message(e))
redis.exceptions.ConnectionError: Error 10061 connecting to localhost:6379. No connection could be made because the target machine actively refused it.

During handling of the above exception, another exception occurred:

Traceback (most recent call last):
  File "C:\Users\jackm\Desktop\tutor\flask\lib\site-packages\redis\connection.py", line 439, in connect
    sock = self._connect()
  File "C:\Users\jackm\Desktop\tutor\flask\lib\site-packages\redis\connection.py", line 494, in _connect
    raise err
  File "C:\Users\jackm\Desktop\tutor\flask\lib\site-packages\redis\connection.py", line 482, in _connect
    sock.connect(socket_address)
ConnectionRefusedError: [WinError 10061] No connection could be made because the target machine actively refused it

During handling of the above exception, another exception occurred:

Traceback (most recent call last):
  File "C:\Users\jackm\Desktop\tutor\flask\lib\site-packages\kombu\connection.py", line 414, in _reraise_as_library_errors
    yield
  File "C:\Users\jackm\Desktop\tutor\flask\lib\site-packages\celery\app\base.py", line 736, in send_task
    self.backend.on_task_call(P, task_id)
  File "C:\Users\jackm\Desktop\tutor\flask\lib\site-packages\celery\backends\redis.py", line 189, in on_task_call
    self.result_consumer.consume_from(task_id)
  File "C:\Users\jackm\Desktop\tutor\flask\lib\site-packages\celery\backends\redis.py", line 75, in consume_from
    return self.start(task_id)
  File "C:\Users\jackm\Desktop\tutor\flask\lib\site-packages\celery\backends\redis.py", line 57, in start
    self._consume_from(initial_task_id)
  File "C:\Users\jackm\Desktop\tutor\flask\lib\site-packages\celery\backends\redis.py", line 82, in _consume_from
    self._pubsub.subscribe(key)
  File "C:\Users\jackm\Desktop\tutor\flask\lib\site-packages\redis\client.py", line 2229, in subscribe
    ret_val = self.execute_command('SUBSCRIBE', *iterkeys(new_channels))
  File "C:\Users\jackm\Desktop\tutor\flask\lib\site-packages\redis\client.py", line 2161, in execute_command
    self._execute(connection, connection.send_command, *args)
  File "C:\Users\jackm\Desktop\tutor\flask\lib\site-packages\redis\client.py", line 2172, in _execute
    connection.connect()
  File "C:\Users\jackm\Desktop\tutor\flask\lib\site-packages\redis\connection.py", line 442, in connect
    raise ConnectionError(self._error_message(e))
redis.exceptions.ConnectionError: Error 10061 connecting to localhost:6379. No connection could be made because the target machine actively refused it.

During handling of the above exception, another exception occurred:

Traceback (most recent call last):
  File "C:\Users\jackm\Desktop\tutor\flask\lib\site-packages\flask\app.py", line 1982, in wsgi_app
    response = self.full_dispatch_request()
  File "C:\Users\jackm\Desktop\tutor\flask\lib\site-packages\flask\app.py", line 1614, in full_dispatch_request
    rv = self.handle_user_exception(e)
  File "C:\Users\jackm\Desktop\tutor\flask\lib\site-packages\flask\app.py", line 1517, in handle_user_exception
    reraise(exc_type, exc_value, tb)
  File "C:\Users\jackm\Desktop\tutor\flask\lib\site-packages\flask\_compat.py", line 33, in reraise
    raise value
  File "C:\Users\jackm\Desktop\tutor\flask\lib\site-packages\flask\app.py", line 1612, in full_dispatch_request
    rv = self.dispatch_request()
  File "C:\Users\jackm\Desktop\tutor\flask\lib\site-packages\flask\app.py", line 1598, in dispatch_request
    return self.view_functions[rule.endpoint](**req.view_args)
  File "C:\Users\jackm\Desktop\tutor\flask\lib\site-packages\flask_login\utils.py", line 228, in decorated_view
    return func(*args, **kwargs)
  File "C:\Users\jackm\Desktop\tutor\app\views.py", line 88, in chat
    remove_room.apply_async(args=[room.roomname], countdown=14400)
  File "C:\Users\jackm\Desktop\tutor\flask\lib\site-packages\celery\app\task.py", line 536, in apply_async
    **options
  File "C:\Users\jackm\Desktop\tutor\flask\lib\site-packages\celery\app\base.py", line 737, in send_task
    amqp.send_task_message(P, name, message, **options)
  File "C:\Users\jackm\Anaconda3\lib\contextlib.py", line 100, in __exit__
    self.gen.throw(type, value, traceback)
  File "C:\Users\jackm\Desktop\tutor\flask\lib\site-packages\kombu\connection.py", line 419, in _reraise_as_library_errors
    sys.exc_info()[2])
  File "C:\Users\jackm\Desktop\tutor\flask\lib\site-packages\vine\five.py", line 178, in reraise
    raise value.with_traceback(tb)
  File "C:\Users\jackm\Desktop\tutor\flask\lib\site-packages\kombu\connection.py", line 414, in _reraise_as_library_errors
    yield
  File "C:\Users\jackm\Desktop\tutor\flask\lib\site-packages\celery\app\base.py", line 736, in send_task
    self.backend.on_task_call(P, task_id)
  File "C:\Users\jackm\Desktop\tutor\flask\lib\site-packages\celery\backends\redis.py", line 189, in on_task_call
    self.result_consumer.consume_from(task_id)
  File "C:\Users\jackm\Desktop\tutor\flask\lib\site-packages\celery\backends\redis.py", line 75, in consume_from
    return self.start(task_id)
  File "C:\Users\jackm\Desktop\tutor\flask\lib\site-packages\celery\backends\redis.py", line 57, in start
    self._consume_from(initial_task_id)
  File "C:\Users\jackm\Desktop\tutor\flask\lib\site-packages\celery\backends\redis.py", line 82, in _consume_from
    self._pubsub.subscribe(key)
  File "C:\Users\jackm\Desktop\tutor\flask\lib\site-packages\redis\client.py", line 2229, in subscribe
    ret_val = self.execute_command('SUBSCRIBE', *iterkeys(new_channels))
  File "C:\Users\jackm\Desktop\tutor\flask\lib\site-packages\redis\client.py", line 2161, in execute_command
    self._execute(connection, connection.send_command, *args)
  File "C:\Users\jackm\Desktop\tutor\flask\lib\site-packages\redis\client.py", line 2172, in _execute
    connection.connect()
  File "C:\Users\jackm\Desktop\tutor\flask\lib\site-packages\redis\connection.py", line 442, in connect
    raise ConnectionError(self._error_message(e))
kombu.exceptions.OperationalError: Error 10061 connecting to localhost:6379. No connection could be made because the target machine actively refused it.
2017-08-03 10:32:57,230 INFO: tutor startup [in C:\Users\jackm\Desktop\tutor\app\__init__.py:44]
2017-08-03 14:36:38,599 INFO: tutor startup [in C:\Users\jackm\Desktop\tutor\app\__init__.py:44]
2017-08-03 14:43:58,903 INFO: tutor startup [in C:\Users\jackm\Desktop\tutor\app\__init__.py:44]
2017-08-03 15:19:52,123 INFO: tutor startup [in C:\Users\jackm\Desktop\tutor\app\__init__.py:44]
2017-08-03 15:20:21,061 INFO: tutor startup [in C:\Users\jackm\Desktop\tutor\app\__init__.py:44]
2017-08-03 15:21:58,023 INFO: tutor startup [in C:\Users\jackm\Desktop\tutor\app\__init__.py:44]
2017-08-05 09:25:16,456 INFO: tutor startup [in C:\Users\jackm\Desktop\tutor\app\__init__.py:44]
2017-08-05 09:25:27,684 INFO: tutor startup [in C:\Users\jackm\Desktop\tutor\app\__init__.py:44]
2017-08-05 09:28:47,986 INFO: tutor startup [in C:\Users\jackm\Desktop\tutor\app\__init__.py:44]
2017-08-05 09:30:17,300 INFO: tutor startup [in C:\Users\jackm\Desktop\tutor\app\__init__.py:44]
2017-08-05 09:30:28,145 INFO: tutor startup [in C:\Users\jackm\Desktop\tutor\app\__init__.py:44]
2017-08-05 09:34:45,116 INFO: tutor startup [in C:\Users\jackm\Desktop\tutor\app\__init__.py:44]
2017-08-05 09:34:47,798 INFO: tutor startup [in C:\Users\jackm\Desktop\tutor\app\__init__.py:44]
2017-08-05 09:35:01,768 ERROR: Exception on /chat [POST] [in C:\Users\jackm\Desktop\tutor\flask\lib\site-packages\flask\app.py:1560]
Traceback (most recent call last):
  File "C:\Users\jackm\Desktop\tutor\flask\lib\site-packages\flask\app.py", line 1982, in wsgi_app
    response = self.full_dispatch_request()
  File "C:\Users\jackm\Desktop\tutor\flask\lib\site-packages\flask\app.py", line 1614, in full_dispatch_request
    rv = self.handle_user_exception(e)
  File "C:\Users\jackm\Desktop\tutor\flask\lib\site-packages\flask\app.py", line 1517, in handle_user_exception
    reraise(exc_type, exc_value, tb)
  File "C:\Users\jackm\Desktop\tutor\flask\lib\site-packages\flask\_compat.py", line 33, in reraise
    raise value
  File "C:\Users\jackm\Desktop\tutor\flask\lib\site-packages\flask\app.py", line 1612, in full_dispatch_request
    rv = self.dispatch_request()
  File "C:\Users\jackm\Desktop\tutor\flask\lib\site-packages\flask\app.py", line 1598, in dispatch_request
    return self.view_functions[rule.endpoint](**req.view_args)
  File "C:\Users\jackm\Desktop\tutor\flask\lib\site-packages\flask_login\utils.py", line 228, in decorated_view
    return func(*args, **kwargs)
  File "C:\Users\jackm\Desktop\tutor\app\views.py", line 89, in chat
    remove_room.apply_async(args=[room.roomname], countdown=10)
  File "C:\Users\jackm\Desktop\tutor\flask\lib\site-packages\celery\app\task.py", line 518, in apply_async
    check_arguments(*(args or ()), **(kwargs or {}))
TypeError: remove_room() missing 1 required positional argument: 'roomname'
2017-08-05 09:35:59,355 INFO: tutor startup [in C:\Users\jackm\Desktop\tutor\app\__init__.py:44]
2017-08-05 09:36:02,841 INFO: tutor startup [in C:\Users\jackm\Desktop\tutor\app\__init__.py:44]
2017-08-05 09:38:10,684 INFO: tutor startup [in C:\Users\jackm\Desktop\tutor\app\__init__.py:44]
2017-08-05 09:38:18,269 INFO: tutor startup [in C:\Users\jackm\Desktop\tutor\app\__init__.py:44]
2017-08-05 09:40:20,025 INFO: tutor startup [in C:\Users\jackm\Desktop\tutor\app\__init__.py:44]
2017-08-05 09:40:23,313 INFO: tutor startup [in C:\Users\jackm\Desktop\tutor\app\__init__.py:44]
2017-08-05 09:41:26,623 INFO: tutor startup [in C:\Users\jackm\Desktop\tutor\app\__init__.py:44]
2017-08-05 09:41:29,924 INFO: tutor startup [in C:\Users\jackm\Desktop\tutor\app\__init__.py:44]
2017-08-05 09:44:46,124 INFO: tutor startup [in C:\Users\jackm\Desktop\tutor\app\__init__.py:44]
2017-08-05 09:44:48,756 INFO: tutor startup [in C:\Users\jackm\Desktop\tutor\app\__init__.py:44]
2017-08-05 09:45:49,497 INFO: tutor startup [in C:\Users\jackm\Desktop\tutor\app\__init__.py:44]
2017-08-05 09:45:52,983 INFO: tutor startup [in C:\Users\jackm\Desktop\tutor\app\__init__.py:44]
2017-08-05 10:24:21,238 INFO: tutor startup [in C:\Users\jackm\Desktop\tutor\app\__init__.py:44]
2017-08-05 10:24:24,020 INFO: tutor startup [in C:\Users\jackm\Desktop\tutor\app\__init__.py:44]
2017-08-05 10:25:19,417 INFO: tutor startup [in C:\Users\jackm\Desktop\tutor\app\__init__.py:44]
2017-08-05 10:25:22,143 INFO: tutor startup [in C:\Users\jackm\Desktop\tutor\app\__init__.py:44]
2017-08-05 10:26:11,830 INFO: tutor startup [in C:\Users\jackm\Desktop\tutor\app\__init__.py:44]
2017-08-05 10:26:13,749 INFO: tutor startup [in C:\Users\jackm\Desktop\tutor\app\__init__.py:44]
2017-08-06 12:48:28,975 INFO: tutor startup [in C:\Users\jackm\Desktop\tutor\app\__init__.py:44]
